2021-02-23 14:48:15,674 - INFO - Scheduler started
2021-02-23 14:48:16,667 - ERROR - None
Traceback (most recent call last):
  File "C:\Users\user\PycharmProjects\InvestBot\DB\Queries\dbConnection.py", line 31, in query
    records = update_db(conn,sql)
  File "C:\Users\user\PycharmProjects\InvestBot\DB\Queries\dbConnection.py", line 23, in update_db
    records = cursor.fetchall()
psycopg2.ProgrammingError: no results to fetch
2021-02-23 14:48:17,279 - ERROR - ERROR:  duplicate key value violates unique constraint "chat_id"
DETAIL:  Key (chat_id)=(350402934) already exists.
Traceback (most recent call last):
  File "C:\Users\user\PycharmProjects\InvestBot\DB\Queries\dbConnection.py", line 31, in query
    records = update_db(conn,sql)
  File "C:\Users\user\PycharmProjects\InvestBot\DB\Queries\dbConnection.py", line 21, in update_db
    cursor.execute(sql)
psycopg2.errors.UniqueViolation: duplicate key value violates unique constraint "chat_id"
DETAIL:  Key (chat_id)=(350402934) already exists.

2021-02-23 14:48:17,780 - ERROR - ERROR:  duplicate key value violates unique constraint "chat_id"
DETAIL:  Key (chat_id)=(350402934) already exists.
Traceback (most recent call last):
  File "C:\Users\user\PycharmProjects\InvestBot\DB\Queries\dbConnection.py", line 31, in query
    records = update_db(conn,sql)
  File "C:\Users\user\PycharmProjects\InvestBot\DB\Queries\dbConnection.py", line 21, in update_db
    cursor.execute(sql)
psycopg2.errors.UniqueViolation: duplicate key value violates unique constraint "chat_id"
DETAIL:  Key (chat_id)=(350402934) already exists.

2021-02-23 14:49:09,698 - INFO - Scheduler started
2021-02-23 14:49:26,371 - INFO - Scheduler started
2021-02-23 14:50:33,746 - ERROR - ERROR:  duplicate key value violates unique constraint "chat_id"
DETAIL:  Key (chat_id)=(350402934) already exists.
Traceback (most recent call last):
  File "C:\Users\user\PycharmProjects\InvestBot\DB\Queries\dbConnection.py", line 31, in query
    records = update_db(conn,sql)
  File "C:\Users\user\PycharmProjects\InvestBot\DB\Queries\dbConnection.py", line 21, in update_db
    cursor.execute(sql)
psycopg2.errors.UniqueViolation: duplicate key value violates unique constraint "chat_id"
DETAIL:  Key (chat_id)=(350402934) already exists.

2021-02-23 14:51:11,755 - ERROR - ERROR:  duplicate key value violates unique constraint "chat_id"
DETAIL:  Key (chat_id)=(350402934) already exists.
Traceback (most recent call last):
  File "C:\Users\user\PycharmProjects\InvestBot\DB\Queries\dbConnection.py", line 31, in query
    records = update_db(conn,sql)
  File "C:\Users\user\PycharmProjects\InvestBot\DB\Queries\dbConnection.py", line 21, in update_db
    cursor.execute(sql)
psycopg2.errors.UniqueViolation: duplicate key value violates unique constraint "chat_id"
DETAIL:  Key (chat_id)=(350402934) already exists.

2021-02-23 14:51:27,814 - INFO - Scheduler started
2021-02-23 14:51:29,987 - ERROR - ERROR:  duplicate key value violates unique constraint "chat_id"
DETAIL:  Key (chat_id)=(350402934) already exists.
Traceback (most recent call last):
  File "C:\Users\user\PycharmProjects\InvestBot\DB\Queries\dbConnection.py", line 31, in query
    records = update_db(conn,sql)
  File "C:\Users\user\PycharmProjects\InvestBot\DB\Queries\dbConnection.py", line 21, in update_db
    cursor.execute(sql)
psycopg2.errors.UniqueViolation: duplicate key value violates unique constraint "chat_id"
DETAIL:  Key (chat_id)=(350402934) already exists.

2021-02-23 16:05:02,431 - INFO - Scheduler started
2021-02-23 16:05:10,137 - ERROR - ERROR:  duplicate key value violates unique constraint "chat_id"
DETAIL:  Key (chat_id)=(350402934) already exists.
Traceback (most recent call last):
  File "C:\Users\user\PycharmProjects\InvestBot\DB\Queries\dbConnection.py", line 31, in query
    records = update_db(conn,sql)
  File "C:\Users\user\PycharmProjects\InvestBot\DB\Queries\dbConnection.py", line 21, in update_db
    cursor.execute(sql)
psycopg2.errors.UniqueViolation: duplicate key value violates unique constraint "chat_id"
DETAIL:  Key (chat_id)=(350402934) already exists.

2021-02-23 16:05:17,672 - ERROR - No error handlers are registered, logging exception.
Traceback (most recent call last):
  File "C:\Users\user\PycharmProjects\pythonProject1\lib\site-packages\telegram\ext\dispatcher.py", line 442, in process_update
    handler.handle_update(update, self, check, context)
  File "C:\Users\user\PycharmProjects\pythonProject1\lib\site-packages\telegram\ext\conversationhandler.py", line 549, in handle_update
    new_state = handler.handle_update(update, dispatcher, check_result, context)
  File "C:\Users\user\PycharmProjects\pythonProject1\lib\site-packages\telegram\ext\handler.py", line 160, in handle_update
    return self.callback(update, context)
  File "C:\Users\user\PycharmProjects\InvestBot\Handlers\ConversationHandlers\CurrencyConversationHandler.py", line 26, in mosCurrency
    sector(bot)
TypeError: sector() missing 1 required positional argument: 'update'
2021-02-23 16:06:25,854 - INFO - Scheduler started
2021-02-23 16:06:31,710 - ERROR - No error handlers are registered, logging exception.
Traceback (most recent call last):
  File "C:\Users\user\PycharmProjects\pythonProject1\lib\site-packages\telegram\ext\dispatcher.py", line 442, in process_update
    handler.handle_update(update, self, check, context)
  File "C:\Users\user\PycharmProjects\pythonProject1\lib\site-packages\telegram\ext\conversationhandler.py", line 549, in handle_update
    new_state = handler.handle_update(update, dispatcher, check_result, context)
  File "C:\Users\user\PycharmProjects\pythonProject1\lib\site-packages\telegram\ext\handler.py", line 160, in handle_update
    return self.callback(update, context)
  File "C:\Users\user\PycharmProjects\InvestBot\Handlers\ConversationHandlers\CurrencyConversationHandler.py", line 26, in mosCurrency
    sector(bot)
  File "C:\Users\user\PycharmProjects\InvestBot\Handlers\ConversationHandlers\CurrencyConversationHandler.py", line 59, in sector
    reply_markup=sectorMarkup())
TypeError: sectorMarkup() missing 2 required positional arguments: 'bot' and 'update'
2021-02-23 16:12:09,612 - INFO - Scheduler started
2021-02-23 16:14:01,279 - INFO - Scheduler started
2021-02-23 16:16:00,774 - INFO - Scheduler started
2021-02-23 16:16:06,091 - ERROR - Error while getting Updates: Conflict: terminated by other getUpdates request; make sure that only one bot instance is running
2021-02-23 16:16:06,091 - ERROR - No error handlers are registered, logging exception.
Traceback (most recent call last):
  File "C:\Users\user\PycharmProjects\pythonProject1\lib\site-packages\telegram\ext\updater.py", line 465, in _network_loop_retry
    if not action_cb():
  File "C:\Users\user\PycharmProjects\pythonProject1\lib\site-packages\telegram\ext\updater.py", line 416, in polling_action_cb
    updates = self.bot.get_updates(
  File "C:\Users\user\PycharmProjects\pythonProject1\lib\site-packages\telegram\bot.py", line 126, in decorator
    result = func(*args, **kwargs)
  File "C:\Users\user\PycharmProjects\pythonProject1\lib\site-packages\telegram\bot.py", line 2748, in get_updates
    result = self._post(
  File "C:\Users\user\PycharmProjects\pythonProject1\lib\site-packages\telegram\bot.py", line 258, in _post
    return self.request.post(
  File "C:\Users\user\PycharmProjects\pythonProject1\lib\site-packages\telegram\utils\request.py", line 349, in post
    result = self._request_wrapper(
  File "C:\Users\user\PycharmProjects\pythonProject1\lib\site-packages\telegram\utils\request.py", line 276, in _request_wrapper
    raise Conflict(message)
telegram.error.Conflict: Conflict: terminated by other getUpdates request; make sure that only one bot instance is running
2021-02-23 16:16:45,662 - INFO - Scheduler started
2021-02-23 16:18:14,558 - ERROR - Error while getting Updates: Conflict: terminated by other getUpdates request; make sure that only one bot instance is running
2021-02-23 16:18:14,559 - ERROR - No error handlers are registered, logging exception.
Traceback (most recent call last):
  File "C:\Users\user\PycharmProjects\pythonProject1\lib\site-packages\telegram\ext\updater.py", line 465, in _network_loop_retry
    if not action_cb():
  File "C:\Users\user\PycharmProjects\pythonProject1\lib\site-packages\telegram\ext\updater.py", line 416, in polling_action_cb
    updates = self.bot.get_updates(
  File "C:\Users\user\PycharmProjects\pythonProject1\lib\site-packages\telegram\bot.py", line 126, in decorator
    result = func(*args, **kwargs)
  File "C:\Users\user\PycharmProjects\pythonProject1\lib\site-packages\telegram\bot.py", line 2748, in get_updates
    result = self._post(
  File "C:\Users\user\PycharmProjects\pythonProject1\lib\site-packages\telegram\bot.py", line 258, in _post
    return self.request.post(
  File "C:\Users\user\PycharmProjects\pythonProject1\lib\site-packages\telegram\utils\request.py", line 349, in post
    result = self._request_wrapper(
  File "C:\Users\user\PycharmProjects\pythonProject1\lib\site-packages\telegram\utils\request.py", line 276, in _request_wrapper
    raise Conflict(message)
telegram.error.Conflict: Conflict: terminated by other getUpdates request; make sure that only one bot instance is running
2021-02-23 16:18:20,195 - ERROR - Error while getting Updates: Conflict: terminated by other getUpdates request; make sure that only one bot instance is running
2021-02-23 16:18:20,195 - ERROR - No error handlers are registered, logging exception.
Traceback (most recent call last):
  File "C:\Users\user\PycharmProjects\pythonProject1\lib\site-packages\telegram\ext\updater.py", line 465, in _network_loop_retry
    if not action_cb():
  File "C:\Users\user\PycharmProjects\pythonProject1\lib\site-packages\telegram\ext\updater.py", line 416, in polling_action_cb
    updates = self.bot.get_updates(
  File "C:\Users\user\PycharmProjects\pythonProject1\lib\site-packages\telegram\bot.py", line 126, in decorator
    result = func(*args, **kwargs)
  File "C:\Users\user\PycharmProjects\pythonProject1\lib\site-packages\telegram\bot.py", line 2748, in get_updates
    result = self._post(
  File "C:\Users\user\PycharmProjects\pythonProject1\lib\site-packages\telegram\bot.py", line 258, in _post
    return self.request.post(
  File "C:\Users\user\PycharmProjects\pythonProject1\lib\site-packages\telegram\utils\request.py", line 349, in post
    result = self._request_wrapper(
  File "C:\Users\user\PycharmProjects\pythonProject1\lib\site-packages\telegram\utils\request.py", line 276, in _request_wrapper
    raise Conflict(message)
telegram.error.Conflict: Conflict: terminated by other getUpdates request; make sure that only one bot instance is running
2021-02-23 16:18:26,254 - ERROR - Error while getting Updates: Conflict: terminated by other getUpdates request; make sure that only one bot instance is running
2021-02-23 16:18:26,255 - ERROR - No error handlers are registered, logging exception.
Traceback (most recent call last):
  File "C:\Users\user\PycharmProjects\pythonProject1\lib\site-packages\telegram\ext\updater.py", line 465, in _network_loop_retry
    if not action_cb():
  File "C:\Users\user\PycharmProjects\pythonProject1\lib\site-packages\telegram\ext\updater.py", line 416, in polling_action_cb
    updates = self.bot.get_updates(
  File "C:\Users\user\PycharmProjects\pythonProject1\lib\site-packages\telegram\bot.py", line 126, in decorator
    result = func(*args, **kwargs)
  File "C:\Users\user\PycharmProjects\pythonProject1\lib\site-packages\telegram\bot.py", line 2748, in get_updates
    result = self._post(
  File "C:\Users\user\PycharmProjects\pythonProject1\lib\site-packages\telegram\bot.py", line 258, in _post
    return self.request.post(
  File "C:\Users\user\PycharmProjects\pythonProject1\lib\site-packages\telegram\utils\request.py", line 349, in post
    result = self._request_wrapper(
  File "C:\Users\user\PycharmProjects\pythonProject1\lib\site-packages\telegram\utils\request.py", line 276, in _request_wrapper
    raise Conflict(message)
telegram.error.Conflict: Conflict: terminated by other getUpdates request; make sure that only one bot instance is running
2021-02-23 16:18:32,253 - ERROR - Error while getting Updates: Conflict: terminated by other getUpdates request; make sure that only one bot instance is running
2021-02-23 16:18:32,254 - ERROR - No error handlers are registered, logging exception.
Traceback (most recent call last):
  File "C:\Users\user\PycharmProjects\pythonProject1\lib\site-packages\telegram\ext\updater.py", line 465, in _network_loop_retry
    if not action_cb():
  File "C:\Users\user\PycharmProjects\pythonProject1\lib\site-packages\telegram\ext\updater.py", line 416, in polling_action_cb
    updates = self.bot.get_updates(
  File "C:\Users\user\PycharmProjects\pythonProject1\lib\site-packages\telegram\bot.py", line 126, in decorator
    result = func(*args, **kwargs)
  File "C:\Users\user\PycharmProjects\pythonProject1\lib\site-packages\telegram\bot.py", line 2748, in get_updates
    result = self._post(
  File "C:\Users\user\PycharmProjects\pythonProject1\lib\site-packages\telegram\bot.py", line 258, in _post
    return self.request.post(
  File "C:\Users\user\PycharmProjects\pythonProject1\lib\site-packages\telegram\utils\request.py", line 349, in post
    result = self._request_wrapper(
  File "C:\Users\user\PycharmProjects\pythonProject1\lib\site-packages\telegram\utils\request.py", line 276, in _request_wrapper
    raise Conflict(message)
telegram.error.Conflict: Conflict: terminated by other getUpdates request; make sure that only one bot instance is running
2021-02-23 16:18:49,969 - INFO - Scheduler started
2021-02-23 16:20:49,999 - ERROR - Error while getting Updates: Conflict: terminated by other getUpdates request; make sure that only one bot instance is running
2021-02-23 16:20:49,999 - ERROR - No error handlers are registered, logging exception.
Traceback (most recent call last):
  File "C:\Users\user\PycharmProjects\pythonProject1\lib\site-packages\telegram\ext\updater.py", line 465, in _network_loop_retry
    if not action_cb():
  File "C:\Users\user\PycharmProjects\pythonProject1\lib\site-packages\telegram\ext\updater.py", line 416, in polling_action_cb
    updates = self.bot.get_updates(
  File "C:\Users\user\PycharmProjects\pythonProject1\lib\site-packages\telegram\bot.py", line 126, in decorator
    result = func(*args, **kwargs)
  File "C:\Users\user\PycharmProjects\pythonProject1\lib\site-packages\telegram\bot.py", line 2748, in get_updates
    result = self._post(
  File "C:\Users\user\PycharmProjects\pythonProject1\lib\site-packages\telegram\bot.py", line 258, in _post
    return self.request.post(
  File "C:\Users\user\PycharmProjects\pythonProject1\lib\site-packages\telegram\utils\request.py", line 349, in post
    result = self._request_wrapper(
  File "C:\Users\user\PycharmProjects\pythonProject1\lib\site-packages\telegram\utils\request.py", line 276, in _request_wrapper
    raise Conflict(message)
telegram.error.Conflict: Conflict: terminated by other getUpdates request; make sure that only one bot instance is running
2021-02-23 16:20:55,775 - ERROR - Error while getting Updates: Conflict: terminated by other getUpdates request; make sure that only one bot instance is running
2021-02-23 16:20:55,775 - ERROR - No error handlers are registered, logging exception.
Traceback (most recent call last):
  File "C:\Users\user\PycharmProjects\pythonProject1\lib\site-packages\telegram\ext\updater.py", line 465, in _network_loop_retry
    if not action_cb():
  File "C:\Users\user\PycharmProjects\pythonProject1\lib\site-packages\telegram\ext\updater.py", line 416, in polling_action_cb
    updates = self.bot.get_updates(
  File "C:\Users\user\PycharmProjects\pythonProject1\lib\site-packages\telegram\bot.py", line 126, in decorator
    result = func(*args, **kwargs)
  File "C:\Users\user\PycharmProjects\pythonProject1\lib\site-packages\telegram\bot.py", line 2748, in get_updates
    result = self._post(
  File "C:\Users\user\PycharmProjects\pythonProject1\lib\site-packages\telegram\bot.py", line 258, in _post
    return self.request.post(
  File "C:\Users\user\PycharmProjects\pythonProject1\lib\site-packages\telegram\utils\request.py", line 349, in post
    result = self._request_wrapper(
  File "C:\Users\user\PycharmProjects\pythonProject1\lib\site-packages\telegram\utils\request.py", line 276, in _request_wrapper
    raise Conflict(message)
telegram.error.Conflict: Conflict: terminated by other getUpdates request; make sure that only one bot instance is running
2021-02-23 16:21:02,071 - ERROR - Error while getting Updates: Conflict: terminated by other getUpdates request; make sure that only one bot instance is running
2021-02-23 16:21:02,071 - ERROR - No error handlers are registered, logging exception.
Traceback (most recent call last):
  File "C:\Users\user\PycharmProjects\pythonProject1\lib\site-packages\telegram\ext\updater.py", line 465, in _network_loop_retry
    if not action_cb():
  File "C:\Users\user\PycharmProjects\pythonProject1\lib\site-packages\telegram\ext\updater.py", line 416, in polling_action_cb
    updates = self.bot.get_updates(
  File "C:\Users\user\PycharmProjects\pythonProject1\lib\site-packages\telegram\bot.py", line 126, in decorator
    result = func(*args, **kwargs)
  File "C:\Users\user\PycharmProjects\pythonProject1\lib\site-packages\telegram\bot.py", line 2748, in get_updates
    result = self._post(
  File "C:\Users\user\PycharmProjects\pythonProject1\lib\site-packages\telegram\bot.py", line 258, in _post
    return self.request.post(
  File "C:\Users\user\PycharmProjects\pythonProject1\lib\site-packages\telegram\utils\request.py", line 349, in post
    result = self._request_wrapper(
  File "C:\Users\user\PycharmProjects\pythonProject1\lib\site-packages\telegram\utils\request.py", line 276, in _request_wrapper
    raise Conflict(message)
telegram.error.Conflict: Conflict: terminated by other getUpdates request; make sure that only one bot instance is running
2021-02-23 16:21:09,553 - ERROR - Error while getting Updates: Conflict: terminated by other getUpdates request; make sure that only one bot instance is running
2021-02-23 16:21:09,553 - ERROR - No error handlers are registered, logging exception.
Traceback (most recent call last):
  File "C:\Users\user\PycharmProjects\pythonProject1\lib\site-packages\telegram\ext\updater.py", line 465, in _network_loop_retry
    if not action_cb():
  File "C:\Users\user\PycharmProjects\pythonProject1\lib\site-packages\telegram\ext\updater.py", line 416, in polling_action_cb
    updates = self.bot.get_updates(
  File "C:\Users\user\PycharmProjects\pythonProject1\lib\site-packages\telegram\bot.py", line 126, in decorator
    result = func(*args, **kwargs)
  File "C:\Users\user\PycharmProjects\pythonProject1\lib\site-packages\telegram\bot.py", line 2748, in get_updates
    result = self._post(
  File "C:\Users\user\PycharmProjects\pythonProject1\lib\site-packages\telegram\bot.py", line 258, in _post
    return self.request.post(
  File "C:\Users\user\PycharmProjects\pythonProject1\lib\site-packages\telegram\utils\request.py", line 349, in post
    result = self._request_wrapper(
  File "C:\Users\user\PycharmProjects\pythonProject1\lib\site-packages\telegram\utils\request.py", line 276, in _request_wrapper
    raise Conflict(message)
telegram.error.Conflict: Conflict: terminated by other getUpdates request; make sure that only one bot instance is running
2021-02-23 16:21:19,387 - ERROR - Error while getting Updates: Conflict: terminated by other getUpdates request; make sure that only one bot instance is running
2021-02-23 16:21:19,387 - ERROR - No error handlers are registered, logging exception.
Traceback (most recent call last):
  File "C:\Users\user\PycharmProjects\pythonProject1\lib\site-packages\telegram\ext\updater.py", line 465, in _network_loop_retry
    if not action_cb():
  File "C:\Users\user\PycharmProjects\pythonProject1\lib\site-packages\telegram\ext\updater.py", line 416, in polling_action_cb
    updates = self.bot.get_updates(
  File "C:\Users\user\PycharmProjects\pythonProject1\lib\site-packages\telegram\bot.py", line 126, in decorator
    result = func(*args, **kwargs)
  File "C:\Users\user\PycharmProjects\pythonProject1\lib\site-packages\telegram\bot.py", line 2748, in get_updates
    result = self._post(
  File "C:\Users\user\PycharmProjects\pythonProject1\lib\site-packages\telegram\bot.py", line 258, in _post
    return self.request.post(
  File "C:\Users\user\PycharmProjects\pythonProject1\lib\site-packages\telegram\utils\request.py", line 349, in post
    result = self._request_wrapper(
  File "C:\Users\user\PycharmProjects\pythonProject1\lib\site-packages\telegram\utils\request.py", line 276, in _request_wrapper
    raise Conflict(message)
telegram.error.Conflict: Conflict: terminated by other getUpdates request; make sure that only one bot instance is running
2021-02-23 16:21:29,207 - ERROR - Error while getting Updates: Conflict: terminated by other getUpdates request; make sure that only one bot instance is running
2021-02-23 16:21:29,208 - ERROR - No error handlers are registered, logging exception.
Traceback (most recent call last):
  File "C:\Users\user\PycharmProjects\pythonProject1\lib\site-packages\telegram\ext\updater.py", line 465, in _network_loop_retry
    if not action_cb():
  File "C:\Users\user\PycharmProjects\pythonProject1\lib\site-packages\telegram\ext\updater.py", line 416, in polling_action_cb
    updates = self.bot.get_updates(
  File "C:\Users\user\PycharmProjects\pythonProject1\lib\site-packages\telegram\bot.py", line 126, in decorator
    result = func(*args, **kwargs)
  File "C:\Users\user\PycharmProjects\pythonProject1\lib\site-packages\telegram\bot.py", line 2748, in get_updates
    result = self._post(
  File "C:\Users\user\PycharmProjects\pythonProject1\lib\site-packages\telegram\bot.py", line 258, in _post
    return self.request.post(
  File "C:\Users\user\PycharmProjects\pythonProject1\lib\site-packages\telegram\utils\request.py", line 349, in post
    result = self._request_wrapper(
  File "C:\Users\user\PycharmProjects\pythonProject1\lib\site-packages\telegram\utils\request.py", line 276, in _request_wrapper
    raise Conflict(message)
telegram.error.Conflict: Conflict: terminated by other getUpdates request; make sure that only one bot instance is running
2021-02-23 16:21:42,066 - ERROR - Error while getting Updates: Conflict: terminated by other getUpdates request; make sure that only one bot instance is running
2021-02-23 16:21:42,066 - ERROR - No error handlers are registered, logging exception.
Traceback (most recent call last):
  File "C:\Users\user\PycharmProjects\pythonProject1\lib\site-packages\telegram\ext\updater.py", line 465, in _network_loop_retry
    if not action_cb():
  File "C:\Users\user\PycharmProjects\pythonProject1\lib\site-packages\telegram\ext\updater.py", line 416, in polling_action_cb
    updates = self.bot.get_updates(
  File "C:\Users\user\PycharmProjects\pythonProject1\lib\site-packages\telegram\bot.py", line 126, in decorator
    result = func(*args, **kwargs)
  File "C:\Users\user\PycharmProjects\pythonProject1\lib\site-packages\telegram\bot.py", line 2748, in get_updates
    result = self._post(
  File "C:\Users\user\PycharmProjects\pythonProject1\lib\site-packages\telegram\bot.py", line 258, in _post
    return self.request.post(
  File "C:\Users\user\PycharmProjects\pythonProject1\lib\site-packages\telegram\utils\request.py", line 349, in post
    result = self._request_wrapper(
  File "C:\Users\user\PycharmProjects\pythonProject1\lib\site-packages\telegram\utils\request.py", line 276, in _request_wrapper
    raise Conflict(message)
telegram.error.Conflict: Conflict: terminated by other getUpdates request; make sure that only one bot instance is running
2021-02-23 16:21:58,223 - ERROR - Error while getting Updates: Conflict: terminated by other getUpdates request; make sure that only one bot instance is running
2021-02-23 16:21:58,223 - ERROR - No error handlers are registered, logging exception.
Traceback (most recent call last):
  File "C:\Users\user\PycharmProjects\pythonProject1\lib\site-packages\telegram\ext\updater.py", line 465, in _network_loop_retry
    if not action_cb():
  File "C:\Users\user\PycharmProjects\pythonProject1\lib\site-packages\telegram\ext\updater.py", line 416, in polling_action_cb
    updates = self.bot.get_updates(
  File "C:\Users\user\PycharmProjects\pythonProject1\lib\site-packages\telegram\bot.py", line 126, in decorator
    result = func(*args, **kwargs)
  File "C:\Users\user\PycharmProjects\pythonProject1\lib\site-packages\telegram\bot.py", line 2748, in get_updates
    result = self._post(
  File "C:\Users\user\PycharmProjects\pythonProject1\lib\site-packages\telegram\bot.py", line 258, in _post
    return self.request.post(
  File "C:\Users\user\PycharmProjects\pythonProject1\lib\site-packages\telegram\utils\request.py", line 349, in post
    result = self._request_wrapper(
  File "C:\Users\user\PycharmProjects\pythonProject1\lib\site-packages\telegram\utils\request.py", line 276, in _request_wrapper
    raise Conflict(message)
telegram.error.Conflict: Conflict: terminated by other getUpdates request; make sure that only one bot instance is running
2021-02-26 14:11:19,152 - INFO - Scheduler started
2021-02-26 14:11:47,776 - ERROR - ERROR:  duplicate key value violates unique constraint "chat_id"
DETAIL:  Key (chat_id)=(350402934) already exists.
Traceback (most recent call last):
  File "C:\Users\user\PycharmProjects\InvestBot\DB\Queries\dbConnection.py", line 31, in query
    records = update_db(conn,sql)
  File "C:\Users\user\PycharmProjects\InvestBot\DB\Queries\dbConnection.py", line 21, in update_db
    cursor.execute(sql)
psycopg2.errors.UniqueViolation: duplicate key value violates unique constraint "chat_id"
DETAIL:  Key (chat_id)=(350402934) already exists.

2021-02-26 14:11:52,307 - ERROR - ERROR:  duplicate key value violates unique constraint "chat_id"
DETAIL:  Key (chat_id)=(350402934) already exists.
Traceback (most recent call last):
  File "C:\Users\user\PycharmProjects\InvestBot\DB\Queries\dbConnection.py", line 31, in query
    records = update_db(conn,sql)
  File "C:\Users\user\PycharmProjects\InvestBot\DB\Queries\dbConnection.py", line 21, in update_db
    cursor.execute(sql)
psycopg2.errors.UniqueViolation: duplicate key value violates unique constraint "chat_id"
DETAIL:  Key (chat_id)=(350402934) already exists.

2021-02-26 14:12:29,838 - ERROR - ERROR:  duplicate key value violates unique constraint "chat_id"
DETAIL:  Key (chat_id)=(350402934) already exists.
Traceback (most recent call last):
  File "C:\Users\user\PycharmProjects\InvestBot\DB\Queries\dbConnection.py", line 31, in query
    records = update_db(conn,sql)
  File "C:\Users\user\PycharmProjects\InvestBot\DB\Queries\dbConnection.py", line 21, in update_db
    cursor.execute(sql)
psycopg2.errors.UniqueViolation: duplicate key value violates unique constraint "chat_id"
DETAIL:  Key (chat_id)=(350402934) already exists.

2021-02-26 14:12:54,161 - INFO - Scheduler started
2021-02-26 14:14:11,802 - INFO - Scheduler started
2021-02-26 14:15:29,471 - INFO - Scheduler started
2021-02-26 14:22:02,496 - INFO - Scheduler started
2021-02-28 23:04:47,521 - INFO - Scheduler started
2021-02-28 23:05:05,853 - ERROR - ERROR:  duplicate key value violates unique constraint "chat_id"
DETAIL:  Key (chat_id)=(350402934) already exists.
Traceback (most recent call last):
  File "C:\Users\user\PycharmProjects\InvestBot\DB\Queries\dbConnection.py", line 31, in query
    records = update_db(conn,sql)
  File "C:\Users\user\PycharmProjects\InvestBot\DB\Queries\dbConnection.py", line 21, in update_db
    cursor.execute(sql)
psycopg2.errors.UniqueViolation: duplicate key value violates unique constraint "chat_id"
DETAIL:  Key (chat_id)=(350402934) already exists.

2021-02-28 23:06:01,748 - ERROR - ERROR:  duplicate key value violates unique constraint "chat_id"
DETAIL:  Key (chat_id)=(350402934) already exists.
Traceback (most recent call last):
  File "C:\Users\user\PycharmProjects\InvestBot\DB\Queries\dbConnection.py", line 31, in query
    records = update_db(conn,sql)
  File "C:\Users\user\PycharmProjects\InvestBot\DB\Queries\dbConnection.py", line 21, in update_db
    cursor.execute(sql)
psycopg2.errors.UniqueViolation: duplicate key value violates unique constraint "chat_id"
DETAIL:  Key (chat_id)=(350402934) already exists.

2021-02-28 23:06:54,937 - ERROR - ERROR:  duplicate key value violates unique constraint "chat_id"
DETAIL:  Key (chat_id)=(350402934) already exists.
Traceback (most recent call last):
  File "C:\Users\user\PycharmProjects\InvestBot\DB\Queries\dbConnection.py", line 31, in query
    records = update_db(conn,sql)
  File "C:\Users\user\PycharmProjects\InvestBot\DB\Queries\dbConnection.py", line 21, in update_db
    cursor.execute(sql)
psycopg2.errors.UniqueViolation: duplicate key value violates unique constraint "chat_id"
DETAIL:  Key (chat_id)=(350402934) already exists.

2021-02-28 23:06:57,715 - ERROR - ERROR:  duplicate key value violates unique constraint "chat_id"
DETAIL:  Key (chat_id)=(350402934) already exists.
Traceback (most recent call last):
  File "C:\Users\user\PycharmProjects\InvestBot\DB\Queries\dbConnection.py", line 31, in query
    records = update_db(conn,sql)
  File "C:\Users\user\PycharmProjects\InvestBot\DB\Queries\dbConnection.py", line 21, in update_db
    cursor.execute(sql)
psycopg2.errors.UniqueViolation: duplicate key value violates unique constraint "chat_id"
DETAIL:  Key (chat_id)=(350402934) already exists.

2021-02-28 23:07:15,588 - INFO - Scheduler started
2021-02-28 23:07:16,750 - ERROR - ERROR:  duplicate key value violates unique constraint "chat_id"
DETAIL:  Key (chat_id)=(350402934) already exists.
Traceback (most recent call last):
  File "C:\Users\user\PycharmProjects\InvestBot\DB\Queries\dbConnection.py", line 31, in query
    records = update_db(conn,sql)
  File "C:\Users\user\PycharmProjects\InvestBot\DB\Queries\dbConnection.py", line 21, in update_db
    cursor.execute(sql)
psycopg2.errors.UniqueViolation: duplicate key value violates unique constraint "chat_id"
DETAIL:  Key (chat_id)=(350402934) already exists.

2021-03-01 00:11:30,566 - ERROR - Error while getting Updates: Conflict: terminated by other getUpdates request; make sure that only one bot instance is running
2021-03-01 00:11:30,567 - ERROR - No error handlers are registered, logging exception.
Traceback (most recent call last):
  File "C:\Users\user\PycharmProjects\pythonProject1\lib\site-packages\telegram\ext\updater.py", line 465, in _network_loop_retry
    if not action_cb():
  File "C:\Users\user\PycharmProjects\pythonProject1\lib\site-packages\telegram\ext\updater.py", line 416, in polling_action_cb
    updates = self.bot.get_updates(
  File "C:\Users\user\PycharmProjects\pythonProject1\lib\site-packages\telegram\bot.py", line 126, in decorator
    result = func(*args, **kwargs)
  File "C:\Users\user\PycharmProjects\pythonProject1\lib\site-packages\telegram\bot.py", line 2748, in get_updates
    result = self._post(
  File "C:\Users\user\PycharmProjects\pythonProject1\lib\site-packages\telegram\bot.py", line 258, in _post
    return self.request.post(
  File "C:\Users\user\PycharmProjects\pythonProject1\lib\site-packages\telegram\utils\request.py", line 349, in post
    result = self._request_wrapper(
  File "C:\Users\user\PycharmProjects\pythonProject1\lib\site-packages\telegram\utils\request.py", line 276, in _request_wrapper
    raise Conflict(message)
telegram.error.Conflict: Conflict: terminated by other getUpdates request; make sure that only one bot instance is running
2021-03-01 00:11:35,995 - ERROR - Error while getting Updates: Conflict: terminated by other getUpdates request; make sure that only one bot instance is running
2021-03-01 00:11:35,996 - ERROR - No error handlers are registered, logging exception.
Traceback (most recent call last):
  File "C:\Users\user\PycharmProjects\pythonProject1\lib\site-packages\telegram\ext\updater.py", line 465, in _network_loop_retry
    if not action_cb():
  File "C:\Users\user\PycharmProjects\pythonProject1\lib\site-packages\telegram\ext\updater.py", line 416, in polling_action_cb
    updates = self.bot.get_updates(
  File "C:\Users\user\PycharmProjects\pythonProject1\lib\site-packages\telegram\bot.py", line 126, in decorator
    result = func(*args, **kwargs)
  File "C:\Users\user\PycharmProjects\pythonProject1\lib\site-packages\telegram\bot.py", line 2748, in get_updates
    result = self._post(
  File "C:\Users\user\PycharmProjects\pythonProject1\lib\site-packages\telegram\bot.py", line 258, in _post
    return self.request.post(
  File "C:\Users\user\PycharmProjects\pythonProject1\lib\site-packages\telegram\utils\request.py", line 349, in post
    result = self._request_wrapper(
  File "C:\Users\user\PycharmProjects\pythonProject1\lib\site-packages\telegram\utils\request.py", line 276, in _request_wrapper
    raise Conflict(message)
telegram.error.Conflict: Conflict: terminated by other getUpdates request; make sure that only one bot instance is running
2021-03-01 00:11:42,484 - ERROR - Error while getting Updates: Conflict: terminated by other getUpdates request; make sure that only one bot instance is running
2021-03-01 00:11:42,485 - ERROR - No error handlers are registered, logging exception.
Traceback (most recent call last):
  File "C:\Users\user\PycharmProjects\pythonProject1\lib\site-packages\telegram\ext\updater.py", line 465, in _network_loop_retry
    if not action_cb():
  File "C:\Users\user\PycharmProjects\pythonProject1\lib\site-packages\telegram\ext\updater.py", line 416, in polling_action_cb
    updates = self.bot.get_updates(
  File "C:\Users\user\PycharmProjects\pythonProject1\lib\site-packages\telegram\bot.py", line 126, in decorator
    result = func(*args, **kwargs)
  File "C:\Users\user\PycharmProjects\pythonProject1\lib\site-packages\telegram\bot.py", line 2748, in get_updates
    result = self._post(
  File "C:\Users\user\PycharmProjects\pythonProject1\lib\site-packages\telegram\bot.py", line 258, in _post
    return self.request.post(
  File "C:\Users\user\PycharmProjects\pythonProject1\lib\site-packages\telegram\utils\request.py", line 349, in post
    result = self._request_wrapper(
  File "C:\Users\user\PycharmProjects\pythonProject1\lib\site-packages\telegram\utils\request.py", line 276, in _request_wrapper
    raise Conflict(message)
telegram.error.Conflict: Conflict: terminated by other getUpdates request; make sure that only one bot instance is running
2021-03-01 00:11:49,148 - ERROR - Error while getting Updates: Conflict: terminated by other getUpdates request; make sure that only one bot instance is running
2021-03-01 00:11:49,149 - ERROR - No error handlers are registered, logging exception.
Traceback (most recent call last):
  File "C:\Users\user\PycharmProjects\pythonProject1\lib\site-packages\telegram\ext\updater.py", line 465, in _network_loop_retry
    if not action_cb():
  File "C:\Users\user\PycharmProjects\pythonProject1\lib\site-packages\telegram\ext\updater.py", line 416, in polling_action_cb
    updates = self.bot.get_updates(
  File "C:\Users\user\PycharmProjects\pythonProject1\lib\site-packages\telegram\bot.py", line 126, in decorator
    result = func(*args, **kwargs)
  File "C:\Users\user\PycharmProjects\pythonProject1\lib\site-packages\telegram\bot.py", line 2748, in get_updates
    result = self._post(
  File "C:\Users\user\PycharmProjects\pythonProject1\lib\site-packages\telegram\bot.py", line 258, in _post
    return self.request.post(
  File "C:\Users\user\PycharmProjects\pythonProject1\lib\site-packages\telegram\utils\request.py", line 349, in post
    result = self._request_wrapper(
  File "C:\Users\user\PycharmProjects\pythonProject1\lib\site-packages\telegram\utils\request.py", line 276, in _request_wrapper
    raise Conflict(message)
telegram.error.Conflict: Conflict: terminated by other getUpdates request; make sure that only one bot instance is running
2021-03-01 00:12:20,327 - ERROR - Error while getting Updates: Conflict: terminated by other getUpdates request; make sure that only one bot instance is running
2021-03-01 00:12:20,327 - ERROR - No error handlers are registered, logging exception.
Traceback (most recent call last):
  File "C:\Users\user\PycharmProjects\pythonProject1\lib\site-packages\telegram\ext\updater.py", line 465, in _network_loop_retry
    if not action_cb():
  File "C:\Users\user\PycharmProjects\pythonProject1\lib\site-packages\telegram\ext\updater.py", line 416, in polling_action_cb
    updates = self.bot.get_updates(
  File "C:\Users\user\PycharmProjects\pythonProject1\lib\site-packages\telegram\bot.py", line 126, in decorator
    result = func(*args, **kwargs)
  File "C:\Users\user\PycharmProjects\pythonProject1\lib\site-packages\telegram\bot.py", line 2748, in get_updates
    result = self._post(
  File "C:\Users\user\PycharmProjects\pythonProject1\lib\site-packages\telegram\bot.py", line 258, in _post
    return self.request.post(
  File "C:\Users\user\PycharmProjects\pythonProject1\lib\site-packages\telegram\utils\request.py", line 349, in post
    result = self._request_wrapper(
  File "C:\Users\user\PycharmProjects\pythonProject1\lib\site-packages\telegram\utils\request.py", line 276, in _request_wrapper
    raise Conflict(message)
telegram.error.Conflict: Conflict: terminated by other getUpdates request; make sure that only one bot instance is running
2021-03-01 00:12:25,855 - ERROR - Error while getting Updates: Conflict: terminated by other getUpdates request; make sure that only one bot instance is running
2021-03-01 00:12:25,856 - ERROR - No error handlers are registered, logging exception.
Traceback (most recent call last):
  File "C:\Users\user\PycharmProjects\pythonProject1\lib\site-packages\telegram\ext\updater.py", line 465, in _network_loop_retry
    if not action_cb():
  File "C:\Users\user\PycharmProjects\pythonProject1\lib\site-packages\telegram\ext\updater.py", line 416, in polling_action_cb
    updates = self.bot.get_updates(
  File "C:\Users\user\PycharmProjects\pythonProject1\lib\site-packages\telegram\bot.py", line 126, in decorator
    result = func(*args, **kwargs)
  File "C:\Users\user\PycharmProjects\pythonProject1\lib\site-packages\telegram\bot.py", line 2748, in get_updates
    result = self._post(
  File "C:\Users\user\PycharmProjects\pythonProject1\lib\site-packages\telegram\bot.py", line 258, in _post
    return self.request.post(
  File "C:\Users\user\PycharmProjects\pythonProject1\lib\site-packages\telegram\utils\request.py", line 349, in post
    result = self._request_wrapper(
  File "C:\Users\user\PycharmProjects\pythonProject1\lib\site-packages\telegram\utils\request.py", line 276, in _request_wrapper
    raise Conflict(message)
telegram.error.Conflict: Conflict: terminated by other getUpdates request; make sure that only one bot instance is running
2021-03-01 00:12:31,893 - ERROR - Error while getting Updates: Conflict: terminated by other getUpdates request; make sure that only one bot instance is running
2021-03-01 00:12:31,894 - ERROR - No error handlers are registered, logging exception.
Traceback (most recent call last):
  File "C:\Users\user\PycharmProjects\pythonProject1\lib\site-packages\telegram\ext\updater.py", line 465, in _network_loop_retry
    if not action_cb():
  File "C:\Users\user\PycharmProjects\pythonProject1\lib\site-packages\telegram\ext\updater.py", line 416, in polling_action_cb
    updates = self.bot.get_updates(
  File "C:\Users\user\PycharmProjects\pythonProject1\lib\site-packages\telegram\bot.py", line 126, in decorator
    result = func(*args, **kwargs)
  File "C:\Users\user\PycharmProjects\pythonProject1\lib\site-packages\telegram\bot.py", line 2748, in get_updates
    result = self._post(
  File "C:\Users\user\PycharmProjects\pythonProject1\lib\site-packages\telegram\bot.py", line 258, in _post
    return self.request.post(
  File "C:\Users\user\PycharmProjects\pythonProject1\lib\site-packages\telegram\utils\request.py", line 349, in post
    result = self._request_wrapper(
  File "C:\Users\user\PycharmProjects\pythonProject1\lib\site-packages\telegram\utils\request.py", line 276, in _request_wrapper
    raise Conflict(message)
telegram.error.Conflict: Conflict: terminated by other getUpdates request; make sure that only one bot instance is running
2021-03-01 00:48:02,408 - INFO - Scheduler started
2021-03-01 00:48:03,695 - ERROR - Error while getting Updates: Conflict: terminated by other getUpdates request; make sure that only one bot instance is running
2021-03-01 00:48:03,696 - ERROR - No error handlers are registered, logging exception.
Traceback (most recent call last):
  File "C:\Users\user\PycharmProjects\pythonProject1\lib\site-packages\telegram\ext\updater.py", line 465, in _network_loop_retry
    if not action_cb():
  File "C:\Users\user\PycharmProjects\pythonProject1\lib\site-packages\telegram\ext\updater.py", line 416, in polling_action_cb
    updates = self.bot.get_updates(
  File "C:\Users\user\PycharmProjects\pythonProject1\lib\site-packages\telegram\bot.py", line 126, in decorator
    result = func(*args, **kwargs)
  File "C:\Users\user\PycharmProjects\pythonProject1\lib\site-packages\telegram\bot.py", line 2748, in get_updates
    result = self._post(
  File "C:\Users\user\PycharmProjects\pythonProject1\lib\site-packages\telegram\bot.py", line 258, in _post
    return self.request.post(
  File "C:\Users\user\PycharmProjects\pythonProject1\lib\site-packages\telegram\utils\request.py", line 349, in post
    result = self._request_wrapper(
  File "C:\Users\user\PycharmProjects\pythonProject1\lib\site-packages\telegram\utils\request.py", line 276, in _request_wrapper
    raise Conflict(message)
telegram.error.Conflict: Conflict: terminated by other getUpdates request; make sure that only one bot instance is running
2021-03-01 00:48:07,879 - ERROR - Error while getting Updates: Conflict: terminated by other getUpdates request; make sure that only one bot instance is running
2021-03-01 00:48:07,880 - ERROR - No error handlers are registered, logging exception.
Traceback (most recent call last):
  File "C:\Users\user\PycharmProjects\pythonProject\venv\lib\site-packages\telegram\ext\updater.py", line 465, in _network_loop_retry
    if not action_cb():
  File "C:\Users\user\PycharmProjects\pythonProject\venv\lib\site-packages\telegram\ext\updater.py", line 416, in polling_action_cb
    updates = self.bot.get_updates(
  File "<decorator-gen-31>", line 2, in get_updates
  File "C:\Users\user\PycharmProjects\pythonProject\venv\lib\site-packages\telegram\bot.py", line 135, in decorator
    result = func(*args, **kwargs)
  File "C:\Users\user\PycharmProjects\pythonProject\venv\lib\site-packages\telegram\bot.py", line 2638, in get_updates
    result = self._post(
  File "C:\Users\user\PycharmProjects\pythonProject\venv\lib\site-packages\telegram\bot.py", line 245, in _post
    return self.request.post(f'{self.base_url}/{endpoint}', data=data, timeout=timeout)
  File "C:\Users\user\PycharmProjects\pythonProject\venv\lib\site-packages\telegram\utils\request.py", line 349, in post
    result = self._request_wrapper(
  File "C:\Users\user\PycharmProjects\pythonProject\venv\lib\site-packages\telegram\utils\request.py", line 276, in _request_wrapper
    raise Conflict(message)
telegram.error.Conflict: Conflict: terminated by other getUpdates request; make sure that only one bot instance is running
2021-03-01 00:48:09,102 - ERROR - Error while getting Updates: Conflict: terminated by other getUpdates request; make sure that only one bot instance is running
2021-03-01 00:48:09,102 - ERROR - No error handlers are registered, logging exception.
Traceback (most recent call last):
  File "C:\Users\user\PycharmProjects\pythonProject1\lib\site-packages\telegram\ext\updater.py", line 465, in _network_loop_retry
    if not action_cb():
  File "C:\Users\user\PycharmProjects\pythonProject1\lib\site-packages\telegram\ext\updater.py", line 416, in polling_action_cb
    updates = self.bot.get_updates(
  File "C:\Users\user\PycharmProjects\pythonProject1\lib\site-packages\telegram\bot.py", line 126, in decorator
    result = func(*args, **kwargs)
  File "C:\Users\user\PycharmProjects\pythonProject1\lib\site-packages\telegram\bot.py", line 2748, in get_updates
    result = self._post(
  File "C:\Users\user\PycharmProjects\pythonProject1\lib\site-packages\telegram\bot.py", line 258, in _post
    return self.request.post(
  File "C:\Users\user\PycharmProjects\pythonProject1\lib\site-packages\telegram\utils\request.py", line 349, in post
    result = self._request_wrapper(
  File "C:\Users\user\PycharmProjects\pythonProject1\lib\site-packages\telegram\utils\request.py", line 276, in _request_wrapper
    raise Conflict(message)
telegram.error.Conflict: Conflict: terminated by other getUpdates request; make sure that only one bot instance is running
2021-03-01 00:48:14,140 - ERROR - Error while getting Updates: Conflict: terminated by other getUpdates request; make sure that only one bot instance is running
2021-03-01 00:48:14,141 - ERROR - No error handlers are registered, logging exception.
Traceback (most recent call last):
  File "C:\Users\user\PycharmProjects\pythonProject\venv\lib\site-packages\telegram\ext\updater.py", line 465, in _network_loop_retry
    if not action_cb():
  File "C:\Users\user\PycharmProjects\pythonProject\venv\lib\site-packages\telegram\ext\updater.py", line 416, in polling_action_cb
    updates = self.bot.get_updates(
  File "<decorator-gen-31>", line 2, in get_updates
  File "C:\Users\user\PycharmProjects\pythonProject\venv\lib\site-packages\telegram\bot.py", line 135, in decorator
    result = func(*args, **kwargs)
  File "C:\Users\user\PycharmProjects\pythonProject\venv\lib\site-packages\telegram\bot.py", line 2638, in get_updates
    result = self._post(
  File "C:\Users\user\PycharmProjects\pythonProject\venv\lib\site-packages\telegram\bot.py", line 245, in _post
    return self.request.post(f'{self.base_url}/{endpoint}', data=data, timeout=timeout)
  File "C:\Users\user\PycharmProjects\pythonProject\venv\lib\site-packages\telegram\utils\request.py", line 349, in post
    result = self._request_wrapper(
  File "C:\Users\user\PycharmProjects\pythonProject\venv\lib\site-packages\telegram\utils\request.py", line 276, in _request_wrapper
    raise Conflict(message)
telegram.error.Conflict: Conflict: terminated by other getUpdates request; make sure that only one bot instance is running
2021-03-01 00:48:15,575 - ERROR - Error while getting Updates: Conflict: terminated by other getUpdates request; make sure that only one bot instance is running
2021-03-01 00:48:15,576 - ERROR - No error handlers are registered, logging exception.
Traceback (most recent call last):
  File "C:\Users\user\PycharmProjects\pythonProject1\lib\site-packages\telegram\ext\updater.py", line 465, in _network_loop_retry
    if not action_cb():
  File "C:\Users\user\PycharmProjects\pythonProject1\lib\site-packages\telegram\ext\updater.py", line 416, in polling_action_cb
    updates = self.bot.get_updates(
  File "C:\Users\user\PycharmProjects\pythonProject1\lib\site-packages\telegram\bot.py", line 126, in decorator
    result = func(*args, **kwargs)
  File "C:\Users\user\PycharmProjects\pythonProject1\lib\site-packages\telegram\bot.py", line 2748, in get_updates
    result = self._post(
  File "C:\Users\user\PycharmProjects\pythonProject1\lib\site-packages\telegram\bot.py", line 258, in _post
    return self.request.post(
  File "C:\Users\user\PycharmProjects\pythonProject1\lib\site-packages\telegram\utils\request.py", line 349, in post
    result = self._request_wrapper(
  File "C:\Users\user\PycharmProjects\pythonProject1\lib\site-packages\telegram\utils\request.py", line 276, in _request_wrapper
    raise Conflict(message)
telegram.error.Conflict: Conflict: terminated by other getUpdates request; make sure that only one bot instance is running
2021-03-01 00:48:19,869 - ERROR - Error while getting Updates: Conflict: terminated by other getUpdates request; make sure that only one bot instance is running
2021-03-01 00:48:19,871 - ERROR - No error handlers are registered, logging exception.
Traceback (most recent call last):
  File "C:\Users\user\PycharmProjects\pythonProject\venv\lib\site-packages\telegram\ext\updater.py", line 465, in _network_loop_retry
    if not action_cb():
  File "C:\Users\user\PycharmProjects\pythonProject\venv\lib\site-packages\telegram\ext\updater.py", line 416, in polling_action_cb
    updates = self.bot.get_updates(
  File "<decorator-gen-31>", line 2, in get_updates
  File "C:\Users\user\PycharmProjects\pythonProject\venv\lib\site-packages\telegram\bot.py", line 135, in decorator
    result = func(*args, **kwargs)
  File "C:\Users\user\PycharmProjects\pythonProject\venv\lib\site-packages\telegram\bot.py", line 2638, in get_updates
    result = self._post(
  File "C:\Users\user\PycharmProjects\pythonProject\venv\lib\site-packages\telegram\bot.py", line 245, in _post
    return self.request.post(f'{self.base_url}/{endpoint}', data=data, timeout=timeout)
  File "C:\Users\user\PycharmProjects\pythonProject\venv\lib\site-packages\telegram\utils\request.py", line 349, in post
    result = self._request_wrapper(
  File "C:\Users\user\PycharmProjects\pythonProject\venv\lib\site-packages\telegram\utils\request.py", line 276, in _request_wrapper
    raise Conflict(message)
telegram.error.Conflict: Conflict: terminated by other getUpdates request; make sure that only one bot instance is running
2021-03-01 00:48:21,585 - ERROR - Error while getting Updates: Conflict: terminated by other getUpdates request; make sure that only one bot instance is running
2021-03-01 00:48:21,586 - ERROR - No error handlers are registered, logging exception.
Traceback (most recent call last):
  File "C:\Users\user\PycharmProjects\pythonProject1\lib\site-packages\telegram\ext\updater.py", line 465, in _network_loop_retry
    if not action_cb():
  File "C:\Users\user\PycharmProjects\pythonProject1\lib\site-packages\telegram\ext\updater.py", line 416, in polling_action_cb
    updates = self.bot.get_updates(
  File "C:\Users\user\PycharmProjects\pythonProject1\lib\site-packages\telegram\bot.py", line 126, in decorator
    result = func(*args, **kwargs)
  File "C:\Users\user\PycharmProjects\pythonProject1\lib\site-packages\telegram\bot.py", line 2748, in get_updates
    result = self._post(
  File "C:\Users\user\PycharmProjects\pythonProject1\lib\site-packages\telegram\bot.py", line 258, in _post
    return self.request.post(
  File "C:\Users\user\PycharmProjects\pythonProject1\lib\site-packages\telegram\utils\request.py", line 349, in post
    result = self._request_wrapper(
  File "C:\Users\user\PycharmProjects\pythonProject1\lib\site-packages\telegram\utils\request.py", line 276, in _request_wrapper
    raise Conflict(message)
telegram.error.Conflict: Conflict: terminated by other getUpdates request; make sure that only one bot instance is running
2021-03-01 00:48:26,321 - ERROR - Error while getting Updates: Conflict: terminated by other getUpdates request; make sure that only one bot instance is running
2021-03-01 00:48:26,322 - ERROR - No error handlers are registered, logging exception.
Traceback (most recent call last):
  File "C:\Users\user\PycharmProjects\pythonProject\venv\lib\site-packages\telegram\ext\updater.py", line 465, in _network_loop_retry
    if not action_cb():
  File "C:\Users\user\PycharmProjects\pythonProject\venv\lib\site-packages\telegram\ext\updater.py", line 416, in polling_action_cb
    updates = self.bot.get_updates(
  File "<decorator-gen-31>", line 2, in get_updates
  File "C:\Users\user\PycharmProjects\pythonProject\venv\lib\site-packages\telegram\bot.py", line 135, in decorator
    result = func(*args, **kwargs)
  File "C:\Users\user\PycharmProjects\pythonProject\venv\lib\site-packages\telegram\bot.py", line 2638, in get_updates
    result = self._post(
  File "C:\Users\user\PycharmProjects\pythonProject\venv\lib\site-packages\telegram\bot.py", line 245, in _post
    return self.request.post(f'{self.base_url}/{endpoint}', data=data, timeout=timeout)
  File "C:\Users\user\PycharmProjects\pythonProject\venv\lib\site-packages\telegram\utils\request.py", line 349, in post
    result = self._request_wrapper(
  File "C:\Users\user\PycharmProjects\pythonProject\venv\lib\site-packages\telegram\utils\request.py", line 276, in _request_wrapper
    raise Conflict(message)
telegram.error.Conflict: Conflict: terminated by other getUpdates request; make sure that only one bot instance is running
2021-03-01 00:48:28,873 - ERROR - Error while getting Updates: Conflict: terminated by other getUpdates request; make sure that only one bot instance is running
2021-03-01 00:48:28,874 - ERROR - No error handlers are registered, logging exception.
Traceback (most recent call last):
  File "C:\Users\user\PycharmProjects\pythonProject1\lib\site-packages\telegram\ext\updater.py", line 465, in _network_loop_retry
    if not action_cb():
  File "C:\Users\user\PycharmProjects\pythonProject1\lib\site-packages\telegram\ext\updater.py", line 416, in polling_action_cb
    updates = self.bot.get_updates(
  File "C:\Users\user\PycharmProjects\pythonProject1\lib\site-packages\telegram\bot.py", line 126, in decorator
    result = func(*args, **kwargs)
  File "C:\Users\user\PycharmProjects\pythonProject1\lib\site-packages\telegram\bot.py", line 2748, in get_updates
    result = self._post(
  File "C:\Users\user\PycharmProjects\pythonProject1\lib\site-packages\telegram\bot.py", line 258, in _post
    return self.request.post(
  File "C:\Users\user\PycharmProjects\pythonProject1\lib\site-packages\telegram\utils\request.py", line 349, in post
    result = self._request_wrapper(
  File "C:\Users\user\PycharmProjects\pythonProject1\lib\site-packages\telegram\utils\request.py", line 276, in _request_wrapper
    raise Conflict(message)
telegram.error.Conflict: Conflict: terminated by other getUpdates request; make sure that only one bot instance is running
2021-03-01 00:48:33,219 - ERROR - Error while getting Updates: Conflict: terminated by other getUpdates request; make sure that only one bot instance is running
2021-03-01 00:48:33,220 - ERROR - No error handlers are registered, logging exception.
Traceback (most recent call last):
  File "C:\Users\user\PycharmProjects\pythonProject\venv\lib\site-packages\telegram\ext\updater.py", line 465, in _network_loop_retry
    if not action_cb():
  File "C:\Users\user\PycharmProjects\pythonProject\venv\lib\site-packages\telegram\ext\updater.py", line 416, in polling_action_cb
    updates = self.bot.get_updates(
  File "<decorator-gen-31>", line 2, in get_updates
  File "C:\Users\user\PycharmProjects\pythonProject\venv\lib\site-packages\telegram\bot.py", line 135, in decorator
    result = func(*args, **kwargs)
  File "C:\Users\user\PycharmProjects\pythonProject\venv\lib\site-packages\telegram\bot.py", line 2638, in get_updates
    result = self._post(
  File "C:\Users\user\PycharmProjects\pythonProject\venv\lib\site-packages\telegram\bot.py", line 245, in _post
    return self.request.post(f'{self.base_url}/{endpoint}', data=data, timeout=timeout)
  File "C:\Users\user\PycharmProjects\pythonProject\venv\lib\site-packages\telegram\utils\request.py", line 349, in post
    result = self._request_wrapper(
  File "C:\Users\user\PycharmProjects\pythonProject\venv\lib\site-packages\telegram\utils\request.py", line 276, in _request_wrapper
    raise Conflict(message)
telegram.error.Conflict: Conflict: terminated by other getUpdates request; make sure that only one bot instance is running
2021-03-01 00:48:36,878 - ERROR - Error while getting Updates: Conflict: terminated by other getUpdates request; make sure that only one bot instance is running
2021-03-01 00:48:36,879 - ERROR - No error handlers are registered, logging exception.
Traceback (most recent call last):
  File "C:\Users\user\PycharmProjects\pythonProject1\lib\site-packages\telegram\ext\updater.py", line 465, in _network_loop_retry
    if not action_cb():
  File "C:\Users\user\PycharmProjects\pythonProject1\lib\site-packages\telegram\ext\updater.py", line 416, in polling_action_cb
    updates = self.bot.get_updates(
  File "C:\Users\user\PycharmProjects\pythonProject1\lib\site-packages\telegram\bot.py", line 126, in decorator
    result = func(*args, **kwargs)
  File "C:\Users\user\PycharmProjects\pythonProject1\lib\site-packages\telegram\bot.py", line 2748, in get_updates
    result = self._post(
  File "C:\Users\user\PycharmProjects\pythonProject1\lib\site-packages\telegram\bot.py", line 258, in _post
    return self.request.post(
  File "C:\Users\user\PycharmProjects\pythonProject1\lib\site-packages\telegram\utils\request.py", line 349, in post
    result = self._request_wrapper(
  File "C:\Users\user\PycharmProjects\pythonProject1\lib\site-packages\telegram\utils\request.py", line 276, in _request_wrapper
    raise Conflict(message)
telegram.error.Conflict: Conflict: terminated by other getUpdates request; make sure that only one bot instance is running
2021-03-01 00:48:41,171 - ERROR - Error while getting Updates: Conflict: terminated by other getUpdates request; make sure that only one bot instance is running
2021-03-01 00:48:41,172 - ERROR - No error handlers are registered, logging exception.
Traceback (most recent call last):
  File "C:\Users\user\PycharmProjects\pythonProject\venv\lib\site-packages\telegram\ext\updater.py", line 465, in _network_loop_retry
    if not action_cb():
  File "C:\Users\user\PycharmProjects\pythonProject\venv\lib\site-packages\telegram\ext\updater.py", line 416, in polling_action_cb
    updates = self.bot.get_updates(
  File "<decorator-gen-31>", line 2, in get_updates
  File "C:\Users\user\PycharmProjects\pythonProject\venv\lib\site-packages\telegram\bot.py", line 135, in decorator
    result = func(*args, **kwargs)
  File "C:\Users\user\PycharmProjects\pythonProject\venv\lib\site-packages\telegram\bot.py", line 2638, in get_updates
    result = self._post(
  File "C:\Users\user\PycharmProjects\pythonProject\venv\lib\site-packages\telegram\bot.py", line 245, in _post
    return self.request.post(f'{self.base_url}/{endpoint}', data=data, timeout=timeout)
  File "C:\Users\user\PycharmProjects\pythonProject\venv\lib\site-packages\telegram\utils\request.py", line 349, in post
    result = self._request_wrapper(
  File "C:\Users\user\PycharmProjects\pythonProject\venv\lib\site-packages\telegram\utils\request.py", line 276, in _request_wrapper
    raise Conflict(message)
telegram.error.Conflict: Conflict: terminated by other getUpdates request; make sure that only one bot instance is running
2021-03-01 00:48:46,489 - ERROR - Error while getting Updates: Conflict: terminated by other getUpdates request; make sure that only one bot instance is running
2021-03-01 00:48:46,489 - ERROR - No error handlers are registered, logging exception.
Traceback (most recent call last):
  File "C:\Users\user\PycharmProjects\pythonProject1\lib\site-packages\telegram\ext\updater.py", line 465, in _network_loop_retry
    if not action_cb():
  File "C:\Users\user\PycharmProjects\pythonProject1\lib\site-packages\telegram\ext\updater.py", line 416, in polling_action_cb
    updates = self.bot.get_updates(
  File "C:\Users\user\PycharmProjects\pythonProject1\lib\site-packages\telegram\bot.py", line 126, in decorator
    result = func(*args, **kwargs)
  File "C:\Users\user\PycharmProjects\pythonProject1\lib\site-packages\telegram\bot.py", line 2748, in get_updates
    result = self._post(
  File "C:\Users\user\PycharmProjects\pythonProject1\lib\site-packages\telegram\bot.py", line 258, in _post
    return self.request.post(
  File "C:\Users\user\PycharmProjects\pythonProject1\lib\site-packages\telegram\utils\request.py", line 349, in post
    result = self._request_wrapper(
  File "C:\Users\user\PycharmProjects\pythonProject1\lib\site-packages\telegram\utils\request.py", line 276, in _request_wrapper
    raise Conflict(message)
telegram.error.Conflict: Conflict: terminated by other getUpdates request; make sure that only one bot instance is running
2021-03-01 00:48:51,180 - ERROR - Error while getting Updates: Conflict: terminated by other getUpdates request; make sure that only one bot instance is running
2021-03-01 00:48:51,180 - ERROR - No error handlers are registered, logging exception.
Traceback (most recent call last):
  File "C:\Users\user\PycharmProjects\pythonProject\venv\lib\site-packages\telegram\ext\updater.py", line 465, in _network_loop_retry
    if not action_cb():
  File "C:\Users\user\PycharmProjects\pythonProject\venv\lib\site-packages\telegram\ext\updater.py", line 416, in polling_action_cb
    updates = self.bot.get_updates(
  File "<decorator-gen-31>", line 2, in get_updates
  File "C:\Users\user\PycharmProjects\pythonProject\venv\lib\site-packages\telegram\bot.py", line 135, in decorator
    result = func(*args, **kwargs)
  File "C:\Users\user\PycharmProjects\pythonProject\venv\lib\site-packages\telegram\bot.py", line 2638, in get_updates
    result = self._post(
  File "C:\Users\user\PycharmProjects\pythonProject\venv\lib\site-packages\telegram\bot.py", line 245, in _post
    return self.request.post(f'{self.base_url}/{endpoint}', data=data, timeout=timeout)
  File "C:\Users\user\PycharmProjects\pythonProject\venv\lib\site-packages\telegram\utils\request.py", line 349, in post
    result = self._request_wrapper(
  File "C:\Users\user\PycharmProjects\pythonProject\venv\lib\site-packages\telegram\utils\request.py", line 276, in _request_wrapper
    raise Conflict(message)
telegram.error.Conflict: Conflict: terminated by other getUpdates request; make sure that only one bot instance is running
2021-03-01 00:48:59,091 - ERROR - Error while getting Updates: Conflict: terminated by other getUpdates request; make sure that only one bot instance is running
2021-03-01 00:48:59,092 - ERROR - No error handlers are registered, logging exception.
Traceback (most recent call last):
  File "C:\Users\user\PycharmProjects\pythonProject1\lib\site-packages\telegram\ext\updater.py", line 465, in _network_loop_retry
    if not action_cb():
  File "C:\Users\user\PycharmProjects\pythonProject1\lib\site-packages\telegram\ext\updater.py", line 416, in polling_action_cb
    updates = self.bot.get_updates(
  File "C:\Users\user\PycharmProjects\pythonProject1\lib\site-packages\telegram\bot.py", line 126, in decorator
    result = func(*args, **kwargs)
  File "C:\Users\user\PycharmProjects\pythonProject1\lib\site-packages\telegram\bot.py", line 2748, in get_updates
    result = self._post(
  File "C:\Users\user\PycharmProjects\pythonProject1\lib\site-packages\telegram\bot.py", line 258, in _post
    return self.request.post(
  File "C:\Users\user\PycharmProjects\pythonProject1\lib\site-packages\telegram\utils\request.py", line 349, in post
    result = self._request_wrapper(
  File "C:\Users\user\PycharmProjects\pythonProject1\lib\site-packages\telegram\utils\request.py", line 276, in _request_wrapper
    raise Conflict(message)
telegram.error.Conflict: Conflict: terminated by other getUpdates request; make sure that only one bot instance is running
2021-03-01 00:49:03,400 - ERROR - Error while getting Updates: Conflict: terminated by other getUpdates request; make sure that only one bot instance is running
2021-03-01 00:49:03,401 - ERROR - No error handlers are registered, logging exception.
Traceback (most recent call last):
  File "C:\Users\user\PycharmProjects\pythonProject\venv\lib\site-packages\telegram\ext\updater.py", line 465, in _network_loop_retry
    if not action_cb():
  File "C:\Users\user\PycharmProjects\pythonProject\venv\lib\site-packages\telegram\ext\updater.py", line 416, in polling_action_cb
    updates = self.bot.get_updates(
  File "<decorator-gen-31>", line 2, in get_updates
  File "C:\Users\user\PycharmProjects\pythonProject\venv\lib\site-packages\telegram\bot.py", line 135, in decorator
    result = func(*args, **kwargs)
  File "C:\Users\user\PycharmProjects\pythonProject\venv\lib\site-packages\telegram\bot.py", line 2638, in get_updates
    result = self._post(
  File "C:\Users\user\PycharmProjects\pythonProject\venv\lib\site-packages\telegram\bot.py", line 245, in _post
    return self.request.post(f'{self.base_url}/{endpoint}', data=data, timeout=timeout)
  File "C:\Users\user\PycharmProjects\pythonProject\venv\lib\site-packages\telegram\utils\request.py", line 349, in post
    result = self._request_wrapper(
  File "C:\Users\user\PycharmProjects\pythonProject\venv\lib\site-packages\telegram\utils\request.py", line 276, in _request_wrapper
    raise Conflict(message)
telegram.error.Conflict: Conflict: terminated by other getUpdates request; make sure that only one bot instance is running
2021-03-01 00:49:14,673 - INFO - Scheduler started
2021-03-01 00:49:15,782 - ERROR - Error while getting Updates: Conflict: terminated by other getUpdates request; make sure that only one bot instance is running
2021-03-01 00:49:15,783 - ERROR - No error handlers are registered, logging exception.
Traceback (most recent call last):
  File "C:\Users\user\PycharmProjects\pythonProject1\lib\site-packages\telegram\ext\updater.py", line 465, in _network_loop_retry
    if not action_cb():
  File "C:\Users\user\PycharmProjects\pythonProject1\lib\site-packages\telegram\ext\updater.py", line 416, in polling_action_cb
    updates = self.bot.get_updates(
  File "C:\Users\user\PycharmProjects\pythonProject1\lib\site-packages\telegram\bot.py", line 126, in decorator
    result = func(*args, **kwargs)
  File "C:\Users\user\PycharmProjects\pythonProject1\lib\site-packages\telegram\bot.py", line 2748, in get_updates
    result = self._post(
  File "C:\Users\user\PycharmProjects\pythonProject1\lib\site-packages\telegram\bot.py", line 258, in _post
    return self.request.post(
  File "C:\Users\user\PycharmProjects\pythonProject1\lib\site-packages\telegram\utils\request.py", line 349, in post
    result = self._request_wrapper(
  File "C:\Users\user\PycharmProjects\pythonProject1\lib\site-packages\telegram\utils\request.py", line 276, in _request_wrapper
    raise Conflict(message)
telegram.error.Conflict: Conflict: terminated by other getUpdates request; make sure that only one bot instance is running
2021-03-01 00:49:19,084 - ERROR - ERROR:  duplicate key value violates unique constraint "chat_id"
DETAIL:  Key (chat_id)=(350402934) already exists.
Traceback (most recent call last):
  File "C:\Users\user\PycharmProjects\InvestBot\DB\Queries\dbConnection.py", line 31, in query
    records = update_db(conn,sql)
  File "C:\Users\user\PycharmProjects\InvestBot\DB\Queries\dbConnection.py", line 21, in update_db
    cursor.execute(sql)
psycopg2.errors.UniqueViolation: duplicate key value violates unique constraint "chat_id"
DETAIL:  Key (chat_id)=(350402934) already exists.

2021-03-01 00:49:19,085 - ERROR - No error handlers are registered, logging exception.
Traceback (most recent call last):
  File "C:\Users\user\PycharmProjects\pythonProject1\lib\site-packages\telegram\ext\dispatcher.py", line 442, in process_update
    handler.handle_update(update, self, check, context)
  File "C:\Users\user\PycharmProjects\pythonProject1\lib\site-packages\telegram\ext\handler.py", line 160, in handle_update
    return self.callback(update, context)
  File "C:\Users\user\PycharmProjects\InvestBot\Handlers\CommandHandlers\BaseCommandHandler.py", line 37, in startCommand
    print(bot)
OSError: [Errno 22] Invalid argument
2021-03-01 00:49:20,081 - ERROR - Error while getting Updates: Conflict: terminated by other getUpdates request; make sure that only one bot instance is running
2021-03-01 00:49:20,081 - ERROR - No error handlers are registered, logging exception.
Traceback (most recent call last):
  File "C:\Users\user\PycharmProjects\pythonProject\venv\lib\site-packages\telegram\ext\updater.py", line 465, in _network_loop_retry
    if not action_cb():
  File "C:\Users\user\PycharmProjects\pythonProject\venv\lib\site-packages\telegram\ext\updater.py", line 416, in polling_action_cb
    updates = self.bot.get_updates(
  File "<decorator-gen-31>", line 2, in get_updates
  File "C:\Users\user\PycharmProjects\pythonProject\venv\lib\site-packages\telegram\bot.py", line 135, in decorator
    result = func(*args, **kwargs)
  File "C:\Users\user\PycharmProjects\pythonProject\venv\lib\site-packages\telegram\bot.py", line 2638, in get_updates
    result = self._post(
  File "C:\Users\user\PycharmProjects\pythonProject\venv\lib\site-packages\telegram\bot.py", line 245, in _post
    return self.request.post(f'{self.base_url}/{endpoint}', data=data, timeout=timeout)
  File "C:\Users\user\PycharmProjects\pythonProject\venv\lib\site-packages\telegram\utils\request.py", line 349, in post
    result = self._request_wrapper(
  File "C:\Users\user\PycharmProjects\pythonProject\venv\lib\site-packages\telegram\utils\request.py", line 276, in _request_wrapper
    raise Conflict(message)
telegram.error.Conflict: Conflict: terminated by other getUpdates request; make sure that only one bot instance is running
2021-03-01 00:49:21,100 - ERROR - ERROR:  duplicate key value violates unique constraint "chat_id"
DETAIL:  Key (chat_id)=(350402934) already exists.
Traceback (most recent call last):
  File "C:\Users\user\PycharmProjects\InvestBot\DB\Queries\dbConnection.py", line 31, in query
    records = update_db(conn,sql)
  File "C:\Users\user\PycharmProjects\InvestBot\DB\Queries\dbConnection.py", line 21, in update_db
    cursor.execute(sql)
psycopg2.errors.UniqueViolation: duplicate key value violates unique constraint "chat_id"
DETAIL:  Key (chat_id)=(350402934) already exists.

2021-03-01 00:49:21,102 - ERROR - No error handlers are registered, logging exception.
Traceback (most recent call last):
  File "C:\Users\user\PycharmProjects\pythonProject1\lib\site-packages\telegram\ext\dispatcher.py", line 442, in process_update
    handler.handle_update(update, self, check, context)
  File "C:\Users\user\PycharmProjects\pythonProject1\lib\site-packages\telegram\ext\handler.py", line 160, in handle_update
    return self.callback(update, context)
  File "C:\Users\user\PycharmProjects\InvestBot\Handlers\CommandHandlers\BaseCommandHandler.py", line 37, in startCommand
    print(bot)
OSError: [Errno 22] Invalid argument
2021-03-01 00:49:21,306 - ERROR - Error while getting Updates: Conflict: terminated by other getUpdates request; make sure that only one bot instance is running
2021-03-01 00:49:21,306 - ERROR - No error handlers are registered, logging exception.
Traceback (most recent call last):
  File "C:\Users\user\PycharmProjects\pythonProject1\lib\site-packages\telegram\ext\updater.py", line 465, in _network_loop_retry
    if not action_cb():
  File "C:\Users\user\PycharmProjects\pythonProject1\lib\site-packages\telegram\ext\updater.py", line 416, in polling_action_cb
    updates = self.bot.get_updates(
  File "C:\Users\user\PycharmProjects\pythonProject1\lib\site-packages\telegram\bot.py", line 126, in decorator
    result = func(*args, **kwargs)
  File "C:\Users\user\PycharmProjects\pythonProject1\lib\site-packages\telegram\bot.py", line 2748, in get_updates
    result = self._post(
  File "C:\Users\user\PycharmProjects\pythonProject1\lib\site-packages\telegram\bot.py", line 258, in _post
    return self.request.post(
  File "C:\Users\user\PycharmProjects\pythonProject1\lib\site-packages\telegram\utils\request.py", line 349, in post
    result = self._request_wrapper(
  File "C:\Users\user\PycharmProjects\pythonProject1\lib\site-packages\telegram\utils\request.py", line 276, in _request_wrapper
    raise Conflict(message)
telegram.error.Conflict: Conflict: terminated by other getUpdates request; make sure that only one bot instance is running
2021-03-01 00:49:27,310 - INFO - Scheduler started
2021-03-01 00:49:27,716 - ERROR - ERROR:  duplicate key value violates unique constraint "chat_id"
DETAIL:  Key (chat_id)=(350402934) already exists.
Traceback (most recent call last):
  File "C:\Users\user\PycharmProjects\InvestBot\DB\Queries\dbConnection.py", line 31, in query
    records = update_db(conn,sql)
  File "C:\Users\user\PycharmProjects\InvestBot\DB\Queries\dbConnection.py", line 21, in update_db
    cursor.execute(sql)
psycopg2.errors.UniqueViolation: duplicate key value violates unique constraint "chat_id"
DETAIL:  Key (chat_id)=(350402934) already exists.

2021-03-01 00:49:27,718 - ERROR - No error handlers are registered, logging exception.
Traceback (most recent call last):
  File "C:\Users\user\PycharmProjects\pythonProject1\lib\site-packages\telegram\ext\dispatcher.py", line 442, in process_update
    handler.handle_update(update, self, check, context)
  File "C:\Users\user\PycharmProjects\pythonProject1\lib\site-packages\telegram\ext\handler.py", line 160, in handle_update
    return self.callback(update, context)
  File "C:\Users\user\PycharmProjects\InvestBot\Handlers\CommandHandlers\BaseCommandHandler.py", line 37, in startCommand
    print(bot)
OSError: [Errno 22] Invalid argument
2021-03-01 00:49:28,478 - ERROR - Error while getting Updates: Conflict: terminated by other getUpdates request; make sure that only one bot instance is running
2021-03-01 00:49:28,479 - ERROR - No error handlers are registered, logging exception.
Traceback (most recent call last):
  File "C:\Users\user\PycharmProjects\pythonProject1\lib\site-packages\telegram\ext\updater.py", line 465, in _network_loop_retry
    if not action_cb():
  File "C:\Users\user\PycharmProjects\pythonProject1\lib\site-packages\telegram\ext\updater.py", line 416, in polling_action_cb
    updates = self.bot.get_updates(
  File "C:\Users\user\PycharmProjects\pythonProject1\lib\site-packages\telegram\bot.py", line 126, in decorator
    result = func(*args, **kwargs)
  File "C:\Users\user\PycharmProjects\pythonProject1\lib\site-packages\telegram\bot.py", line 2748, in get_updates
    result = self._post(
  File "C:\Users\user\PycharmProjects\pythonProject1\lib\site-packages\telegram\bot.py", line 258, in _post
    return self.request.post(
  File "C:\Users\user\PycharmProjects\pythonProject1\lib\site-packages\telegram\utils\request.py", line 349, in post
    result = self._request_wrapper(
  File "C:\Users\user\PycharmProjects\pythonProject1\lib\site-packages\telegram\utils\request.py", line 276, in _request_wrapper
    raise Conflict(message)
telegram.error.Conflict: Conflict: terminated by other getUpdates request; make sure that only one bot instance is running
2021-03-01 00:49:32,784 - ERROR - Error while getting Updates: Conflict: terminated by other getUpdates request; make sure that only one bot instance is running
2021-03-01 00:49:32,785 - ERROR - No error handlers are registered, logging exception.
Traceback (most recent call last):
  File "C:\Users\user\PycharmProjects\pythonProject\venv\lib\site-packages\telegram\ext\updater.py", line 465, in _network_loop_retry
    if not action_cb():
  File "C:\Users\user\PycharmProjects\pythonProject\venv\lib\site-packages\telegram\ext\updater.py", line 416, in polling_action_cb
    updates = self.bot.get_updates(
  File "<decorator-gen-31>", line 2, in get_updates
  File "C:\Users\user\PycharmProjects\pythonProject\venv\lib\site-packages\telegram\bot.py", line 135, in decorator
    result = func(*args, **kwargs)
  File "C:\Users\user\PycharmProjects\pythonProject\venv\lib\site-packages\telegram\bot.py", line 2638, in get_updates
    result = self._post(
  File "C:\Users\user\PycharmProjects\pythonProject\venv\lib\site-packages\telegram\bot.py", line 245, in _post
    return self.request.post(f'{self.base_url}/{endpoint}', data=data, timeout=timeout)
  File "C:\Users\user\PycharmProjects\pythonProject\venv\lib\site-packages\telegram\utils\request.py", line 349, in post
    result = self._request_wrapper(
  File "C:\Users\user\PycharmProjects\pythonProject\venv\lib\site-packages\telegram\utils\request.py", line 276, in _request_wrapper
    raise Conflict(message)
telegram.error.Conflict: Conflict: terminated by other getUpdates request; make sure that only one bot instance is running
2021-03-01 00:49:34,106 - ERROR - Error while getting Updates: Conflict: terminated by other getUpdates request; make sure that only one bot instance is running
2021-03-01 00:49:34,107 - ERROR - No error handlers are registered, logging exception.
Traceback (most recent call last):
  File "C:\Users\user\PycharmProjects\pythonProject1\lib\site-packages\telegram\ext\updater.py", line 465, in _network_loop_retry
    if not action_cb():
  File "C:\Users\user\PycharmProjects\pythonProject1\lib\site-packages\telegram\ext\updater.py", line 416, in polling_action_cb
    updates = self.bot.get_updates(
  File "C:\Users\user\PycharmProjects\pythonProject1\lib\site-packages\telegram\bot.py", line 126, in decorator
    result = func(*args, **kwargs)
  File "C:\Users\user\PycharmProjects\pythonProject1\lib\site-packages\telegram\bot.py", line 2748, in get_updates
    result = self._post(
  File "C:\Users\user\PycharmProjects\pythonProject1\lib\site-packages\telegram\bot.py", line 258, in _post
    return self.request.post(
  File "C:\Users\user\PycharmProjects\pythonProject1\lib\site-packages\telegram\utils\request.py", line 349, in post
    result = self._request_wrapper(
  File "C:\Users\user\PycharmProjects\pythonProject1\lib\site-packages\telegram\utils\request.py", line 276, in _request_wrapper
    raise Conflict(message)
telegram.error.Conflict: Conflict: terminated by other getUpdates request; make sure that only one bot instance is running
2021-03-01 00:49:38,926 - ERROR - Error while getting Updates: Conflict: terminated by other getUpdates request; make sure that only one bot instance is running
2021-03-01 00:49:38,926 - ERROR - No error handlers are registered, logging exception.
Traceback (most recent call last):
  File "C:\Users\user\PycharmProjects\pythonProject\venv\lib\site-packages\telegram\ext\updater.py", line 465, in _network_loop_retry
    if not action_cb():
  File "C:\Users\user\PycharmProjects\pythonProject\venv\lib\site-packages\telegram\ext\updater.py", line 416, in polling_action_cb
    updates = self.bot.get_updates(
  File "<decorator-gen-31>", line 2, in get_updates
  File "C:\Users\user\PycharmProjects\pythonProject\venv\lib\site-packages\telegram\bot.py", line 135, in decorator
    result = func(*args, **kwargs)
  File "C:\Users\user\PycharmProjects\pythonProject\venv\lib\site-packages\telegram\bot.py", line 2638, in get_updates
    result = self._post(
  File "C:\Users\user\PycharmProjects\pythonProject\venv\lib\site-packages\telegram\bot.py", line 245, in _post
    return self.request.post(f'{self.base_url}/{endpoint}', data=data, timeout=timeout)
  File "C:\Users\user\PycharmProjects\pythonProject\venv\lib\site-packages\telegram\utils\request.py", line 349, in post
    result = self._request_wrapper(
  File "C:\Users\user\PycharmProjects\pythonProject\venv\lib\site-packages\telegram\utils\request.py", line 276, in _request_wrapper
    raise Conflict(message)
telegram.error.Conflict: Conflict: terminated by other getUpdates request; make sure that only one bot instance is running
2021-03-01 00:49:40,663 - ERROR - Error while getting Updates: Conflict: terminated by other getUpdates request; make sure that only one bot instance is running
2021-03-01 00:49:40,663 - ERROR - No error handlers are registered, logging exception.
Traceback (most recent call last):
  File "C:\Users\user\PycharmProjects\pythonProject1\lib\site-packages\telegram\ext\updater.py", line 465, in _network_loop_retry
    if not action_cb():
  File "C:\Users\user\PycharmProjects\pythonProject1\lib\site-packages\telegram\ext\updater.py", line 416, in polling_action_cb
    updates = self.bot.get_updates(
  File "C:\Users\user\PycharmProjects\pythonProject1\lib\site-packages\telegram\bot.py", line 126, in decorator
    result = func(*args, **kwargs)
  File "C:\Users\user\PycharmProjects\pythonProject1\lib\site-packages\telegram\bot.py", line 2748, in get_updates
    result = self._post(
  File "C:\Users\user\PycharmProjects\pythonProject1\lib\site-packages\telegram\bot.py", line 258, in _post
    return self.request.post(
  File "C:\Users\user\PycharmProjects\pythonProject1\lib\site-packages\telegram\utils\request.py", line 349, in post
    result = self._request_wrapper(
  File "C:\Users\user\PycharmProjects\pythonProject1\lib\site-packages\telegram\utils\request.py", line 276, in _request_wrapper
    raise Conflict(message)
telegram.error.Conflict: Conflict: terminated by other getUpdates request; make sure that only one bot instance is running
2021-03-01 00:49:46,193 - ERROR - Error while getting Updates: Conflict: terminated by other getUpdates request; make sure that only one bot instance is running
2021-03-01 00:49:46,194 - ERROR - No error handlers are registered, logging exception.
Traceback (most recent call last):
  File "C:\Users\user\PycharmProjects\pythonProject\venv\lib\site-packages\telegram\ext\updater.py", line 465, in _network_loop_retry
    if not action_cb():
  File "C:\Users\user\PycharmProjects\pythonProject\venv\lib\site-packages\telegram\ext\updater.py", line 416, in polling_action_cb
    updates = self.bot.get_updates(
  File "<decorator-gen-31>", line 2, in get_updates
  File "C:\Users\user\PycharmProjects\pythonProject\venv\lib\site-packages\telegram\bot.py", line 135, in decorator
    result = func(*args, **kwargs)
  File "C:\Users\user\PycharmProjects\pythonProject\venv\lib\site-packages\telegram\bot.py", line 2638, in get_updates
    result = self._post(
  File "C:\Users\user\PycharmProjects\pythonProject\venv\lib\site-packages\telegram\bot.py", line 245, in _post
    return self.request.post(f'{self.base_url}/{endpoint}', data=data, timeout=timeout)
  File "C:\Users\user\PycharmProjects\pythonProject\venv\lib\site-packages\telegram\utils\request.py", line 349, in post
    result = self._request_wrapper(
  File "C:\Users\user\PycharmProjects\pythonProject\venv\lib\site-packages\telegram\utils\request.py", line 276, in _request_wrapper
    raise Conflict(message)
telegram.error.Conflict: Conflict: terminated by other getUpdates request; make sure that only one bot instance is running
2021-03-01 00:49:46,274 - ERROR - ERROR:  duplicate key value violates unique constraint "chat_id"
DETAIL:  Key (chat_id)=(350402934) already exists.
Traceback (most recent call last):
  File "C:\Users\user\PycharmProjects\InvestBot\DB\Queries\dbConnection.py", line 31, in query
    records = update_db(conn,sql)
  File "C:\Users\user\PycharmProjects\InvestBot\DB\Queries\dbConnection.py", line 21, in update_db
    cursor.execute(sql)
psycopg2.errors.UniqueViolation: duplicate key value violates unique constraint "chat_id"
DETAIL:  Key (chat_id)=(350402934) already exists.

2021-03-01 00:49:46,276 - ERROR - No error handlers are registered, logging exception.
Traceback (most recent call last):
  File "C:\Users\user\PycharmProjects\pythonProject1\lib\site-packages\telegram\ext\dispatcher.py", line 442, in process_update
    handler.handle_update(update, self, check, context)
  File "C:\Users\user\PycharmProjects\pythonProject1\lib\site-packages\telegram\ext\handler.py", line 160, in handle_update
    return self.callback(update, context)
  File "C:\Users\user\PycharmProjects\InvestBot\Handlers\CommandHandlers\BaseCommandHandler.py", line 37, in startCommand
    print(bot)
OSError: [Errno 22] Invalid argument
2021-03-01 00:49:48,790 - ERROR - Error while getting Updates: Conflict: terminated by other getUpdates request; make sure that only one bot instance is running
2021-03-01 00:49:48,790 - ERROR - No error handlers are registered, logging exception.
Traceback (most recent call last):
  File "C:\Users\user\PycharmProjects\pythonProject1\lib\site-packages\telegram\ext\updater.py", line 465, in _network_loop_retry
    if not action_cb():
  File "C:\Users\user\PycharmProjects\pythonProject1\lib\site-packages\telegram\ext\updater.py", line 416, in polling_action_cb
    updates = self.bot.get_updates(
  File "C:\Users\user\PycharmProjects\pythonProject1\lib\site-packages\telegram\bot.py", line 126, in decorator
    result = func(*args, **kwargs)
  File "C:\Users\user\PycharmProjects\pythonProject1\lib\site-packages\telegram\bot.py", line 2748, in get_updates
    result = self._post(
  File "C:\Users\user\PycharmProjects\pythonProject1\lib\site-packages\telegram\bot.py", line 258, in _post
    return self.request.post(
  File "C:\Users\user\PycharmProjects\pythonProject1\lib\site-packages\telegram\utils\request.py", line 349, in post
    result = self._request_wrapper(
  File "C:\Users\user\PycharmProjects\pythonProject1\lib\site-packages\telegram\utils\request.py", line 276, in _request_wrapper
    raise Conflict(message)
telegram.error.Conflict: Conflict: terminated by other getUpdates request; make sure that only one bot instance is running
2021-03-01 00:49:53,052 - ERROR - Error while getting Updates: Conflict: terminated by other getUpdates request; make sure that only one bot instance is running
2021-03-01 00:49:53,052 - ERROR - No error handlers are registered, logging exception.
Traceback (most recent call last):
  File "C:\Users\user\PycharmProjects\pythonProject\venv\lib\site-packages\telegram\ext\updater.py", line 465, in _network_loop_retry
    if not action_cb():
  File "C:\Users\user\PycharmProjects\pythonProject\venv\lib\site-packages\telegram\ext\updater.py", line 416, in polling_action_cb
    updates = self.bot.get_updates(
  File "<decorator-gen-31>", line 2, in get_updates
  File "C:\Users\user\PycharmProjects\pythonProject\venv\lib\site-packages\telegram\bot.py", line 135, in decorator
    result = func(*args, **kwargs)
  File "C:\Users\user\PycharmProjects\pythonProject\venv\lib\site-packages\telegram\bot.py", line 2638, in get_updates
    result = self._post(
  File "C:\Users\user\PycharmProjects\pythonProject\venv\lib\site-packages\telegram\bot.py", line 245, in _post
    return self.request.post(f'{self.base_url}/{endpoint}', data=data, timeout=timeout)
  File "C:\Users\user\PycharmProjects\pythonProject\venv\lib\site-packages\telegram\utils\request.py", line 349, in post
    result = self._request_wrapper(
  File "C:\Users\user\PycharmProjects\pythonProject\venv\lib\site-packages\telegram\utils\request.py", line 276, in _request_wrapper
    raise Conflict(message)
telegram.error.Conflict: Conflict: terminated by other getUpdates request; make sure that only one bot instance is running
2021-03-01 00:49:55,641 - ERROR - No error handlers are registered, logging exception.
Traceback (most recent call last):
  File "C:\Users\user\PycharmProjects\pythonProject1\lib\site-packages\telegram\ext\dispatcher.py", line 442, in process_update
    handler.handle_update(update, self, check, context)
  File "C:\Users\user\PycharmProjects\pythonProject1\lib\site-packages\telegram\ext\conversationhandler.py", line 549, in handle_update
    new_state = handler.handle_update(update, dispatcher, check_result, context)
  File "C:\Users\user\PycharmProjects\pythonProject1\lib\site-packages\telegram\ext\handler.py", line 160, in handle_update
    return self.callback(update, context)
  File "C:\Users\user\PycharmProjects\InvestBot\Handlers\CallBackQueryHandlers\helpCallbackQueryHandler.py", line 15, in aboutCommands
    print(chatId)
OSError: [Errno 22] Invalid argument
2021-03-01 00:49:56,738 - ERROR - Error while getting Updates: Conflict: terminated by other getUpdates request; make sure that only one bot instance is running
2021-03-01 00:49:56,739 - ERROR - No error handlers are registered, logging exception.
Traceback (most recent call last):
  File "C:\Users\user\PycharmProjects\pythonProject1\lib\site-packages\telegram\ext\updater.py", line 465, in _network_loop_retry
    if not action_cb():
  File "C:\Users\user\PycharmProjects\pythonProject1\lib\site-packages\telegram\ext\updater.py", line 416, in polling_action_cb
    updates = self.bot.get_updates(
  File "C:\Users\user\PycharmProjects\pythonProject1\lib\site-packages\telegram\bot.py", line 126, in decorator
    result = func(*args, **kwargs)
  File "C:\Users\user\PycharmProjects\pythonProject1\lib\site-packages\telegram\bot.py", line 2748, in get_updates
    result = self._post(
  File "C:\Users\user\PycharmProjects\pythonProject1\lib\site-packages\telegram\bot.py", line 258, in _post
    return self.request.post(
  File "C:\Users\user\PycharmProjects\pythonProject1\lib\site-packages\telegram\utils\request.py", line 349, in post
    result = self._request_wrapper(
  File "C:\Users\user\PycharmProjects\pythonProject1\lib\site-packages\telegram\utils\request.py", line 276, in _request_wrapper
    raise Conflict(message)
telegram.error.Conflict: Conflict: terminated by other getUpdates request; make sure that only one bot instance is running
2021-03-01 00:50:01,039 - ERROR - Error while getting Updates: Conflict: terminated by other getUpdates request; make sure that only one bot instance is running
2021-03-01 00:50:01,040 - ERROR - No error handlers are registered, logging exception.
Traceback (most recent call last):
  File "C:\Users\user\PycharmProjects\pythonProject\venv\lib\site-packages\telegram\ext\updater.py", line 465, in _network_loop_retry
    if not action_cb():
  File "C:\Users\user\PycharmProjects\pythonProject\venv\lib\site-packages\telegram\ext\updater.py", line 416, in polling_action_cb
    updates = self.bot.get_updates(
  File "<decorator-gen-31>", line 2, in get_updates
  File "C:\Users\user\PycharmProjects\pythonProject\venv\lib\site-packages\telegram\bot.py", line 135, in decorator
    result = func(*args, **kwargs)
  File "C:\Users\user\PycharmProjects\pythonProject\venv\lib\site-packages\telegram\bot.py", line 2638, in get_updates
    result = self._post(
  File "C:\Users\user\PycharmProjects\pythonProject\venv\lib\site-packages\telegram\bot.py", line 245, in _post
    return self.request.post(f'{self.base_url}/{endpoint}', data=data, timeout=timeout)
  File "C:\Users\user\PycharmProjects\pythonProject\venv\lib\site-packages\telegram\utils\request.py", line 349, in post
    result = self._request_wrapper(
  File "C:\Users\user\PycharmProjects\pythonProject\venv\lib\site-packages\telegram\utils\request.py", line 276, in _request_wrapper
    raise Conflict(message)
telegram.error.Conflict: Conflict: terminated by other getUpdates request; make sure that only one bot instance is running
2021-03-01 00:50:06,364 - ERROR - Error while getting Updates: Conflict: terminated by other getUpdates request; make sure that only one bot instance is running
2021-03-01 00:50:06,364 - ERROR - No error handlers are registered, logging exception.
Traceback (most recent call last):
  File "C:\Users\user\PycharmProjects\pythonProject1\lib\site-packages\telegram\ext\updater.py", line 465, in _network_loop_retry
    if not action_cb():
  File "C:\Users\user\PycharmProjects\pythonProject1\lib\site-packages\telegram\ext\updater.py", line 416, in polling_action_cb
    updates = self.bot.get_updates(
  File "C:\Users\user\PycharmProjects\pythonProject1\lib\site-packages\telegram\bot.py", line 126, in decorator
    result = func(*args, **kwargs)
  File "C:\Users\user\PycharmProjects\pythonProject1\lib\site-packages\telegram\bot.py", line 2748, in get_updates
    result = self._post(
  File "C:\Users\user\PycharmProjects\pythonProject1\lib\site-packages\telegram\bot.py", line 258, in _post
    return self.request.post(
  File "C:\Users\user\PycharmProjects\pythonProject1\lib\site-packages\telegram\utils\request.py", line 349, in post
    result = self._request_wrapper(
  File "C:\Users\user\PycharmProjects\pythonProject1\lib\site-packages\telegram\utils\request.py", line 276, in _request_wrapper
    raise Conflict(message)
telegram.error.Conflict: Conflict: terminated by other getUpdates request; make sure that only one bot instance is running
2021-03-01 00:50:08,314 - ERROR - No error handlers are registered, logging exception.
Traceback (most recent call last):
  File "C:\Users\user\PycharmProjects\pythonProject1\lib\site-packages\telegram\ext\dispatcher.py", line 442, in process_update
    handler.handle_update(update, self, check, context)
  File "C:\Users\user\PycharmProjects\pythonProject1\lib\site-packages\telegram\ext\conversationhandler.py", line 549, in handle_update
    new_state = handler.handle_update(update, dispatcher, check_result, context)
  File "C:\Users\user\PycharmProjects\pythonProject1\lib\site-packages\telegram\ext\handler.py", line 160, in handle_update
    return self.callback(update, context)
  File "C:\Users\user\PycharmProjects\InvestBot\Handlers\CallBackQueryHandlers\helpCallbackQueryHandler.py", line 15, in aboutCommands
    print(chatId)
OSError: [Errno 22] Invalid argument
2021-03-01 00:50:11,086 - ERROR - Error while getting Updates: Conflict: terminated by other getUpdates request; make sure that only one bot instance is running
2021-03-01 00:50:11,086 - ERROR - No error handlers are registered, logging exception.
Traceback (most recent call last):
  File "C:\Users\user\PycharmProjects\pythonProject\venv\lib\site-packages\telegram\ext\updater.py", line 465, in _network_loop_retry
    if not action_cb():
  File "C:\Users\user\PycharmProjects\pythonProject\venv\lib\site-packages\telegram\ext\updater.py", line 416, in polling_action_cb
    updates = self.bot.get_updates(
  File "<decorator-gen-31>", line 2, in get_updates
  File "C:\Users\user\PycharmProjects\pythonProject\venv\lib\site-packages\telegram\bot.py", line 135, in decorator
    result = func(*args, **kwargs)
  File "C:\Users\user\PycharmProjects\pythonProject\venv\lib\site-packages\telegram\bot.py", line 2638, in get_updates
    result = self._post(
  File "C:\Users\user\PycharmProjects\pythonProject\venv\lib\site-packages\telegram\bot.py", line 245, in _post
    return self.request.post(f'{self.base_url}/{endpoint}', data=data, timeout=timeout)
  File "C:\Users\user\PycharmProjects\pythonProject\venv\lib\site-packages\telegram\utils\request.py", line 349, in post
    result = self._request_wrapper(
  File "C:\Users\user\PycharmProjects\pythonProject\venv\lib\site-packages\telegram\utils\request.py", line 276, in _request_wrapper
    raise Conflict(message)
telegram.error.Conflict: Conflict: terminated by other getUpdates request; make sure that only one bot instance is running
2021-03-01 00:50:12,311 - ERROR - ERROR:  duplicate key value violates unique constraint "chat_id"
DETAIL:  Key (chat_id)=(350402934) already exists.
Traceback (most recent call last):
  File "C:\Users\user\PycharmProjects\InvestBot\DB\Queries\dbConnection.py", line 31, in query
    records = update_db(conn,sql)
  File "C:\Users\user\PycharmProjects\InvestBot\DB\Queries\dbConnection.py", line 21, in update_db
    cursor.execute(sql)
psycopg2.errors.UniqueViolation: duplicate key value violates unique constraint "chat_id"
DETAIL:  Key (chat_id)=(350402934) already exists.

2021-03-01 00:50:12,312 - ERROR - No error handlers are registered, logging exception.
Traceback (most recent call last):
  File "C:\Users\user\PycharmProjects\pythonProject1\lib\site-packages\telegram\ext\dispatcher.py", line 442, in process_update
    handler.handle_update(update, self, check, context)
  File "C:\Users\user\PycharmProjects\pythonProject1\lib\site-packages\telegram\ext\handler.py", line 160, in handle_update
    return self.callback(update, context)
  File "C:\Users\user\PycharmProjects\InvestBot\Handlers\CommandHandlers\BaseCommandHandler.py", line 37, in startCommand
    print(bot)
OSError: [Errno 22] Invalid argument
2021-03-01 00:50:12,414 - ERROR - ERROR:  duplicate key value violates unique constraint "chat_id"
DETAIL:  Key (chat_id)=(350402934) already exists.
Traceback (most recent call last):
  File "C:\Users\user\PycharmProjects\InvestBot\DB\Queries\dbConnection.py", line 31, in query
    records = update_db(conn,sql)
  File "C:\Users\user\PycharmProjects\InvestBot\DB\Queries\dbConnection.py", line 21, in update_db
    cursor.execute(sql)
psycopg2.errors.UniqueViolation: duplicate key value violates unique constraint "chat_id"
DETAIL:  Key (chat_id)=(350402934) already exists.

2021-03-01 00:50:12,507 - ERROR - Error while getting Updates: Conflict: terminated by other getUpdates request; make sure that only one bot instance is running
2021-03-01 00:50:12,507 - ERROR - No error handlers are registered, logging exception.
Traceback (most recent call last):
  File "C:\Users\user\PycharmProjects\pythonProject1\lib\site-packages\telegram\ext\updater.py", line 465, in _network_loop_retry
    if not action_cb():
  File "C:\Users\user\PycharmProjects\pythonProject1\lib\site-packages\telegram\ext\updater.py", line 416, in polling_action_cb
    updates = self.bot.get_updates(
  File "C:\Users\user\PycharmProjects\pythonProject1\lib\site-packages\telegram\bot.py", line 126, in decorator
    result = func(*args, **kwargs)
  File "C:\Users\user\PycharmProjects\pythonProject1\lib\site-packages\telegram\bot.py", line 2748, in get_updates
    result = self._post(
  File "C:\Users\user\PycharmProjects\pythonProject1\lib\site-packages\telegram\bot.py", line 258, in _post
    return self.request.post(
  File "C:\Users\user\PycharmProjects\pythonProject1\lib\site-packages\telegram\utils\request.py", line 349, in post
    result = self._request_wrapper(
  File "C:\Users\user\PycharmProjects\pythonProject1\lib\site-packages\telegram\utils\request.py", line 276, in _request_wrapper
    raise Conflict(message)
telegram.error.Conflict: Conflict: terminated by other getUpdates request; make sure that only one bot instance is running
2021-03-01 00:50:16,706 - ERROR - Error while getting Updates: Conflict: terminated by other getUpdates request; make sure that only one bot instance is running
2021-03-01 00:50:16,706 - ERROR - No error handlers are registered, logging exception.
Traceback (most recent call last):
  File "C:\Users\user\PycharmProjects\pythonProject\venv\lib\site-packages\telegram\ext\updater.py", line 465, in _network_loop_retry
    if not action_cb():
  File "C:\Users\user\PycharmProjects\pythonProject\venv\lib\site-packages\telegram\ext\updater.py", line 416, in polling_action_cb
    updates = self.bot.get_updates(
  File "<decorator-gen-31>", line 2, in get_updates
  File "C:\Users\user\PycharmProjects\pythonProject\venv\lib\site-packages\telegram\bot.py", line 135, in decorator
    result = func(*args, **kwargs)
  File "C:\Users\user\PycharmProjects\pythonProject\venv\lib\site-packages\telegram\bot.py", line 2638, in get_updates
    result = self._post(
  File "C:\Users\user\PycharmProjects\pythonProject\venv\lib\site-packages\telegram\bot.py", line 245, in _post
    return self.request.post(f'{self.base_url}/{endpoint}', data=data, timeout=timeout)
  File "C:\Users\user\PycharmProjects\pythonProject\venv\lib\site-packages\telegram\utils\request.py", line 349, in post
    result = self._request_wrapper(
  File "C:\Users\user\PycharmProjects\pythonProject\venv\lib\site-packages\telegram\utils\request.py", line 276, in _request_wrapper
    raise Conflict(message)
telegram.error.Conflict: Conflict: terminated by other getUpdates request; make sure that only one bot instance is running
2021-03-01 00:50:18,004 - ERROR - Error while getting Updates: Conflict: terminated by other getUpdates request; make sure that only one bot instance is running
2021-03-01 00:50:18,005 - ERROR - No error handlers are registered, logging exception.
Traceback (most recent call last):
  File "C:\Users\user\PycharmProjects\pythonProject1\lib\site-packages\telegram\ext\updater.py", line 465, in _network_loop_retry
    if not action_cb():
  File "C:\Users\user\PycharmProjects\pythonProject1\lib\site-packages\telegram\ext\updater.py", line 416, in polling_action_cb
    updates = self.bot.get_updates(
  File "C:\Users\user\PycharmProjects\pythonProject1\lib\site-packages\telegram\bot.py", line 126, in decorator
    result = func(*args, **kwargs)
  File "C:\Users\user\PycharmProjects\pythonProject1\lib\site-packages\telegram\bot.py", line 2748, in get_updates
    result = self._post(
  File "C:\Users\user\PycharmProjects\pythonProject1\lib\site-packages\telegram\bot.py", line 258, in _post
    return self.request.post(
  File "C:\Users\user\PycharmProjects\pythonProject1\lib\site-packages\telegram\utils\request.py", line 349, in post
    result = self._request_wrapper(
  File "C:\Users\user\PycharmProjects\pythonProject1\lib\site-packages\telegram\utils\request.py", line 276, in _request_wrapper
    raise Conflict(message)
telegram.error.Conflict: Conflict: terminated by other getUpdates request; make sure that only one bot instance is running
2021-03-01 00:50:22,245 - ERROR - Error while getting Updates: Conflict: terminated by other getUpdates request; make sure that only one bot instance is running
2021-03-01 00:50:22,246 - ERROR - No error handlers are registered, logging exception.
Traceback (most recent call last):
  File "C:\Users\user\PycharmProjects\pythonProject\venv\lib\site-packages\telegram\ext\updater.py", line 465, in _network_loop_retry
    if not action_cb():
  File "C:\Users\user\PycharmProjects\pythonProject\venv\lib\site-packages\telegram\ext\updater.py", line 416, in polling_action_cb
    updates = self.bot.get_updates(
  File "<decorator-gen-31>", line 2, in get_updates
  File "C:\Users\user\PycharmProjects\pythonProject\venv\lib\site-packages\telegram\bot.py", line 135, in decorator
    result = func(*args, **kwargs)
  File "C:\Users\user\PycharmProjects\pythonProject\venv\lib\site-packages\telegram\bot.py", line 2638, in get_updates
    result = self._post(
  File "C:\Users\user\PycharmProjects\pythonProject\venv\lib\site-packages\telegram\bot.py", line 245, in _post
    return self.request.post(f'{self.base_url}/{endpoint}', data=data, timeout=timeout)
  File "C:\Users\user\PycharmProjects\pythonProject\venv\lib\site-packages\telegram\utils\request.py", line 349, in post
    result = self._request_wrapper(
  File "C:\Users\user\PycharmProjects\pythonProject\venv\lib\site-packages\telegram\utils\request.py", line 276, in _request_wrapper
    raise Conflict(message)
telegram.error.Conflict: Conflict: terminated by other getUpdates request; make sure that only one bot instance is running
2021-03-01 00:50:24,181 - ERROR - Error while getting Updates: Conflict: terminated by other getUpdates request; make sure that only one bot instance is running
2021-03-01 00:50:24,182 - ERROR - No error handlers are registered, logging exception.
Traceback (most recent call last):
  File "C:\Users\user\PycharmProjects\pythonProject1\lib\site-packages\telegram\ext\updater.py", line 465, in _network_loop_retry
    if not action_cb():
  File "C:\Users\user\PycharmProjects\pythonProject1\lib\site-packages\telegram\ext\updater.py", line 416, in polling_action_cb
    updates = self.bot.get_updates(
  File "C:\Users\user\PycharmProjects\pythonProject1\lib\site-packages\telegram\bot.py", line 126, in decorator
    result = func(*args, **kwargs)
  File "C:\Users\user\PycharmProjects\pythonProject1\lib\site-packages\telegram\bot.py", line 2748, in get_updates
    result = self._post(
  File "C:\Users\user\PycharmProjects\pythonProject1\lib\site-packages\telegram\bot.py", line 258, in _post
    return self.request.post(
  File "C:\Users\user\PycharmProjects\pythonProject1\lib\site-packages\telegram\utils\request.py", line 349, in post
    result = self._request_wrapper(
  File "C:\Users\user\PycharmProjects\pythonProject1\lib\site-packages\telegram\utils\request.py", line 276, in _request_wrapper
    raise Conflict(message)
telegram.error.Conflict: Conflict: terminated by other getUpdates request; make sure that only one bot instance is running
2021-03-01 00:50:28,484 - ERROR - Error while getting Updates: Conflict: terminated by other getUpdates request; make sure that only one bot instance is running
2021-03-01 00:50:28,484 - ERROR - No error handlers are registered, logging exception.
Traceback (most recent call last):
  File "C:\Users\user\PycharmProjects\pythonProject\venv\lib\site-packages\telegram\ext\updater.py", line 465, in _network_loop_retry
    if not action_cb():
  File "C:\Users\user\PycharmProjects\pythonProject\venv\lib\site-packages\telegram\ext\updater.py", line 416, in polling_action_cb
    updates = self.bot.get_updates(
  File "<decorator-gen-31>", line 2, in get_updates
  File "C:\Users\user\PycharmProjects\pythonProject\venv\lib\site-packages\telegram\bot.py", line 135, in decorator
    result = func(*args, **kwargs)
  File "C:\Users\user\PycharmProjects\pythonProject\venv\lib\site-packages\telegram\bot.py", line 2638, in get_updates
    result = self._post(
  File "C:\Users\user\PycharmProjects\pythonProject\venv\lib\site-packages\telegram\bot.py", line 245, in _post
    return self.request.post(f'{self.base_url}/{endpoint}', data=data, timeout=timeout)
  File "C:\Users\user\PycharmProjects\pythonProject\venv\lib\site-packages\telegram\utils\request.py", line 349, in post
    result = self._request_wrapper(
  File "C:\Users\user\PycharmProjects\pythonProject\venv\lib\site-packages\telegram\utils\request.py", line 276, in _request_wrapper
    raise Conflict(message)
telegram.error.Conflict: Conflict: terminated by other getUpdates request; make sure that only one bot instance is running
2021-03-01 00:50:30,941 - ERROR - Error while getting Updates: Conflict: terminated by other getUpdates request; make sure that only one bot instance is running
2021-03-01 00:50:30,942 - ERROR - No error handlers are registered, logging exception.
Traceback (most recent call last):
  File "C:\Users\user\PycharmProjects\pythonProject1\lib\site-packages\telegram\ext\updater.py", line 465, in _network_loop_retry
    if not action_cb():
  File "C:\Users\user\PycharmProjects\pythonProject1\lib\site-packages\telegram\ext\updater.py", line 416, in polling_action_cb
    updates = self.bot.get_updates(
  File "C:\Users\user\PycharmProjects\pythonProject1\lib\site-packages\telegram\bot.py", line 126, in decorator
    result = func(*args, **kwargs)
  File "C:\Users\user\PycharmProjects\pythonProject1\lib\site-packages\telegram\bot.py", line 2748, in get_updates
    result = self._post(
  File "C:\Users\user\PycharmProjects\pythonProject1\lib\site-packages\telegram\bot.py", line 258, in _post
    return self.request.post(
  File "C:\Users\user\PycharmProjects\pythonProject1\lib\site-packages\telegram\utils\request.py", line 349, in post
    result = self._request_wrapper(
  File "C:\Users\user\PycharmProjects\pythonProject1\lib\site-packages\telegram\utils\request.py", line 276, in _request_wrapper
    raise Conflict(message)
telegram.error.Conflict: Conflict: terminated by other getUpdates request; make sure that only one bot instance is running
2021-03-01 00:50:35,761 - ERROR - Error while getting Updates: Conflict: terminated by other getUpdates request; make sure that only one bot instance is running
2021-03-01 00:50:35,762 - ERROR - No error handlers are registered, logging exception.
Traceback (most recent call last):
  File "C:\Users\user\PycharmProjects\pythonProject\venv\lib\site-packages\telegram\ext\updater.py", line 465, in _network_loop_retry
    if not action_cb():
  File "C:\Users\user\PycharmProjects\pythonProject\venv\lib\site-packages\telegram\ext\updater.py", line 416, in polling_action_cb
    updates = self.bot.get_updates(
  File "<decorator-gen-31>", line 2, in get_updates
  File "C:\Users\user\PycharmProjects\pythonProject\venv\lib\site-packages\telegram\bot.py", line 135, in decorator
    result = func(*args, **kwargs)
  File "C:\Users\user\PycharmProjects\pythonProject\venv\lib\site-packages\telegram\bot.py", line 2638, in get_updates
    result = self._post(
  File "C:\Users\user\PycharmProjects\pythonProject\venv\lib\site-packages\telegram\bot.py", line 245, in _post
    return self.request.post(f'{self.base_url}/{endpoint}', data=data, timeout=timeout)
  File "C:\Users\user\PycharmProjects\pythonProject\venv\lib\site-packages\telegram\utils\request.py", line 349, in post
    result = self._request_wrapper(
  File "C:\Users\user\PycharmProjects\pythonProject\venv\lib\site-packages\telegram\utils\request.py", line 276, in _request_wrapper
    raise Conflict(message)
telegram.error.Conflict: Conflict: terminated by other getUpdates request; make sure that only one bot instance is running
2021-03-01 00:50:39,445 - ERROR - Error while getting Updates: Conflict: terminated by other getUpdates request; make sure that only one bot instance is running
2021-03-01 00:50:39,445 - ERROR - No error handlers are registered, logging exception.
Traceback (most recent call last):
  File "C:\Users\user\PycharmProjects\pythonProject1\lib\site-packages\telegram\ext\updater.py", line 465, in _network_loop_retry
    if not action_cb():
  File "C:\Users\user\PycharmProjects\pythonProject1\lib\site-packages\telegram\ext\updater.py", line 416, in polling_action_cb
    updates = self.bot.get_updates(
  File "C:\Users\user\PycharmProjects\pythonProject1\lib\site-packages\telegram\bot.py", line 126, in decorator
    result = func(*args, **kwargs)
  File "C:\Users\user\PycharmProjects\pythonProject1\lib\site-packages\telegram\bot.py", line 2748, in get_updates
    result = self._post(
  File "C:\Users\user\PycharmProjects\pythonProject1\lib\site-packages\telegram\bot.py", line 258, in _post
    return self.request.post(
  File "C:\Users\user\PycharmProjects\pythonProject1\lib\site-packages\telegram\utils\request.py", line 349, in post
    result = self._request_wrapper(
  File "C:\Users\user\PycharmProjects\pythonProject1\lib\site-packages\telegram\utils\request.py", line 276, in _request_wrapper
    raise Conflict(message)
telegram.error.Conflict: Conflict: terminated by other getUpdates request; make sure that only one bot instance is running
2021-03-01 00:50:45,076 - ERROR - Error while getting Updates: Conflict: terminated by other getUpdates request; make sure that only one bot instance is running
2021-03-01 00:50:45,077 - ERROR - No error handlers are registered, logging exception.
Traceback (most recent call last):
  File "C:\Users\user\PycharmProjects\pythonProject\venv\lib\site-packages\telegram\ext\updater.py", line 465, in _network_loop_retry
    if not action_cb():
  File "C:\Users\user\PycharmProjects\pythonProject\venv\lib\site-packages\telegram\ext\updater.py", line 416, in polling_action_cb
    updates = self.bot.get_updates(
  File "<decorator-gen-31>", line 2, in get_updates
  File "C:\Users\user\PycharmProjects\pythonProject\venv\lib\site-packages\telegram\bot.py", line 135, in decorator
    result = func(*args, **kwargs)
  File "C:\Users\user\PycharmProjects\pythonProject\venv\lib\site-packages\telegram\bot.py", line 2638, in get_updates
    result = self._post(
  File "C:\Users\user\PycharmProjects\pythonProject\venv\lib\site-packages\telegram\bot.py", line 245, in _post
    return self.request.post(f'{self.base_url}/{endpoint}', data=data, timeout=timeout)
  File "C:\Users\user\PycharmProjects\pythonProject\venv\lib\site-packages\telegram\utils\request.py", line 349, in post
    result = self._request_wrapper(
  File "C:\Users\user\PycharmProjects\pythonProject\venv\lib\site-packages\telegram\utils\request.py", line 276, in _request_wrapper
    raise Conflict(message)
telegram.error.Conflict: Conflict: terminated by other getUpdates request; make sure that only one bot instance is running
2021-03-01 00:50:50,406 - ERROR - Error while getting Updates: Conflict: terminated by other getUpdates request; make sure that only one bot instance is running
2021-03-01 00:50:50,407 - ERROR - No error handlers are registered, logging exception.
Traceback (most recent call last):
  File "C:\Users\user\PycharmProjects\pythonProject1\lib\site-packages\telegram\ext\updater.py", line 465, in _network_loop_retry
    if not action_cb():
  File "C:\Users\user\PycharmProjects\pythonProject1\lib\site-packages\telegram\ext\updater.py", line 416, in polling_action_cb
    updates = self.bot.get_updates(
  File "C:\Users\user\PycharmProjects\pythonProject1\lib\site-packages\telegram\bot.py", line 126, in decorator
    result = func(*args, **kwargs)
  File "C:\Users\user\PycharmProjects\pythonProject1\lib\site-packages\telegram\bot.py", line 2748, in get_updates
    result = self._post(
  File "C:\Users\user\PycharmProjects\pythonProject1\lib\site-packages\telegram\bot.py", line 258, in _post
    return self.request.post(
  File "C:\Users\user\PycharmProjects\pythonProject1\lib\site-packages\telegram\utils\request.py", line 349, in post
    result = self._request_wrapper(
  File "C:\Users\user\PycharmProjects\pythonProject1\lib\site-packages\telegram\utils\request.py", line 276, in _request_wrapper
    raise Conflict(message)
telegram.error.Conflict: Conflict: terminated by other getUpdates request; make sure that only one bot instance is running
2021-03-01 00:50:54,027 - ERROR - Error while getting Updates: Conflict: terminated by other getUpdates request; make sure that only one bot instance is running
2021-03-01 00:50:54,027 - ERROR - No error handlers are registered, logging exception.
Traceback (most recent call last):
  File "C:\Users\user\PycharmProjects\pythonProject\venv\lib\site-packages\telegram\ext\updater.py", line 465, in _network_loop_retry
    if not action_cb():
  File "C:\Users\user\PycharmProjects\pythonProject\venv\lib\site-packages\telegram\ext\updater.py", line 416, in polling_action_cb
    updates = self.bot.get_updates(
  File "<decorator-gen-31>", line 2, in get_updates
  File "C:\Users\user\PycharmProjects\pythonProject\venv\lib\site-packages\telegram\bot.py", line 135, in decorator
    result = func(*args, **kwargs)
  File "C:\Users\user\PycharmProjects\pythonProject\venv\lib\site-packages\telegram\bot.py", line 2638, in get_updates
    result = self._post(
  File "C:\Users\user\PycharmProjects\pythonProject\venv\lib\site-packages\telegram\bot.py", line 245, in _post
    return self.request.post(f'{self.base_url}/{endpoint}', data=data, timeout=timeout)
  File "C:\Users\user\PycharmProjects\pythonProject\venv\lib\site-packages\telegram\utils\request.py", line 349, in post
    result = self._request_wrapper(
  File "C:\Users\user\PycharmProjects\pythonProject\venv\lib\site-packages\telegram\utils\request.py", line 276, in _request_wrapper
    raise Conflict(message)
telegram.error.Conflict: Conflict: terminated by other getUpdates request; make sure that only one bot instance is running
2021-03-01 00:51:01,871 - ERROR - Error while getting Updates: Conflict: terminated by other getUpdates request; make sure that only one bot instance is running
2021-03-01 00:51:01,871 - ERROR - No error handlers are registered, logging exception.
Traceback (most recent call last):
  File "C:\Users\user\PycharmProjects\pythonProject1\lib\site-packages\telegram\ext\updater.py", line 465, in _network_loop_retry
    if not action_cb():
  File "C:\Users\user\PycharmProjects\pythonProject1\lib\site-packages\telegram\ext\updater.py", line 416, in polling_action_cb
    updates = self.bot.get_updates(
  File "C:\Users\user\PycharmProjects\pythonProject1\lib\site-packages\telegram\bot.py", line 126, in decorator
    result = func(*args, **kwargs)
  File "C:\Users\user\PycharmProjects\pythonProject1\lib\site-packages\telegram\bot.py", line 2748, in get_updates
    result = self._post(
  File "C:\Users\user\PycharmProjects\pythonProject1\lib\site-packages\telegram\bot.py", line 258, in _post
    return self.request.post(
  File "C:\Users\user\PycharmProjects\pythonProject1\lib\site-packages\telegram\utils\request.py", line 349, in post
    result = self._request_wrapper(
  File "C:\Users\user\PycharmProjects\pythonProject1\lib\site-packages\telegram\utils\request.py", line 276, in _request_wrapper
    raise Conflict(message)
telegram.error.Conflict: Conflict: terminated by other getUpdates request; make sure that only one bot instance is running
2021-03-01 00:51:07,198 - ERROR - Error while getting Updates: Conflict: terminated by other getUpdates request; make sure that only one bot instance is running
2021-03-01 00:51:07,199 - ERROR - No error handlers are registered, logging exception.
Traceback (most recent call last):
  File "C:\Users\user\PycharmProjects\pythonProject\venv\lib\site-packages\telegram\ext\updater.py", line 465, in _network_loop_retry
    if not action_cb():
  File "C:\Users\user\PycharmProjects\pythonProject\venv\lib\site-packages\telegram\ext\updater.py", line 416, in polling_action_cb
    updates = self.bot.get_updates(
  File "<decorator-gen-31>", line 2, in get_updates
  File "C:\Users\user\PycharmProjects\pythonProject\venv\lib\site-packages\telegram\bot.py", line 135, in decorator
    result = func(*args, **kwargs)
  File "C:\Users\user\PycharmProjects\pythonProject\venv\lib\site-packages\telegram\bot.py", line 2638, in get_updates
    result = self._post(
  File "C:\Users\user\PycharmProjects\pythonProject\venv\lib\site-packages\telegram\bot.py", line 245, in _post
    return self.request.post(f'{self.base_url}/{endpoint}', data=data, timeout=timeout)
  File "C:\Users\user\PycharmProjects\pythonProject\venv\lib\site-packages\telegram\utils\request.py", line 349, in post
    result = self._request_wrapper(
  File "C:\Users\user\PycharmProjects\pythonProject\venv\lib\site-packages\telegram\utils\request.py", line 276, in _request_wrapper
    raise Conflict(message)
telegram.error.Conflict: Conflict: terminated by other getUpdates request; make sure that only one bot instance is running
2021-03-01 00:51:18,866 - ERROR - Error while getting Updates: Conflict: terminated by other getUpdates request; make sure that only one bot instance is running
2021-03-01 00:51:18,866 - ERROR - No error handlers are registered, logging exception.
Traceback (most recent call last):
  File "C:\Users\user\PycharmProjects\pythonProject1\lib\site-packages\telegram\ext\updater.py", line 465, in _network_loop_retry
    if not action_cb():
  File "C:\Users\user\PycharmProjects\pythonProject1\lib\site-packages\telegram\ext\updater.py", line 416, in polling_action_cb
    updates = self.bot.get_updates(
  File "C:\Users\user\PycharmProjects\pythonProject1\lib\site-packages\telegram\bot.py", line 126, in decorator
    result = func(*args, **kwargs)
  File "C:\Users\user\PycharmProjects\pythonProject1\lib\site-packages\telegram\bot.py", line 2748, in get_updates
    result = self._post(
  File "C:\Users\user\PycharmProjects\pythonProject1\lib\site-packages\telegram\bot.py", line 258, in _post
    return self.request.post(
  File "C:\Users\user\PycharmProjects\pythonProject1\lib\site-packages\telegram\utils\request.py", line 349, in post
    result = self._request_wrapper(
  File "C:\Users\user\PycharmProjects\pythonProject1\lib\site-packages\telegram\utils\request.py", line 276, in _request_wrapper
    raise Conflict(message)
telegram.error.Conflict: Conflict: terminated by other getUpdates request; make sure that only one bot instance is running
2021-03-01 00:51:23,170 - ERROR - Error while getting Updates: Conflict: terminated by other getUpdates request; make sure that only one bot instance is running
2021-03-01 00:51:23,171 - ERROR - No error handlers are registered, logging exception.
Traceback (most recent call last):
  File "C:\Users\user\PycharmProjects\pythonProject\venv\lib\site-packages\telegram\ext\updater.py", line 465, in _network_loop_retry
    if not action_cb():
  File "C:\Users\user\PycharmProjects\pythonProject\venv\lib\site-packages\telegram\ext\updater.py", line 416, in polling_action_cb
    updates = self.bot.get_updates(
  File "<decorator-gen-31>", line 2, in get_updates
  File "C:\Users\user\PycharmProjects\pythonProject\venv\lib\site-packages\telegram\bot.py", line 135, in decorator
    result = func(*args, **kwargs)
  File "C:\Users\user\PycharmProjects\pythonProject\venv\lib\site-packages\telegram\bot.py", line 2638, in get_updates
    result = self._post(
  File "C:\Users\user\PycharmProjects\pythonProject\venv\lib\site-packages\telegram\bot.py", line 245, in _post
    return self.request.post(f'{self.base_url}/{endpoint}', data=data, timeout=timeout)
  File "C:\Users\user\PycharmProjects\pythonProject\venv\lib\site-packages\telegram\utils\request.py", line 349, in post
    result = self._request_wrapper(
  File "C:\Users\user\PycharmProjects\pythonProject\venv\lib\site-packages\telegram\utils\request.py", line 276, in _request_wrapper
    raise Conflict(message)
telegram.error.Conflict: Conflict: terminated by other getUpdates request; make sure that only one bot instance is running
2021-03-01 00:51:40,588 - ERROR - Error while getting Updates: Conflict: terminated by other getUpdates request; make sure that only one bot instance is running
2021-03-01 00:51:40,588 - ERROR - No error handlers are registered, logging exception.
Traceback (most recent call last):
  File "C:\Users\user\PycharmProjects\pythonProject\venv\lib\site-packages\telegram\ext\updater.py", line 465, in _network_loop_retry
    if not action_cb():
  File "C:\Users\user\PycharmProjects\pythonProject\venv\lib\site-packages\telegram\ext\updater.py", line 416, in polling_action_cb
    updates = self.bot.get_updates(
  File "<decorator-gen-31>", line 2, in get_updates
  File "C:\Users\user\PycharmProjects\pythonProject\venv\lib\site-packages\telegram\bot.py", line 135, in decorator
    result = func(*args, **kwargs)
  File "C:\Users\user\PycharmProjects\pythonProject\venv\lib\site-packages\telegram\bot.py", line 2638, in get_updates
    result = self._post(
  File "C:\Users\user\PycharmProjects\pythonProject\venv\lib\site-packages\telegram\bot.py", line 245, in _post
    return self.request.post(f'{self.base_url}/{endpoint}', data=data, timeout=timeout)
  File "C:\Users\user\PycharmProjects\pythonProject\venv\lib\site-packages\telegram\utils\request.py", line 349, in post
    result = self._request_wrapper(
  File "C:\Users\user\PycharmProjects\pythonProject\venv\lib\site-packages\telegram\utils\request.py", line 276, in _request_wrapper
    raise Conflict(message)
telegram.error.Conflict: Conflict: terminated by other getUpdates request; make sure that only one bot instance is running
2021-03-01 00:52:06,496 - ERROR - Error while getting Updates: Conflict: terminated by other getUpdates request; make sure that only one bot instance is running
2021-03-01 00:52:06,497 - ERROR - No error handlers are registered, logging exception.
Traceback (most recent call last):
  File "C:\Users\user\PycharmProjects\pythonProject1\lib\site-packages\telegram\ext\updater.py", line 465, in _network_loop_retry
    if not action_cb():
  File "C:\Users\user\PycharmProjects\pythonProject1\lib\site-packages\telegram\ext\updater.py", line 416, in polling_action_cb
    updates = self.bot.get_updates(
  File "C:\Users\user\PycharmProjects\pythonProject1\lib\site-packages\telegram\bot.py", line 126, in decorator
    result = func(*args, **kwargs)
  File "C:\Users\user\PycharmProjects\pythonProject1\lib\site-packages\telegram\bot.py", line 2748, in get_updates
    result = self._post(
  File "C:\Users\user\PycharmProjects\pythonProject1\lib\site-packages\telegram\bot.py", line 258, in _post
    return self.request.post(
  File "C:\Users\user\PycharmProjects\pythonProject1\lib\site-packages\telegram\utils\request.py", line 349, in post
    result = self._request_wrapper(
  File "C:\Users\user\PycharmProjects\pythonProject1\lib\site-packages\telegram\utils\request.py", line 276, in _request_wrapper
    raise Conflict(message)
telegram.error.Conflict: Conflict: terminated by other getUpdates request; make sure that only one bot instance is running
2021-03-01 00:52:10,787 - ERROR - Error while getting Updates: Conflict: terminated by other getUpdates request; make sure that only one bot instance is running
2021-03-01 00:52:10,787 - ERROR - No error handlers are registered, logging exception.
Traceback (most recent call last):
  File "C:\Users\user\PycharmProjects\pythonProject\venv\lib\site-packages\telegram\ext\updater.py", line 465, in _network_loop_retry
    if not action_cb():
  File "C:\Users\user\PycharmProjects\pythonProject\venv\lib\site-packages\telegram\ext\updater.py", line 416, in polling_action_cb
    updates = self.bot.get_updates(
  File "<decorator-gen-31>", line 2, in get_updates
  File "C:\Users\user\PycharmProjects\pythonProject\venv\lib\site-packages\telegram\bot.py", line 135, in decorator
    result = func(*args, **kwargs)
  File "C:\Users\user\PycharmProjects\pythonProject\venv\lib\site-packages\telegram\bot.py", line 2638, in get_updates
    result = self._post(
  File "C:\Users\user\PycharmProjects\pythonProject\venv\lib\site-packages\telegram\bot.py", line 245, in _post
    return self.request.post(f'{self.base_url}/{endpoint}', data=data, timeout=timeout)
  File "C:\Users\user\PycharmProjects\pythonProject\venv\lib\site-packages\telegram\utils\request.py", line 349, in post
    result = self._request_wrapper(
  File "C:\Users\user\PycharmProjects\pythonProject\venv\lib\site-packages\telegram\utils\request.py", line 276, in _request_wrapper
    raise Conflict(message)
telegram.error.Conflict: Conflict: terminated by other getUpdates request; make sure that only one bot instance is running
2021-03-01 00:52:36,329 - INFO - Scheduler started
2021-03-01 00:52:37,540 - ERROR - Error while getting Updates: Conflict: terminated by other getUpdates request; make sure that only one bot instance is running
2021-03-01 00:52:37,540 - ERROR - No error handlers are registered, logging exception.
Traceback (most recent call last):
  File "C:\Users\user\PycharmProjects\pythonProject1\lib\site-packages\telegram\ext\updater.py", line 465, in _network_loop_retry
    if not action_cb():
  File "C:\Users\user\PycharmProjects\pythonProject1\lib\site-packages\telegram\ext\updater.py", line 416, in polling_action_cb
    updates = self.bot.get_updates(
  File "C:\Users\user\PycharmProjects\pythonProject1\lib\site-packages\telegram\bot.py", line 126, in decorator
    result = func(*args, **kwargs)
  File "C:\Users\user\PycharmProjects\pythonProject1\lib\site-packages\telegram\bot.py", line 2748, in get_updates
    result = self._post(
  File "C:\Users\user\PycharmProjects\pythonProject1\lib\site-packages\telegram\bot.py", line 258, in _post
    return self.request.post(
  File "C:\Users\user\PycharmProjects\pythonProject1\lib\site-packages\telegram\utils\request.py", line 349, in post
    result = self._request_wrapper(
  File "C:\Users\user\PycharmProjects\pythonProject1\lib\site-packages\telegram\utils\request.py", line 276, in _request_wrapper
    raise Conflict(message)
telegram.error.Conflict: Conflict: terminated by other getUpdates request; make sure that only one bot instance is running
2021-03-01 00:52:41,204 - ERROR - ERROR:  duplicate key value violates unique constraint "chat_id"
DETAIL:  Key (chat_id)=(350402934) already exists.
Traceback (most recent call last):
  File "C:\Users\user\PycharmProjects\InvestBot\DB\Queries\dbConnection.py", line 31, in query
    records = update_db(conn,sql)
  File "C:\Users\user\PycharmProjects\InvestBot\DB\Queries\dbConnection.py", line 21, in update_db
    cursor.execute(sql)
psycopg2.errors.UniqueViolation: duplicate key value violates unique constraint "chat_id"
DETAIL:  Key (chat_id)=(350402934) already exists.

2021-03-01 00:52:41,206 - ERROR - No error handlers are registered, logging exception.
Traceback (most recent call last):
  File "C:\Users\user\PycharmProjects\pythonProject1\lib\site-packages\telegram\ext\dispatcher.py", line 442, in process_update
    handler.handle_update(update, self, check, context)
  File "C:\Users\user\PycharmProjects\pythonProject1\lib\site-packages\telegram\ext\handler.py", line 160, in handle_update
    return self.callback(update, context)
  File "C:\Users\user\PycharmProjects\InvestBot\Handlers\CommandHandlers\BaseCommandHandler.py", line 37, in startCommand
    print(bot)
OSError: [Errno 22] Invalid argument
2021-03-01 00:52:41,823 - ERROR - Error while getting Updates: Conflict: terminated by other getUpdates request; make sure that only one bot instance is running
2021-03-01 00:52:41,823 - ERROR - No error handlers are registered, logging exception.
Traceback (most recent call last):
  File "C:\Users\user\PycharmProjects\pythonProject\venv\lib\site-packages\telegram\ext\updater.py", line 465, in _network_loop_retry
    if not action_cb():
  File "C:\Users\user\PycharmProjects\pythonProject\venv\lib\site-packages\telegram\ext\updater.py", line 416, in polling_action_cb
    updates = self.bot.get_updates(
  File "<decorator-gen-31>", line 2, in get_updates
  File "C:\Users\user\PycharmProjects\pythonProject\venv\lib\site-packages\telegram\bot.py", line 135, in decorator
    result = func(*args, **kwargs)
  File "C:\Users\user\PycharmProjects\pythonProject\venv\lib\site-packages\telegram\bot.py", line 2638, in get_updates
    result = self._post(
  File "C:\Users\user\PycharmProjects\pythonProject\venv\lib\site-packages\telegram\bot.py", line 245, in _post
    return self.request.post(f'{self.base_url}/{endpoint}', data=data, timeout=timeout)
  File "C:\Users\user\PycharmProjects\pythonProject\venv\lib\site-packages\telegram\utils\request.py", line 349, in post
    result = self._request_wrapper(
  File "C:\Users\user\PycharmProjects\pythonProject\venv\lib\site-packages\telegram\utils\request.py", line 276, in _request_wrapper
    raise Conflict(message)
telegram.error.Conflict: Conflict: terminated by other getUpdates request; make sure that only one bot instance is running
2021-03-01 00:52:43,146 - ERROR - Error while getting Updates: Conflict: terminated by other getUpdates request; make sure that only one bot instance is running
2021-03-01 00:52:43,146 - ERROR - No error handlers are registered, logging exception.
Traceback (most recent call last):
  File "C:\Users\user\PycharmProjects\pythonProject1\lib\site-packages\telegram\ext\updater.py", line 465, in _network_loop_retry
    if not action_cb():
  File "C:\Users\user\PycharmProjects\pythonProject1\lib\site-packages\telegram\ext\updater.py", line 416, in polling_action_cb
    updates = self.bot.get_updates(
  File "C:\Users\user\PycharmProjects\pythonProject1\lib\site-packages\telegram\bot.py", line 126, in decorator
    result = func(*args, **kwargs)
  File "C:\Users\user\PycharmProjects\pythonProject1\lib\site-packages\telegram\bot.py", line 2748, in get_updates
    result = self._post(
  File "C:\Users\user\PycharmProjects\pythonProject1\lib\site-packages\telegram\bot.py", line 258, in _post
    return self.request.post(
  File "C:\Users\user\PycharmProjects\pythonProject1\lib\site-packages\telegram\utils\request.py", line 349, in post
    result = self._request_wrapper(
  File "C:\Users\user\PycharmProjects\pythonProject1\lib\site-packages\telegram\utils\request.py", line 276, in _request_wrapper
    raise Conflict(message)
telegram.error.Conflict: Conflict: terminated by other getUpdates request; make sure that only one bot instance is running
2021-03-01 00:52:47,448 - ERROR - Error while getting Updates: Conflict: terminated by other getUpdates request; make sure that only one bot instance is running
2021-03-01 00:52:47,449 - ERROR - No error handlers are registered, logging exception.
Traceback (most recent call last):
  File "C:\Users\user\PycharmProjects\pythonProject\venv\lib\site-packages\telegram\ext\updater.py", line 465, in _network_loop_retry
    if not action_cb():
  File "C:\Users\user\PycharmProjects\pythonProject\venv\lib\site-packages\telegram\ext\updater.py", line 416, in polling_action_cb
    updates = self.bot.get_updates(
  File "<decorator-gen-31>", line 2, in get_updates
  File "C:\Users\user\PycharmProjects\pythonProject\venv\lib\site-packages\telegram\bot.py", line 135, in decorator
    result = func(*args, **kwargs)
  File "C:\Users\user\PycharmProjects\pythonProject\venv\lib\site-packages\telegram\bot.py", line 2638, in get_updates
    result = self._post(
  File "C:\Users\user\PycharmProjects\pythonProject\venv\lib\site-packages\telegram\bot.py", line 245, in _post
    return self.request.post(f'{self.base_url}/{endpoint}', data=data, timeout=timeout)
  File "C:\Users\user\PycharmProjects\pythonProject\venv\lib\site-packages\telegram\utils\request.py", line 349, in post
    result = self._request_wrapper(
  File "C:\Users\user\PycharmProjects\pythonProject\venv\lib\site-packages\telegram\utils\request.py", line 276, in _request_wrapper
    raise Conflict(message)
telegram.error.Conflict: Conflict: terminated by other getUpdates request; make sure that only one bot instance is running
2021-03-01 00:52:49,189 - ERROR - Error while getting Updates: Conflict: terminated by other getUpdates request; make sure that only one bot instance is running
2021-03-01 00:52:49,189 - ERROR - No error handlers are registered, logging exception.
Traceback (most recent call last):
  File "C:\Users\user\PycharmProjects\pythonProject1\lib\site-packages\telegram\ext\updater.py", line 465, in _network_loop_retry
    if not action_cb():
  File "C:\Users\user\PycharmProjects\pythonProject1\lib\site-packages\telegram\ext\updater.py", line 416, in polling_action_cb
    updates = self.bot.get_updates(
  File "C:\Users\user\PycharmProjects\pythonProject1\lib\site-packages\telegram\bot.py", line 126, in decorator
    result = func(*args, **kwargs)
  File "C:\Users\user\PycharmProjects\pythonProject1\lib\site-packages\telegram\bot.py", line 2748, in get_updates
    result = self._post(
  File "C:\Users\user\PycharmProjects\pythonProject1\lib\site-packages\telegram\bot.py", line 258, in _post
    return self.request.post(
  File "C:\Users\user\PycharmProjects\pythonProject1\lib\site-packages\telegram\utils\request.py", line 349, in post
    result = self._request_wrapper(
  File "C:\Users\user\PycharmProjects\pythonProject1\lib\site-packages\telegram\utils\request.py", line 276, in _request_wrapper
    raise Conflict(message)
telegram.error.Conflict: Conflict: terminated by other getUpdates request; make sure that only one bot instance is running
2021-03-01 00:52:53,910 - ERROR - Error while getting Updates: Conflict: terminated by other getUpdates request; make sure that only one bot instance is running
2021-03-01 00:52:53,910 - ERROR - No error handlers are registered, logging exception.
Traceback (most recent call last):
  File "C:\Users\user\PycharmProjects\pythonProject\venv\lib\site-packages\telegram\ext\updater.py", line 465, in _network_loop_retry
    if not action_cb():
  File "C:\Users\user\PycharmProjects\pythonProject\venv\lib\site-packages\telegram\ext\updater.py", line 416, in polling_action_cb
    updates = self.bot.get_updates(
  File "<decorator-gen-31>", line 2, in get_updates
  File "C:\Users\user\PycharmProjects\pythonProject\venv\lib\site-packages\telegram\bot.py", line 135, in decorator
    result = func(*args, **kwargs)
  File "C:\Users\user\PycharmProjects\pythonProject\venv\lib\site-packages\telegram\bot.py", line 2638, in get_updates
    result = self._post(
  File "C:\Users\user\PycharmProjects\pythonProject\venv\lib\site-packages\telegram\bot.py", line 245, in _post
    return self.request.post(f'{self.base_url}/{endpoint}', data=data, timeout=timeout)
  File "C:\Users\user\PycharmProjects\pythonProject\venv\lib\site-packages\telegram\utils\request.py", line 349, in post
    result = self._request_wrapper(
  File "C:\Users\user\PycharmProjects\pythonProject\venv\lib\site-packages\telegram\utils\request.py", line 276, in _request_wrapper
    raise Conflict(message)
telegram.error.Conflict: Conflict: terminated by other getUpdates request; make sure that only one bot instance is running
2021-03-01 00:52:56,459 - ERROR - Error while getting Updates: Conflict: terminated by other getUpdates request; make sure that only one bot instance is running
2021-03-01 00:52:56,460 - ERROR - No error handlers are registered, logging exception.
Traceback (most recent call last):
  File "C:\Users\user\PycharmProjects\pythonProject1\lib\site-packages\telegram\ext\updater.py", line 465, in _network_loop_retry
    if not action_cb():
  File "C:\Users\user\PycharmProjects\pythonProject1\lib\site-packages\telegram\ext\updater.py", line 416, in polling_action_cb
    updates = self.bot.get_updates(
  File "C:\Users\user\PycharmProjects\pythonProject1\lib\site-packages\telegram\bot.py", line 126, in decorator
    result = func(*args, **kwargs)
  File "C:\Users\user\PycharmProjects\pythonProject1\lib\site-packages\telegram\bot.py", line 2748, in get_updates
    result = self._post(
  File "C:\Users\user\PycharmProjects\pythonProject1\lib\site-packages\telegram\bot.py", line 258, in _post
    return self.request.post(
  File "C:\Users\user\PycharmProjects\pythonProject1\lib\site-packages\telegram\utils\request.py", line 349, in post
    result = self._request_wrapper(
  File "C:\Users\user\PycharmProjects\pythonProject1\lib\site-packages\telegram\utils\request.py", line 276, in _request_wrapper
    raise Conflict(message)
telegram.error.Conflict: Conflict: terminated by other getUpdates request; make sure that only one bot instance is running
2021-03-01 00:53:00,764 - ERROR - Error while getting Updates: Conflict: terminated by other getUpdates request; make sure that only one bot instance is running
2021-03-01 00:53:00,764 - ERROR - No error handlers are registered, logging exception.
Traceback (most recent call last):
  File "C:\Users\user\PycharmProjects\pythonProject\venv\lib\site-packages\telegram\ext\updater.py", line 465, in _network_loop_retry
    if not action_cb():
  File "C:\Users\user\PycharmProjects\pythonProject\venv\lib\site-packages\telegram\ext\updater.py", line 416, in polling_action_cb
    updates = self.bot.get_updates(
  File "<decorator-gen-31>", line 2, in get_updates
  File "C:\Users\user\PycharmProjects\pythonProject\venv\lib\site-packages\telegram\bot.py", line 135, in decorator
    result = func(*args, **kwargs)
  File "C:\Users\user\PycharmProjects\pythonProject\venv\lib\site-packages\telegram\bot.py", line 2638, in get_updates
    result = self._post(
  File "C:\Users\user\PycharmProjects\pythonProject\venv\lib\site-packages\telegram\bot.py", line 245, in _post
    return self.request.post(f'{self.base_url}/{endpoint}', data=data, timeout=timeout)
  File "C:\Users\user\PycharmProjects\pythonProject\venv\lib\site-packages\telegram\utils\request.py", line 349, in post
    result = self._request_wrapper(
  File "C:\Users\user\PycharmProjects\pythonProject\venv\lib\site-packages\telegram\utils\request.py", line 276, in _request_wrapper
    raise Conflict(message)
telegram.error.Conflict: Conflict: terminated by other getUpdates request; make sure that only one bot instance is running
