2021-02-23 14:48:15,674 - INFO - Scheduler started
2021-02-23 14:48:16,667 - ERROR - None
Traceback (most recent call last):
  File "C:\Users\user\PycharmProjects\InvestBot\DB\Queries\dbConnection.py", line 31, in query
    records = update_db(conn,sql)
  File "C:\Users\user\PycharmProjects\InvestBot\DB\Queries\dbConnection.py", line 23, in update_db
    records = cursor.fetchall()
psycopg2.ProgrammingError: no results to fetch
2021-02-23 14:48:17,279 - ERROR - ERROR:  duplicate key value violates unique constraint "chat_id"
DETAIL:  Key (chat_id)=(350402934) already exists.
Traceback (most recent call last):
  File "C:\Users\user\PycharmProjects\InvestBot\DB\Queries\dbConnection.py", line 31, in query
    records = update_db(conn,sql)
  File "C:\Users\user\PycharmProjects\InvestBot\DB\Queries\dbConnection.py", line 21, in update_db
    cursor.execute(sql)
psycopg2.errors.UniqueViolation: duplicate key value violates unique constraint "chat_id"
DETAIL:  Key (chat_id)=(350402934) already exists.

2021-02-23 14:48:17,780 - ERROR - ERROR:  duplicate key value violates unique constraint "chat_id"
DETAIL:  Key (chat_id)=(350402934) already exists.
Traceback (most recent call last):
  File "C:\Users\user\PycharmProjects\InvestBot\DB\Queries\dbConnection.py", line 31, in query
    records = update_db(conn,sql)
  File "C:\Users\user\PycharmProjects\InvestBot\DB\Queries\dbConnection.py", line 21, in update_db
    cursor.execute(sql)
psycopg2.errors.UniqueViolation: duplicate key value violates unique constraint "chat_id"
DETAIL:  Key (chat_id)=(350402934) already exists.

2021-02-23 14:49:09,698 - INFO - Scheduler started
2021-02-23 14:49:26,371 - INFO - Scheduler started
2021-02-23 14:50:33,746 - ERROR - ERROR:  duplicate key value violates unique constraint "chat_id"
DETAIL:  Key (chat_id)=(350402934) already exists.
Traceback (most recent call last):
  File "C:\Users\user\PycharmProjects\InvestBot\DB\Queries\dbConnection.py", line 31, in query
    records = update_db(conn,sql)
  File "C:\Users\user\PycharmProjects\InvestBot\DB\Queries\dbConnection.py", line 21, in update_db
    cursor.execute(sql)
psycopg2.errors.UniqueViolation: duplicate key value violates unique constraint "chat_id"
DETAIL:  Key (chat_id)=(350402934) already exists.

2021-02-23 14:51:11,755 - ERROR - ERROR:  duplicate key value violates unique constraint "chat_id"
DETAIL:  Key (chat_id)=(350402934) already exists.
Traceback (most recent call last):
  File "C:\Users\user\PycharmProjects\InvestBot\DB\Queries\dbConnection.py", line 31, in query
    records = update_db(conn,sql)
  File "C:\Users\user\PycharmProjects\InvestBot\DB\Queries\dbConnection.py", line 21, in update_db
    cursor.execute(sql)
psycopg2.errors.UniqueViolation: duplicate key value violates unique constraint "chat_id"
DETAIL:  Key (chat_id)=(350402934) already exists.

2021-02-23 14:51:27,814 - INFO - Scheduler started
2021-02-23 14:51:29,987 - ERROR - ERROR:  duplicate key value violates unique constraint "chat_id"
DETAIL:  Key (chat_id)=(350402934) already exists.
Traceback (most recent call last):
  File "C:\Users\user\PycharmProjects\InvestBot\DB\Queries\dbConnection.py", line 31, in query
    records = update_db(conn,sql)
  File "C:\Users\user\PycharmProjects\InvestBot\DB\Queries\dbConnection.py", line 21, in update_db
    cursor.execute(sql)
psycopg2.errors.UniqueViolation: duplicate key value violates unique constraint "chat_id"
DETAIL:  Key (chat_id)=(350402934) already exists.

2021-02-23 16:05:02,431 - INFO - Scheduler started
2021-02-23 16:05:10,137 - ERROR - ERROR:  duplicate key value violates unique constraint "chat_id"
DETAIL:  Key (chat_id)=(350402934) already exists.
Traceback (most recent call last):
  File "C:\Users\user\PycharmProjects\InvestBot\DB\Queries\dbConnection.py", line 31, in query
    records = update_db(conn,sql)
  File "C:\Users\user\PycharmProjects\InvestBot\DB\Queries\dbConnection.py", line 21, in update_db
    cursor.execute(sql)
psycopg2.errors.UniqueViolation: duplicate key value violates unique constraint "chat_id"
DETAIL:  Key (chat_id)=(350402934) already exists.

2021-02-23 16:05:17,672 - ERROR - No error handlers are registered, logging exception.
Traceback (most recent call last):
  File "C:\Users\user\PycharmProjects\pythonProject1\lib\site-packages\telegram\ext\dispatcher.py", line 442, in process_update
    handler.handle_update(update, self, check, context)
  File "C:\Users\user\PycharmProjects\pythonProject1\lib\site-packages\telegram\ext\conversationhandler.py", line 549, in handle_update
    new_state = handler.handle_update(update, dispatcher, check_result, context)
  File "C:\Users\user\PycharmProjects\pythonProject1\lib\site-packages\telegram\ext\handler.py", line 160, in handle_update
    return self.callback(update, context)
  File "C:\Users\user\PycharmProjects\InvestBot\Handlers\ConversationHandlers\CurrencyConversationHandler.py", line 26, in mosCurrency
    sector(bot)
TypeError: sector() missing 1 required positional argument: 'update'
2021-02-23 16:06:25,854 - INFO - Scheduler started
2021-02-23 16:06:31,710 - ERROR - No error handlers are registered, logging exception.
Traceback (most recent call last):
  File "C:\Users\user\PycharmProjects\pythonProject1\lib\site-packages\telegram\ext\dispatcher.py", line 442, in process_update
    handler.handle_update(update, self, check, context)
  File "C:\Users\user\PycharmProjects\pythonProject1\lib\site-packages\telegram\ext\conversationhandler.py", line 549, in handle_update
    new_state = handler.handle_update(update, dispatcher, check_result, context)
  File "C:\Users\user\PycharmProjects\pythonProject1\lib\site-packages\telegram\ext\handler.py", line 160, in handle_update
    return self.callback(update, context)
  File "C:\Users\user\PycharmProjects\InvestBot\Handlers\ConversationHandlers\CurrencyConversationHandler.py", line 26, in mosCurrency
    sector(bot)
  File "C:\Users\user\PycharmProjects\InvestBot\Handlers\ConversationHandlers\CurrencyConversationHandler.py", line 59, in sector
    reply_markup=sectorMarkup())
TypeError: sectorMarkup() missing 2 required positional arguments: 'bot' and 'update'
2021-02-23 16:12:09,612 - INFO - Scheduler started
2021-02-23 16:14:01,279 - INFO - Scheduler started
2021-02-23 16:16:00,774 - INFO - Scheduler started
2021-02-23 16:16:06,091 - ERROR - Error while getting Updates: Conflict: terminated by other getUpdates request; make sure that only one bot instance is running
2021-02-23 16:16:06,091 - ERROR - No error handlers are registered, logging exception.
Traceback (most recent call last):
  File "C:\Users\user\PycharmProjects\pythonProject1\lib\site-packages\telegram\ext\updater.py", line 465, in _network_loop_retry
    if not action_cb():
  File "C:\Users\user\PycharmProjects\pythonProject1\lib\site-packages\telegram\ext\updater.py", line 416, in polling_action_cb
    updates = self.bot.get_updates(
  File "C:\Users\user\PycharmProjects\pythonProject1\lib\site-packages\telegram\bot.py", line 126, in decorator
    result = func(*args, **kwargs)
  File "C:\Users\user\PycharmProjects\pythonProject1\lib\site-packages\telegram\bot.py", line 2748, in get_updates
    result = self._post(
  File "C:\Users\user\PycharmProjects\pythonProject1\lib\site-packages\telegram\bot.py", line 258, in _post
    return self.request.post(
  File "C:\Users\user\PycharmProjects\pythonProject1\lib\site-packages\telegram\utils\request.py", line 349, in post
    result = self._request_wrapper(
  File "C:\Users\user\PycharmProjects\pythonProject1\lib\site-packages\telegram\utils\request.py", line 276, in _request_wrapper
    raise Conflict(message)
telegram.error.Conflict: Conflict: terminated by other getUpdates request; make sure that only one bot instance is running
2021-02-23 16:16:45,662 - INFO - Scheduler started
2021-02-23 16:18:14,558 - ERROR - Error while getting Updates: Conflict: terminated by other getUpdates request; make sure that only one bot instance is running
2021-02-23 16:18:14,559 - ERROR - No error handlers are registered, logging exception.
Traceback (most recent call last):
  File "C:\Users\user\PycharmProjects\pythonProject1\lib\site-packages\telegram\ext\updater.py", line 465, in _network_loop_retry
    if not action_cb():
  File "C:\Users\user\PycharmProjects\pythonProject1\lib\site-packages\telegram\ext\updater.py", line 416, in polling_action_cb
    updates = self.bot.get_updates(
  File "C:\Users\user\PycharmProjects\pythonProject1\lib\site-packages\telegram\bot.py", line 126, in decorator
    result = func(*args, **kwargs)
  File "C:\Users\user\PycharmProjects\pythonProject1\lib\site-packages\telegram\bot.py", line 2748, in get_updates
    result = self._post(
  File "C:\Users\user\PycharmProjects\pythonProject1\lib\site-packages\telegram\bot.py", line 258, in _post
    return self.request.post(
  File "C:\Users\user\PycharmProjects\pythonProject1\lib\site-packages\telegram\utils\request.py", line 349, in post
    result = self._request_wrapper(
  File "C:\Users\user\PycharmProjects\pythonProject1\lib\site-packages\telegram\utils\request.py", line 276, in _request_wrapper
    raise Conflict(message)
telegram.error.Conflict: Conflict: terminated by other getUpdates request; make sure that only one bot instance is running
2021-02-23 16:18:20,195 - ERROR - Error while getting Updates: Conflict: terminated by other getUpdates request; make sure that only one bot instance is running
2021-02-23 16:18:20,195 - ERROR - No error handlers are registered, logging exception.
Traceback (most recent call last):
  File "C:\Users\user\PycharmProjects\pythonProject1\lib\site-packages\telegram\ext\updater.py", line 465, in _network_loop_retry
    if not action_cb():
  File "C:\Users\user\PycharmProjects\pythonProject1\lib\site-packages\telegram\ext\updater.py", line 416, in polling_action_cb
    updates = self.bot.get_updates(
  File "C:\Users\user\PycharmProjects\pythonProject1\lib\site-packages\telegram\bot.py", line 126, in decorator
    result = func(*args, **kwargs)
  File "C:\Users\user\PycharmProjects\pythonProject1\lib\site-packages\telegram\bot.py", line 2748, in get_updates
    result = self._post(
  File "C:\Users\user\PycharmProjects\pythonProject1\lib\site-packages\telegram\bot.py", line 258, in _post
    return self.request.post(
  File "C:\Users\user\PycharmProjects\pythonProject1\lib\site-packages\telegram\utils\request.py", line 349, in post
    result = self._request_wrapper(
  File "C:\Users\user\PycharmProjects\pythonProject1\lib\site-packages\telegram\utils\request.py", line 276, in _request_wrapper
    raise Conflict(message)
telegram.error.Conflict: Conflict: terminated by other getUpdates request; make sure that only one bot instance is running
2021-02-23 16:18:26,254 - ERROR - Error while getting Updates: Conflict: terminated by other getUpdates request; make sure that only one bot instance is running
2021-02-23 16:18:26,255 - ERROR - No error handlers are registered, logging exception.
Traceback (most recent call last):
  File "C:\Users\user\PycharmProjects\pythonProject1\lib\site-packages\telegram\ext\updater.py", line 465, in _network_loop_retry
    if not action_cb():
  File "C:\Users\user\PycharmProjects\pythonProject1\lib\site-packages\telegram\ext\updater.py", line 416, in polling_action_cb
    updates = self.bot.get_updates(
  File "C:\Users\user\PycharmProjects\pythonProject1\lib\site-packages\telegram\bot.py", line 126, in decorator
    result = func(*args, **kwargs)
  File "C:\Users\user\PycharmProjects\pythonProject1\lib\site-packages\telegram\bot.py", line 2748, in get_updates
    result = self._post(
  File "C:\Users\user\PycharmProjects\pythonProject1\lib\site-packages\telegram\bot.py", line 258, in _post
    return self.request.post(
  File "C:\Users\user\PycharmProjects\pythonProject1\lib\site-packages\telegram\utils\request.py", line 349, in post
    result = self._request_wrapper(
  File "C:\Users\user\PycharmProjects\pythonProject1\lib\site-packages\telegram\utils\request.py", line 276, in _request_wrapper
    raise Conflict(message)
telegram.error.Conflict: Conflict: terminated by other getUpdates request; make sure that only one bot instance is running
2021-02-23 16:18:32,253 - ERROR - Error while getting Updates: Conflict: terminated by other getUpdates request; make sure that only one bot instance is running
2021-02-23 16:18:32,254 - ERROR - No error handlers are registered, logging exception.
Traceback (most recent call last):
  File "C:\Users\user\PycharmProjects\pythonProject1\lib\site-packages\telegram\ext\updater.py", line 465, in _network_loop_retry
    if not action_cb():
  File "C:\Users\user\PycharmProjects\pythonProject1\lib\site-packages\telegram\ext\updater.py", line 416, in polling_action_cb
    updates = self.bot.get_updates(
  File "C:\Users\user\PycharmProjects\pythonProject1\lib\site-packages\telegram\bot.py", line 126, in decorator
    result = func(*args, **kwargs)
  File "C:\Users\user\PycharmProjects\pythonProject1\lib\site-packages\telegram\bot.py", line 2748, in get_updates
    result = self._post(
  File "C:\Users\user\PycharmProjects\pythonProject1\lib\site-packages\telegram\bot.py", line 258, in _post
    return self.request.post(
  File "C:\Users\user\PycharmProjects\pythonProject1\lib\site-packages\telegram\utils\request.py", line 349, in post
    result = self._request_wrapper(
  File "C:\Users\user\PycharmProjects\pythonProject1\lib\site-packages\telegram\utils\request.py", line 276, in _request_wrapper
    raise Conflict(message)
telegram.error.Conflict: Conflict: terminated by other getUpdates request; make sure that only one bot instance is running
2021-02-23 16:18:49,969 - INFO - Scheduler started
2021-02-23 16:20:49,999 - ERROR - Error while getting Updates: Conflict: terminated by other getUpdates request; make sure that only one bot instance is running
2021-02-23 16:20:49,999 - ERROR - No error handlers are registered, logging exception.
Traceback (most recent call last):
  File "C:\Users\user\PycharmProjects\pythonProject1\lib\site-packages\telegram\ext\updater.py", line 465, in _network_loop_retry
    if not action_cb():
  File "C:\Users\user\PycharmProjects\pythonProject1\lib\site-packages\telegram\ext\updater.py", line 416, in polling_action_cb
    updates = self.bot.get_updates(
  File "C:\Users\user\PycharmProjects\pythonProject1\lib\site-packages\telegram\bot.py", line 126, in decorator
    result = func(*args, **kwargs)
  File "C:\Users\user\PycharmProjects\pythonProject1\lib\site-packages\telegram\bot.py", line 2748, in get_updates
    result = self._post(
  File "C:\Users\user\PycharmProjects\pythonProject1\lib\site-packages\telegram\bot.py", line 258, in _post
    return self.request.post(
  File "C:\Users\user\PycharmProjects\pythonProject1\lib\site-packages\telegram\utils\request.py", line 349, in post
    result = self._request_wrapper(
  File "C:\Users\user\PycharmProjects\pythonProject1\lib\site-packages\telegram\utils\request.py", line 276, in _request_wrapper
    raise Conflict(message)
telegram.error.Conflict: Conflict: terminated by other getUpdates request; make sure that only one bot instance is running
2021-02-23 16:20:55,775 - ERROR - Error while getting Updates: Conflict: terminated by other getUpdates request; make sure that only one bot instance is running
2021-02-23 16:20:55,775 - ERROR - No error handlers are registered, logging exception.
Traceback (most recent call last):
  File "C:\Users\user\PycharmProjects\pythonProject1\lib\site-packages\telegram\ext\updater.py", line 465, in _network_loop_retry
    if not action_cb():
  File "C:\Users\user\PycharmProjects\pythonProject1\lib\site-packages\telegram\ext\updater.py", line 416, in polling_action_cb
    updates = self.bot.get_updates(
  File "C:\Users\user\PycharmProjects\pythonProject1\lib\site-packages\telegram\bot.py", line 126, in decorator
    result = func(*args, **kwargs)
  File "C:\Users\user\PycharmProjects\pythonProject1\lib\site-packages\telegram\bot.py", line 2748, in get_updates
    result = self._post(
  File "C:\Users\user\PycharmProjects\pythonProject1\lib\site-packages\telegram\bot.py", line 258, in _post
    return self.request.post(
  File "C:\Users\user\PycharmProjects\pythonProject1\lib\site-packages\telegram\utils\request.py", line 349, in post
    result = self._request_wrapper(
  File "C:\Users\user\PycharmProjects\pythonProject1\lib\site-packages\telegram\utils\request.py", line 276, in _request_wrapper
    raise Conflict(message)
telegram.error.Conflict: Conflict: terminated by other getUpdates request; make sure that only one bot instance is running
2021-02-23 16:21:02,071 - ERROR - Error while getting Updates: Conflict: terminated by other getUpdates request; make sure that only one bot instance is running
2021-02-23 16:21:02,071 - ERROR - No error handlers are registered, logging exception.
Traceback (most recent call last):
  File "C:\Users\user\PycharmProjects\pythonProject1\lib\site-packages\telegram\ext\updater.py", line 465, in _network_loop_retry
    if not action_cb():
  File "C:\Users\user\PycharmProjects\pythonProject1\lib\site-packages\telegram\ext\updater.py", line 416, in polling_action_cb
    updates = self.bot.get_updates(
  File "C:\Users\user\PycharmProjects\pythonProject1\lib\site-packages\telegram\bot.py", line 126, in decorator
    result = func(*args, **kwargs)
  File "C:\Users\user\PycharmProjects\pythonProject1\lib\site-packages\telegram\bot.py", line 2748, in get_updates
    result = self._post(
  File "C:\Users\user\PycharmProjects\pythonProject1\lib\site-packages\telegram\bot.py", line 258, in _post
    return self.request.post(
  File "C:\Users\user\PycharmProjects\pythonProject1\lib\site-packages\telegram\utils\request.py", line 349, in post
    result = self._request_wrapper(
  File "C:\Users\user\PycharmProjects\pythonProject1\lib\site-packages\telegram\utils\request.py", line 276, in _request_wrapper
    raise Conflict(message)
telegram.error.Conflict: Conflict: terminated by other getUpdates request; make sure that only one bot instance is running
2021-02-23 16:21:09,553 - ERROR - Error while getting Updates: Conflict: terminated by other getUpdates request; make sure that only one bot instance is running
2021-02-23 16:21:09,553 - ERROR - No error handlers are registered, logging exception.
Traceback (most recent call last):
  File "C:\Users\user\PycharmProjects\pythonProject1\lib\site-packages\telegram\ext\updater.py", line 465, in _network_loop_retry
    if not action_cb():
  File "C:\Users\user\PycharmProjects\pythonProject1\lib\site-packages\telegram\ext\updater.py", line 416, in polling_action_cb
    updates = self.bot.get_updates(
  File "C:\Users\user\PycharmProjects\pythonProject1\lib\site-packages\telegram\bot.py", line 126, in decorator
    result = func(*args, **kwargs)
  File "C:\Users\user\PycharmProjects\pythonProject1\lib\site-packages\telegram\bot.py", line 2748, in get_updates
    result = self._post(
  File "C:\Users\user\PycharmProjects\pythonProject1\lib\site-packages\telegram\bot.py", line 258, in _post
    return self.request.post(
  File "C:\Users\user\PycharmProjects\pythonProject1\lib\site-packages\telegram\utils\request.py", line 349, in post
    result = self._request_wrapper(
  File "C:\Users\user\PycharmProjects\pythonProject1\lib\site-packages\telegram\utils\request.py", line 276, in _request_wrapper
    raise Conflict(message)
telegram.error.Conflict: Conflict: terminated by other getUpdates request; make sure that only one bot instance is running
2021-02-23 16:21:19,387 - ERROR - Error while getting Updates: Conflict: terminated by other getUpdates request; make sure that only one bot instance is running
2021-02-23 16:21:19,387 - ERROR - No error handlers are registered, logging exception.
Traceback (most recent call last):
  File "C:\Users\user\PycharmProjects\pythonProject1\lib\site-packages\telegram\ext\updater.py", line 465, in _network_loop_retry
    if not action_cb():
  File "C:\Users\user\PycharmProjects\pythonProject1\lib\site-packages\telegram\ext\updater.py", line 416, in polling_action_cb
    updates = self.bot.get_updates(
  File "C:\Users\user\PycharmProjects\pythonProject1\lib\site-packages\telegram\bot.py", line 126, in decorator
    result = func(*args, **kwargs)
  File "C:\Users\user\PycharmProjects\pythonProject1\lib\site-packages\telegram\bot.py", line 2748, in get_updates
    result = self._post(
  File "C:\Users\user\PycharmProjects\pythonProject1\lib\site-packages\telegram\bot.py", line 258, in _post
    return self.request.post(
  File "C:\Users\user\PycharmProjects\pythonProject1\lib\site-packages\telegram\utils\request.py", line 349, in post
    result = self._request_wrapper(
  File "C:\Users\user\PycharmProjects\pythonProject1\lib\site-packages\telegram\utils\request.py", line 276, in _request_wrapper
    raise Conflict(message)
telegram.error.Conflict: Conflict: terminated by other getUpdates request; make sure that only one bot instance is running
2021-02-23 16:21:29,207 - ERROR - Error while getting Updates: Conflict: terminated by other getUpdates request; make sure that only one bot instance is running
2021-02-23 16:21:29,208 - ERROR - No error handlers are registered, logging exception.
Traceback (most recent call last):
  File "C:\Users\user\PycharmProjects\pythonProject1\lib\site-packages\telegram\ext\updater.py", line 465, in _network_loop_retry
    if not action_cb():
  File "C:\Users\user\PycharmProjects\pythonProject1\lib\site-packages\telegram\ext\updater.py", line 416, in polling_action_cb
    updates = self.bot.get_updates(
  File "C:\Users\user\PycharmProjects\pythonProject1\lib\site-packages\telegram\bot.py", line 126, in decorator
    result = func(*args, **kwargs)
  File "C:\Users\user\PycharmProjects\pythonProject1\lib\site-packages\telegram\bot.py", line 2748, in get_updates
    result = self._post(
  File "C:\Users\user\PycharmProjects\pythonProject1\lib\site-packages\telegram\bot.py", line 258, in _post
    return self.request.post(
  File "C:\Users\user\PycharmProjects\pythonProject1\lib\site-packages\telegram\utils\request.py", line 349, in post
    result = self._request_wrapper(
  File "C:\Users\user\PycharmProjects\pythonProject1\lib\site-packages\telegram\utils\request.py", line 276, in _request_wrapper
    raise Conflict(message)
telegram.error.Conflict: Conflict: terminated by other getUpdates request; make sure that only one bot instance is running
2021-02-23 16:21:42,066 - ERROR - Error while getting Updates: Conflict: terminated by other getUpdates request; make sure that only one bot instance is running
2021-02-23 16:21:42,066 - ERROR - No error handlers are registered, logging exception.
Traceback (most recent call last):
  File "C:\Users\user\PycharmProjects\pythonProject1\lib\site-packages\telegram\ext\updater.py", line 465, in _network_loop_retry
    if not action_cb():
  File "C:\Users\user\PycharmProjects\pythonProject1\lib\site-packages\telegram\ext\updater.py", line 416, in polling_action_cb
    updates = self.bot.get_updates(
  File "C:\Users\user\PycharmProjects\pythonProject1\lib\site-packages\telegram\bot.py", line 126, in decorator
    result = func(*args, **kwargs)
  File "C:\Users\user\PycharmProjects\pythonProject1\lib\site-packages\telegram\bot.py", line 2748, in get_updates
    result = self._post(
  File "C:\Users\user\PycharmProjects\pythonProject1\lib\site-packages\telegram\bot.py", line 258, in _post
    return self.request.post(
  File "C:\Users\user\PycharmProjects\pythonProject1\lib\site-packages\telegram\utils\request.py", line 349, in post
    result = self._request_wrapper(
  File "C:\Users\user\PycharmProjects\pythonProject1\lib\site-packages\telegram\utils\request.py", line 276, in _request_wrapper
    raise Conflict(message)
telegram.error.Conflict: Conflict: terminated by other getUpdates request; make sure that only one bot instance is running
2021-02-23 16:21:58,223 - ERROR - Error while getting Updates: Conflict: terminated by other getUpdates request; make sure that only one bot instance is running
2021-02-23 16:21:58,223 - ERROR - No error handlers are registered, logging exception.
Traceback (most recent call last):
  File "C:\Users\user\PycharmProjects\pythonProject1\lib\site-packages\telegram\ext\updater.py", line 465, in _network_loop_retry
    if not action_cb():
  File "C:\Users\user\PycharmProjects\pythonProject1\lib\site-packages\telegram\ext\updater.py", line 416, in polling_action_cb
    updates = self.bot.get_updates(
  File "C:\Users\user\PycharmProjects\pythonProject1\lib\site-packages\telegram\bot.py", line 126, in decorator
    result = func(*args, **kwargs)
  File "C:\Users\user\PycharmProjects\pythonProject1\lib\site-packages\telegram\bot.py", line 2748, in get_updates
    result = self._post(
  File "C:\Users\user\PycharmProjects\pythonProject1\lib\site-packages\telegram\bot.py", line 258, in _post
    return self.request.post(
  File "C:\Users\user\PycharmProjects\pythonProject1\lib\site-packages\telegram\utils\request.py", line 349, in post
    result = self._request_wrapper(
  File "C:\Users\user\PycharmProjects\pythonProject1\lib\site-packages\telegram\utils\request.py", line 276, in _request_wrapper
    raise Conflict(message)
telegram.error.Conflict: Conflict: terminated by other getUpdates request; make sure that only one bot instance is running
2021-02-26 14:11:19,152 - INFO - Scheduler started
2021-02-26 14:11:47,776 - ERROR - ERROR:  duplicate key value violates unique constraint "chat_id"
DETAIL:  Key (chat_id)=(350402934) already exists.
Traceback (most recent call last):
  File "C:\Users\user\PycharmProjects\InvestBot\DB\Queries\dbConnection.py", line 31, in query
    records = update_db(conn,sql)
  File "C:\Users\user\PycharmProjects\InvestBot\DB\Queries\dbConnection.py", line 21, in update_db
    cursor.execute(sql)
psycopg2.errors.UniqueViolation: duplicate key value violates unique constraint "chat_id"
DETAIL:  Key (chat_id)=(350402934) already exists.

2021-02-26 14:11:52,307 - ERROR - ERROR:  duplicate key value violates unique constraint "chat_id"
DETAIL:  Key (chat_id)=(350402934) already exists.
Traceback (most recent call last):
  File "C:\Users\user\PycharmProjects\InvestBot\DB\Queries\dbConnection.py", line 31, in query
    records = update_db(conn,sql)
  File "C:\Users\user\PycharmProjects\InvestBot\DB\Queries\dbConnection.py", line 21, in update_db
    cursor.execute(sql)
psycopg2.errors.UniqueViolation: duplicate key value violates unique constraint "chat_id"
DETAIL:  Key (chat_id)=(350402934) already exists.

2021-02-26 14:12:29,838 - ERROR - ERROR:  duplicate key value violates unique constraint "chat_id"
DETAIL:  Key (chat_id)=(350402934) already exists.
Traceback (most recent call last):
  File "C:\Users\user\PycharmProjects\InvestBot\DB\Queries\dbConnection.py", line 31, in query
    records = update_db(conn,sql)
  File "C:\Users\user\PycharmProjects\InvestBot\DB\Queries\dbConnection.py", line 21, in update_db
    cursor.execute(sql)
psycopg2.errors.UniqueViolation: duplicate key value violates unique constraint "chat_id"
DETAIL:  Key (chat_id)=(350402934) already exists.

2021-02-26 14:12:54,161 - INFO - Scheduler started
2021-02-26 14:14:11,802 - INFO - Scheduler started
2021-02-26 14:15:29,471 - INFO - Scheduler started
2021-02-26 14:22:02,496 - INFO - Scheduler started
2021-02-28 23:04:47,521 - INFO - Scheduler started
2021-02-28 23:05:05,853 - ERROR - ERROR:  duplicate key value violates unique constraint "chat_id"
DETAIL:  Key (chat_id)=(350402934) already exists.
Traceback (most recent call last):
  File "C:\Users\user\PycharmProjects\InvestBot\DB\Queries\dbConnection.py", line 31, in query
    records = update_db(conn,sql)
  File "C:\Users\user\PycharmProjects\InvestBot\DB\Queries\dbConnection.py", line 21, in update_db
    cursor.execute(sql)
psycopg2.errors.UniqueViolation: duplicate key value violates unique constraint "chat_id"
DETAIL:  Key (chat_id)=(350402934) already exists.

2021-02-28 23:06:01,748 - ERROR - ERROR:  duplicate key value violates unique constraint "chat_id"
DETAIL:  Key (chat_id)=(350402934) already exists.
Traceback (most recent call last):
  File "C:\Users\user\PycharmProjects\InvestBot\DB\Queries\dbConnection.py", line 31, in query
    records = update_db(conn,sql)
  File "C:\Users\user\PycharmProjects\InvestBot\DB\Queries\dbConnection.py", line 21, in update_db
    cursor.execute(sql)
psycopg2.errors.UniqueViolation: duplicate key value violates unique constraint "chat_id"
DETAIL:  Key (chat_id)=(350402934) already exists.

2021-02-28 23:06:54,937 - ERROR - ERROR:  duplicate key value violates unique constraint "chat_id"
DETAIL:  Key (chat_id)=(350402934) already exists.
Traceback (most recent call last):
  File "C:\Users\user\PycharmProjects\InvestBot\DB\Queries\dbConnection.py", line 31, in query
    records = update_db(conn,sql)
  File "C:\Users\user\PycharmProjects\InvestBot\DB\Queries\dbConnection.py", line 21, in update_db
    cursor.execute(sql)
psycopg2.errors.UniqueViolation: duplicate key value violates unique constraint "chat_id"
DETAIL:  Key (chat_id)=(350402934) already exists.

2021-02-28 23:06:57,715 - ERROR - ERROR:  duplicate key value violates unique constraint "chat_id"
DETAIL:  Key (chat_id)=(350402934) already exists.
Traceback (most recent call last):
  File "C:\Users\user\PycharmProjects\InvestBot\DB\Queries\dbConnection.py", line 31, in query
    records = update_db(conn,sql)
  File "C:\Users\user\PycharmProjects\InvestBot\DB\Queries\dbConnection.py", line 21, in update_db
    cursor.execute(sql)
psycopg2.errors.UniqueViolation: duplicate key value violates unique constraint "chat_id"
DETAIL:  Key (chat_id)=(350402934) already exists.

2021-02-28 23:07:15,588 - INFO - Scheduler started
2021-02-28 23:07:16,750 - ERROR - ERROR:  duplicate key value violates unique constraint "chat_id"
DETAIL:  Key (chat_id)=(350402934) already exists.
Traceback (most recent call last):
  File "C:\Users\user\PycharmProjects\InvestBot\DB\Queries\dbConnection.py", line 31, in query
    records = update_db(conn,sql)
  File "C:\Users\user\PycharmProjects\InvestBot\DB\Queries\dbConnection.py", line 21, in update_db
    cursor.execute(sql)
psycopg2.errors.UniqueViolation: duplicate key value violates unique constraint "chat_id"
DETAIL:  Key (chat_id)=(350402934) already exists.

2021-03-01 00:11:30,566 - ERROR - Error while getting Updates: Conflict: terminated by other getUpdates request; make sure that only one bot instance is running
2021-03-01 00:11:30,567 - ERROR - No error handlers are registered, logging exception.
Traceback (most recent call last):
  File "C:\Users\user\PycharmProjects\pythonProject1\lib\site-packages\telegram\ext\updater.py", line 465, in _network_loop_retry
    if not action_cb():
  File "C:\Users\user\PycharmProjects\pythonProject1\lib\site-packages\telegram\ext\updater.py", line 416, in polling_action_cb
    updates = self.bot.get_updates(
  File "C:\Users\user\PycharmProjects\pythonProject1\lib\site-packages\telegram\bot.py", line 126, in decorator
    result = func(*args, **kwargs)
  File "C:\Users\user\PycharmProjects\pythonProject1\lib\site-packages\telegram\bot.py", line 2748, in get_updates
    result = self._post(
  File "C:\Users\user\PycharmProjects\pythonProject1\lib\site-packages\telegram\bot.py", line 258, in _post
    return self.request.post(
  File "C:\Users\user\PycharmProjects\pythonProject1\lib\site-packages\telegram\utils\request.py", line 349, in post
    result = self._request_wrapper(
  File "C:\Users\user\PycharmProjects\pythonProject1\lib\site-packages\telegram\utils\request.py", line 276, in _request_wrapper
    raise Conflict(message)
telegram.error.Conflict: Conflict: terminated by other getUpdates request; make sure that only one bot instance is running
2021-03-01 00:11:35,995 - ERROR - Error while getting Updates: Conflict: terminated by other getUpdates request; make sure that only one bot instance is running
2021-03-01 00:11:35,996 - ERROR - No error handlers are registered, logging exception.
Traceback (most recent call last):
  File "C:\Users\user\PycharmProjects\pythonProject1\lib\site-packages\telegram\ext\updater.py", line 465, in _network_loop_retry
    if not action_cb():
  File "C:\Users\user\PycharmProjects\pythonProject1\lib\site-packages\telegram\ext\updater.py", line 416, in polling_action_cb
    updates = self.bot.get_updates(
  File "C:\Users\user\PycharmProjects\pythonProject1\lib\site-packages\telegram\bot.py", line 126, in decorator
    result = func(*args, **kwargs)
  File "C:\Users\user\PycharmProjects\pythonProject1\lib\site-packages\telegram\bot.py", line 2748, in get_updates
    result = self._post(
  File "C:\Users\user\PycharmProjects\pythonProject1\lib\site-packages\telegram\bot.py", line 258, in _post
    return self.request.post(
  File "C:\Users\user\PycharmProjects\pythonProject1\lib\site-packages\telegram\utils\request.py", line 349, in post
    result = self._request_wrapper(
  File "C:\Users\user\PycharmProjects\pythonProject1\lib\site-packages\telegram\utils\request.py", line 276, in _request_wrapper
    raise Conflict(message)
telegram.error.Conflict: Conflict: terminated by other getUpdates request; make sure that only one bot instance is running
2021-03-01 00:11:42,484 - ERROR - Error while getting Updates: Conflict: terminated by other getUpdates request; make sure that only one bot instance is running
2021-03-01 00:11:42,485 - ERROR - No error handlers are registered, logging exception.
Traceback (most recent call last):
  File "C:\Users\user\PycharmProjects\pythonProject1\lib\site-packages\telegram\ext\updater.py", line 465, in _network_loop_retry
    if not action_cb():
  File "C:\Users\user\PycharmProjects\pythonProject1\lib\site-packages\telegram\ext\updater.py", line 416, in polling_action_cb
    updates = self.bot.get_updates(
  File "C:\Users\user\PycharmProjects\pythonProject1\lib\site-packages\telegram\bot.py", line 126, in decorator
    result = func(*args, **kwargs)
  File "C:\Users\user\PycharmProjects\pythonProject1\lib\site-packages\telegram\bot.py", line 2748, in get_updates
    result = self._post(
  File "C:\Users\user\PycharmProjects\pythonProject1\lib\site-packages\telegram\bot.py", line 258, in _post
    return self.request.post(
  File "C:\Users\user\PycharmProjects\pythonProject1\lib\site-packages\telegram\utils\request.py", line 349, in post
    result = self._request_wrapper(
  File "C:\Users\user\PycharmProjects\pythonProject1\lib\site-packages\telegram\utils\request.py", line 276, in _request_wrapper
    raise Conflict(message)
telegram.error.Conflict: Conflict: terminated by other getUpdates request; make sure that only one bot instance is running
2021-03-01 00:11:49,148 - ERROR - Error while getting Updates: Conflict: terminated by other getUpdates request; make sure that only one bot instance is running
2021-03-01 00:11:49,149 - ERROR - No error handlers are registered, logging exception.
Traceback (most recent call last):
  File "C:\Users\user\PycharmProjects\pythonProject1\lib\site-packages\telegram\ext\updater.py", line 465, in _network_loop_retry
    if not action_cb():
  File "C:\Users\user\PycharmProjects\pythonProject1\lib\site-packages\telegram\ext\updater.py", line 416, in polling_action_cb
    updates = self.bot.get_updates(
  File "C:\Users\user\PycharmProjects\pythonProject1\lib\site-packages\telegram\bot.py", line 126, in decorator
    result = func(*args, **kwargs)
  File "C:\Users\user\PycharmProjects\pythonProject1\lib\site-packages\telegram\bot.py", line 2748, in get_updates
    result = self._post(
  File "C:\Users\user\PycharmProjects\pythonProject1\lib\site-packages\telegram\bot.py", line 258, in _post
    return self.request.post(
  File "C:\Users\user\PycharmProjects\pythonProject1\lib\site-packages\telegram\utils\request.py", line 349, in post
    result = self._request_wrapper(
  File "C:\Users\user\PycharmProjects\pythonProject1\lib\site-packages\telegram\utils\request.py", line 276, in _request_wrapper
    raise Conflict(message)
telegram.error.Conflict: Conflict: terminated by other getUpdates request; make sure that only one bot instance is running
2021-03-01 00:12:20,327 - ERROR - Error while getting Updates: Conflict: terminated by other getUpdates request; make sure that only one bot instance is running
2021-03-01 00:12:20,327 - ERROR - No error handlers are registered, logging exception.
Traceback (most recent call last):
  File "C:\Users\user\PycharmProjects\pythonProject1\lib\site-packages\telegram\ext\updater.py", line 465, in _network_loop_retry
    if not action_cb():
  File "C:\Users\user\PycharmProjects\pythonProject1\lib\site-packages\telegram\ext\updater.py", line 416, in polling_action_cb
    updates = self.bot.get_updates(
  File "C:\Users\user\PycharmProjects\pythonProject1\lib\site-packages\telegram\bot.py", line 126, in decorator
    result = func(*args, **kwargs)
  File "C:\Users\user\PycharmProjects\pythonProject1\lib\site-packages\telegram\bot.py", line 2748, in get_updates
    result = self._post(
  File "C:\Users\user\PycharmProjects\pythonProject1\lib\site-packages\telegram\bot.py", line 258, in _post
    return self.request.post(
  File "C:\Users\user\PycharmProjects\pythonProject1\lib\site-packages\telegram\utils\request.py", line 349, in post
    result = self._request_wrapper(
  File "C:\Users\user\PycharmProjects\pythonProject1\lib\site-packages\telegram\utils\request.py", line 276, in _request_wrapper
    raise Conflict(message)
telegram.error.Conflict: Conflict: terminated by other getUpdates request; make sure that only one bot instance is running
2021-03-01 00:12:25,855 - ERROR - Error while getting Updates: Conflict: terminated by other getUpdates request; make sure that only one bot instance is running
2021-03-01 00:12:25,856 - ERROR - No error handlers are registered, logging exception.
Traceback (most recent call last):
  File "C:\Users\user\PycharmProjects\pythonProject1\lib\site-packages\telegram\ext\updater.py", line 465, in _network_loop_retry
    if not action_cb():
  File "C:\Users\user\PycharmProjects\pythonProject1\lib\site-packages\telegram\ext\updater.py", line 416, in polling_action_cb
    updates = self.bot.get_updates(
  File "C:\Users\user\PycharmProjects\pythonProject1\lib\site-packages\telegram\bot.py", line 126, in decorator
    result = func(*args, **kwargs)
  File "C:\Users\user\PycharmProjects\pythonProject1\lib\site-packages\telegram\bot.py", line 2748, in get_updates
    result = self._post(
  File "C:\Users\user\PycharmProjects\pythonProject1\lib\site-packages\telegram\bot.py", line 258, in _post
    return self.request.post(
  File "C:\Users\user\PycharmProjects\pythonProject1\lib\site-packages\telegram\utils\request.py", line 349, in post
    result = self._request_wrapper(
  File "C:\Users\user\PycharmProjects\pythonProject1\lib\site-packages\telegram\utils\request.py", line 276, in _request_wrapper
    raise Conflict(message)
telegram.error.Conflict: Conflict: terminated by other getUpdates request; make sure that only one bot instance is running
2021-03-01 00:12:31,893 - ERROR - Error while getting Updates: Conflict: terminated by other getUpdates request; make sure that only one bot instance is running
2021-03-01 00:12:31,894 - ERROR - No error handlers are registered, logging exception.
Traceback (most recent call last):
  File "C:\Users\user\PycharmProjects\pythonProject1\lib\site-packages\telegram\ext\updater.py", line 465, in _network_loop_retry
    if not action_cb():
  File "C:\Users\user\PycharmProjects\pythonProject1\lib\site-packages\telegram\ext\updater.py", line 416, in polling_action_cb
    updates = self.bot.get_updates(
  File "C:\Users\user\PycharmProjects\pythonProject1\lib\site-packages\telegram\bot.py", line 126, in decorator
    result = func(*args, **kwargs)
  File "C:\Users\user\PycharmProjects\pythonProject1\lib\site-packages\telegram\bot.py", line 2748, in get_updates
    result = self._post(
  File "C:\Users\user\PycharmProjects\pythonProject1\lib\site-packages\telegram\bot.py", line 258, in _post
    return self.request.post(
  File "C:\Users\user\PycharmProjects\pythonProject1\lib\site-packages\telegram\utils\request.py", line 349, in post
    result = self._request_wrapper(
  File "C:\Users\user\PycharmProjects\pythonProject1\lib\site-packages\telegram\utils\request.py", line 276, in _request_wrapper
    raise Conflict(message)
telegram.error.Conflict: Conflict: terminated by other getUpdates request; make sure that only one bot instance is running
2021-03-01 00:48:02,408 - INFO - Scheduler started
2021-03-01 00:48:03,695 - ERROR - Error while getting Updates: Conflict: terminated by other getUpdates request; make sure that only one bot instance is running
2021-03-01 00:48:03,696 - ERROR - No error handlers are registered, logging exception.
Traceback (most recent call last):
  File "C:\Users\user\PycharmProjects\pythonProject1\lib\site-packages\telegram\ext\updater.py", line 465, in _network_loop_retry
    if not action_cb():
  File "C:\Users\user\PycharmProjects\pythonProject1\lib\site-packages\telegram\ext\updater.py", line 416, in polling_action_cb
    updates = self.bot.get_updates(
  File "C:\Users\user\PycharmProjects\pythonProject1\lib\site-packages\telegram\bot.py", line 126, in decorator
    result = func(*args, **kwargs)
  File "C:\Users\user\PycharmProjects\pythonProject1\lib\site-packages\telegram\bot.py", line 2748, in get_updates
    result = self._post(
  File "C:\Users\user\PycharmProjects\pythonProject1\lib\site-packages\telegram\bot.py", line 258, in _post
    return self.request.post(
  File "C:\Users\user\PycharmProjects\pythonProject1\lib\site-packages\telegram\utils\request.py", line 349, in post
    result = self._request_wrapper(
  File "C:\Users\user\PycharmProjects\pythonProject1\lib\site-packages\telegram\utils\request.py", line 276, in _request_wrapper
    raise Conflict(message)
telegram.error.Conflict: Conflict: terminated by other getUpdates request; make sure that only one bot instance is running
2021-03-01 00:48:07,879 - ERROR - Error while getting Updates: Conflict: terminated by other getUpdates request; make sure that only one bot instance is running
2021-03-01 00:48:07,880 - ERROR - No error handlers are registered, logging exception.
Traceback (most recent call last):
  File "C:\Users\user\PycharmProjects\pythonProject\venv\lib\site-packages\telegram\ext\updater.py", line 465, in _network_loop_retry
    if not action_cb():
  File "C:\Users\user\PycharmProjects\pythonProject\venv\lib\site-packages\telegram\ext\updater.py", line 416, in polling_action_cb
    updates = self.bot.get_updates(
  File "<decorator-gen-31>", line 2, in get_updates
  File "C:\Users\user\PycharmProjects\pythonProject\venv\lib\site-packages\telegram\bot.py", line 135, in decorator
    result = func(*args, **kwargs)
  File "C:\Users\user\PycharmProjects\pythonProject\venv\lib\site-packages\telegram\bot.py", line 2638, in get_updates
    result = self._post(
  File "C:\Users\user\PycharmProjects\pythonProject\venv\lib\site-packages\telegram\bot.py", line 245, in _post
    return self.request.post(f'{self.base_url}/{endpoint}', data=data, timeout=timeout)
  File "C:\Users\user\PycharmProjects\pythonProject\venv\lib\site-packages\telegram\utils\request.py", line 349, in post
    result = self._request_wrapper(
  File "C:\Users\user\PycharmProjects\pythonProject\venv\lib\site-packages\telegram\utils\request.py", line 276, in _request_wrapper
    raise Conflict(message)
telegram.error.Conflict: Conflict: terminated by other getUpdates request; make sure that only one bot instance is running
2021-03-01 00:48:09,102 - ERROR - Error while getting Updates: Conflict: terminated by other getUpdates request; make sure that only one bot instance is running
2021-03-01 00:48:09,102 - ERROR - No error handlers are registered, logging exception.
Traceback (most recent call last):
  File "C:\Users\user\PycharmProjects\pythonProject1\lib\site-packages\telegram\ext\updater.py", line 465, in _network_loop_retry
    if not action_cb():
  File "C:\Users\user\PycharmProjects\pythonProject1\lib\site-packages\telegram\ext\updater.py", line 416, in polling_action_cb
    updates = self.bot.get_updates(
  File "C:\Users\user\PycharmProjects\pythonProject1\lib\site-packages\telegram\bot.py", line 126, in decorator
    result = func(*args, **kwargs)
  File "C:\Users\user\PycharmProjects\pythonProject1\lib\site-packages\telegram\bot.py", line 2748, in get_updates
    result = self._post(
  File "C:\Users\user\PycharmProjects\pythonProject1\lib\site-packages\telegram\bot.py", line 258, in _post
    return self.request.post(
  File "C:\Users\user\PycharmProjects\pythonProject1\lib\site-packages\telegram\utils\request.py", line 349, in post
    result = self._request_wrapper(
  File "C:\Users\user\PycharmProjects\pythonProject1\lib\site-packages\telegram\utils\request.py", line 276, in _request_wrapper
    raise Conflict(message)
telegram.error.Conflict: Conflict: terminated by other getUpdates request; make sure that only one bot instance is running
2021-03-01 00:48:14,140 - ERROR - Error while getting Updates: Conflict: terminated by other getUpdates request; make sure that only one bot instance is running
2021-03-01 00:48:14,141 - ERROR - No error handlers are registered, logging exception.
Traceback (most recent call last):
  File "C:\Users\user\PycharmProjects\pythonProject\venv\lib\site-packages\telegram\ext\updater.py", line 465, in _network_loop_retry
    if not action_cb():
  File "C:\Users\user\PycharmProjects\pythonProject\venv\lib\site-packages\telegram\ext\updater.py", line 416, in polling_action_cb
    updates = self.bot.get_updates(
  File "<decorator-gen-31>", line 2, in get_updates
  File "C:\Users\user\PycharmProjects\pythonProject\venv\lib\site-packages\telegram\bot.py", line 135, in decorator
    result = func(*args, **kwargs)
  File "C:\Users\user\PycharmProjects\pythonProject\venv\lib\site-packages\telegram\bot.py", line 2638, in get_updates
    result = self._post(
  File "C:\Users\user\PycharmProjects\pythonProject\venv\lib\site-packages\telegram\bot.py", line 245, in _post
    return self.request.post(f'{self.base_url}/{endpoint}', data=data, timeout=timeout)
  File "C:\Users\user\PycharmProjects\pythonProject\venv\lib\site-packages\telegram\utils\request.py", line 349, in post
    result = self._request_wrapper(
  File "C:\Users\user\PycharmProjects\pythonProject\venv\lib\site-packages\telegram\utils\request.py", line 276, in _request_wrapper
    raise Conflict(message)
telegram.error.Conflict: Conflict: terminated by other getUpdates request; make sure that only one bot instance is running
2021-03-01 00:48:15,575 - ERROR - Error while getting Updates: Conflict: terminated by other getUpdates request; make sure that only one bot instance is running
2021-03-01 00:48:15,576 - ERROR - No error handlers are registered, logging exception.
Traceback (most recent call last):
  File "C:\Users\user\PycharmProjects\pythonProject1\lib\site-packages\telegram\ext\updater.py", line 465, in _network_loop_retry
    if not action_cb():
  File "C:\Users\user\PycharmProjects\pythonProject1\lib\site-packages\telegram\ext\updater.py", line 416, in polling_action_cb
    updates = self.bot.get_updates(
  File "C:\Users\user\PycharmProjects\pythonProject1\lib\site-packages\telegram\bot.py", line 126, in decorator
    result = func(*args, **kwargs)
  File "C:\Users\user\PycharmProjects\pythonProject1\lib\site-packages\telegram\bot.py", line 2748, in get_updates
    result = self._post(
  File "C:\Users\user\PycharmProjects\pythonProject1\lib\site-packages\telegram\bot.py", line 258, in _post
    return self.request.post(
  File "C:\Users\user\PycharmProjects\pythonProject1\lib\site-packages\telegram\utils\request.py", line 349, in post
    result = self._request_wrapper(
  File "C:\Users\user\PycharmProjects\pythonProject1\lib\site-packages\telegram\utils\request.py", line 276, in _request_wrapper
    raise Conflict(message)
telegram.error.Conflict: Conflict: terminated by other getUpdates request; make sure that only one bot instance is running
2021-03-01 00:48:19,869 - ERROR - Error while getting Updates: Conflict: terminated by other getUpdates request; make sure that only one bot instance is running
2021-03-01 00:48:19,871 - ERROR - No error handlers are registered, logging exception.
Traceback (most recent call last):
  File "C:\Users\user\PycharmProjects\pythonProject\venv\lib\site-packages\telegram\ext\updater.py", line 465, in _network_loop_retry
    if not action_cb():
  File "C:\Users\user\PycharmProjects\pythonProject\venv\lib\site-packages\telegram\ext\updater.py", line 416, in polling_action_cb
    updates = self.bot.get_updates(
  File "<decorator-gen-31>", line 2, in get_updates
  File "C:\Users\user\PycharmProjects\pythonProject\venv\lib\site-packages\telegram\bot.py", line 135, in decorator
    result = func(*args, **kwargs)
  File "C:\Users\user\PycharmProjects\pythonProject\venv\lib\site-packages\telegram\bot.py", line 2638, in get_updates
    result = self._post(
  File "C:\Users\user\PycharmProjects\pythonProject\venv\lib\site-packages\telegram\bot.py", line 245, in _post
    return self.request.post(f'{self.base_url}/{endpoint}', data=data, timeout=timeout)
  File "C:\Users\user\PycharmProjects\pythonProject\venv\lib\site-packages\telegram\utils\request.py", line 349, in post
    result = self._request_wrapper(
  File "C:\Users\user\PycharmProjects\pythonProject\venv\lib\site-packages\telegram\utils\request.py", line 276, in _request_wrapper
    raise Conflict(message)
telegram.error.Conflict: Conflict: terminated by other getUpdates request; make sure that only one bot instance is running
2021-03-01 00:48:21,585 - ERROR - Error while getting Updates: Conflict: terminated by other getUpdates request; make sure that only one bot instance is running
2021-03-01 00:48:21,586 - ERROR - No error handlers are registered, logging exception.
Traceback (most recent call last):
  File "C:\Users\user\PycharmProjects\pythonProject1\lib\site-packages\telegram\ext\updater.py", line 465, in _network_loop_retry
    if not action_cb():
  File "C:\Users\user\PycharmProjects\pythonProject1\lib\site-packages\telegram\ext\updater.py", line 416, in polling_action_cb
    updates = self.bot.get_updates(
  File "C:\Users\user\PycharmProjects\pythonProject1\lib\site-packages\telegram\bot.py", line 126, in decorator
    result = func(*args, **kwargs)
  File "C:\Users\user\PycharmProjects\pythonProject1\lib\site-packages\telegram\bot.py", line 2748, in get_updates
    result = self._post(
  File "C:\Users\user\PycharmProjects\pythonProject1\lib\site-packages\telegram\bot.py", line 258, in _post
    return self.request.post(
  File "C:\Users\user\PycharmProjects\pythonProject1\lib\site-packages\telegram\utils\request.py", line 349, in post
    result = self._request_wrapper(
  File "C:\Users\user\PycharmProjects\pythonProject1\lib\site-packages\telegram\utils\request.py", line 276, in _request_wrapper
    raise Conflict(message)
telegram.error.Conflict: Conflict: terminated by other getUpdates request; make sure that only one bot instance is running
2021-03-01 00:48:26,321 - ERROR - Error while getting Updates: Conflict: terminated by other getUpdates request; make sure that only one bot instance is running
2021-03-01 00:48:26,322 - ERROR - No error handlers are registered, logging exception.
Traceback (most recent call last):
  File "C:\Users\user\PycharmProjects\pythonProject\venv\lib\site-packages\telegram\ext\updater.py", line 465, in _network_loop_retry
    if not action_cb():
  File "C:\Users\user\PycharmProjects\pythonProject\venv\lib\site-packages\telegram\ext\updater.py", line 416, in polling_action_cb
    updates = self.bot.get_updates(
  File "<decorator-gen-31>", line 2, in get_updates
  File "C:\Users\user\PycharmProjects\pythonProject\venv\lib\site-packages\telegram\bot.py", line 135, in decorator
    result = func(*args, **kwargs)
  File "C:\Users\user\PycharmProjects\pythonProject\venv\lib\site-packages\telegram\bot.py", line 2638, in get_updates
    result = self._post(
  File "C:\Users\user\PycharmProjects\pythonProject\venv\lib\site-packages\telegram\bot.py", line 245, in _post
    return self.request.post(f'{self.base_url}/{endpoint}', data=data, timeout=timeout)
  File "C:\Users\user\PycharmProjects\pythonProject\venv\lib\site-packages\telegram\utils\request.py", line 349, in post
    result = self._request_wrapper(
  File "C:\Users\user\PycharmProjects\pythonProject\venv\lib\site-packages\telegram\utils\request.py", line 276, in _request_wrapper
    raise Conflict(message)
telegram.error.Conflict: Conflict: terminated by other getUpdates request; make sure that only one bot instance is running
2021-03-01 00:48:28,873 - ERROR - Error while getting Updates: Conflict: terminated by other getUpdates request; make sure that only one bot instance is running
2021-03-01 00:48:28,874 - ERROR - No error handlers are registered, logging exception.
Traceback (most recent call last):
  File "C:\Users\user\PycharmProjects\pythonProject1\lib\site-packages\telegram\ext\updater.py", line 465, in _network_loop_retry
    if not action_cb():
  File "C:\Users\user\PycharmProjects\pythonProject1\lib\site-packages\telegram\ext\updater.py", line 416, in polling_action_cb
    updates = self.bot.get_updates(
  File "C:\Users\user\PycharmProjects\pythonProject1\lib\site-packages\telegram\bot.py", line 126, in decorator
    result = func(*args, **kwargs)
  File "C:\Users\user\PycharmProjects\pythonProject1\lib\site-packages\telegram\bot.py", line 2748, in get_updates
    result = self._post(
  File "C:\Users\user\PycharmProjects\pythonProject1\lib\site-packages\telegram\bot.py", line 258, in _post
    return self.request.post(
  File "C:\Users\user\PycharmProjects\pythonProject1\lib\site-packages\telegram\utils\request.py", line 349, in post
    result = self._request_wrapper(
  File "C:\Users\user\PycharmProjects\pythonProject1\lib\site-packages\telegram\utils\request.py", line 276, in _request_wrapper
    raise Conflict(message)
telegram.error.Conflict: Conflict: terminated by other getUpdates request; make sure that only one bot instance is running
2021-03-01 00:48:33,219 - ERROR - Error while getting Updates: Conflict: terminated by other getUpdates request; make sure that only one bot instance is running
2021-03-01 00:48:33,220 - ERROR - No error handlers are registered, logging exception.
Traceback (most recent call last):
  File "C:\Users\user\PycharmProjects\pythonProject\venv\lib\site-packages\telegram\ext\updater.py", line 465, in _network_loop_retry
    if not action_cb():
  File "C:\Users\user\PycharmProjects\pythonProject\venv\lib\site-packages\telegram\ext\updater.py", line 416, in polling_action_cb
    updates = self.bot.get_updates(
  File "<decorator-gen-31>", line 2, in get_updates
  File "C:\Users\user\PycharmProjects\pythonProject\venv\lib\site-packages\telegram\bot.py", line 135, in decorator
    result = func(*args, **kwargs)
  File "C:\Users\user\PycharmProjects\pythonProject\venv\lib\site-packages\telegram\bot.py", line 2638, in get_updates
    result = self._post(
  File "C:\Users\user\PycharmProjects\pythonProject\venv\lib\site-packages\telegram\bot.py", line 245, in _post
    return self.request.post(f'{self.base_url}/{endpoint}', data=data, timeout=timeout)
  File "C:\Users\user\PycharmProjects\pythonProject\venv\lib\site-packages\telegram\utils\request.py", line 349, in post
    result = self._request_wrapper(
  File "C:\Users\user\PycharmProjects\pythonProject\venv\lib\site-packages\telegram\utils\request.py", line 276, in _request_wrapper
    raise Conflict(message)
telegram.error.Conflict: Conflict: terminated by other getUpdates request; make sure that only one bot instance is running
2021-03-01 00:48:36,878 - ERROR - Error while getting Updates: Conflict: terminated by other getUpdates request; make sure that only one bot instance is running
2021-03-01 00:48:36,879 - ERROR - No error handlers are registered, logging exception.
Traceback (most recent call last):
  File "C:\Users\user\PycharmProjects\pythonProject1\lib\site-packages\telegram\ext\updater.py", line 465, in _network_loop_retry
    if not action_cb():
  File "C:\Users\user\PycharmProjects\pythonProject1\lib\site-packages\telegram\ext\updater.py", line 416, in polling_action_cb
    updates = self.bot.get_updates(
  File "C:\Users\user\PycharmProjects\pythonProject1\lib\site-packages\telegram\bot.py", line 126, in decorator
    result = func(*args, **kwargs)
  File "C:\Users\user\PycharmProjects\pythonProject1\lib\site-packages\telegram\bot.py", line 2748, in get_updates
    result = self._post(
  File "C:\Users\user\PycharmProjects\pythonProject1\lib\site-packages\telegram\bot.py", line 258, in _post
    return self.request.post(
  File "C:\Users\user\PycharmProjects\pythonProject1\lib\site-packages\telegram\utils\request.py", line 349, in post
    result = self._request_wrapper(
  File "C:\Users\user\PycharmProjects\pythonProject1\lib\site-packages\telegram\utils\request.py", line 276, in _request_wrapper
    raise Conflict(message)
telegram.error.Conflict: Conflict: terminated by other getUpdates request; make sure that only one bot instance is running
2021-03-01 00:48:41,171 - ERROR - Error while getting Updates: Conflict: terminated by other getUpdates request; make sure that only one bot instance is running
2021-03-01 00:48:41,172 - ERROR - No error handlers are registered, logging exception.
Traceback (most recent call last):
  File "C:\Users\user\PycharmProjects\pythonProject\venv\lib\site-packages\telegram\ext\updater.py", line 465, in _network_loop_retry
    if not action_cb():
  File "C:\Users\user\PycharmProjects\pythonProject\venv\lib\site-packages\telegram\ext\updater.py", line 416, in polling_action_cb
    updates = self.bot.get_updates(
  File "<decorator-gen-31>", line 2, in get_updates
  File "C:\Users\user\PycharmProjects\pythonProject\venv\lib\site-packages\telegram\bot.py", line 135, in decorator
    result = func(*args, **kwargs)
  File "C:\Users\user\PycharmProjects\pythonProject\venv\lib\site-packages\telegram\bot.py", line 2638, in get_updates
    result = self._post(
  File "C:\Users\user\PycharmProjects\pythonProject\venv\lib\site-packages\telegram\bot.py", line 245, in _post
    return self.request.post(f'{self.base_url}/{endpoint}', data=data, timeout=timeout)
  File "C:\Users\user\PycharmProjects\pythonProject\venv\lib\site-packages\telegram\utils\request.py", line 349, in post
    result = self._request_wrapper(
  File "C:\Users\user\PycharmProjects\pythonProject\venv\lib\site-packages\telegram\utils\request.py", line 276, in _request_wrapper
    raise Conflict(message)
telegram.error.Conflict: Conflict: terminated by other getUpdates request; make sure that only one bot instance is running
2021-03-01 00:48:46,489 - ERROR - Error while getting Updates: Conflict: terminated by other getUpdates request; make sure that only one bot instance is running
2021-03-01 00:48:46,489 - ERROR - No error handlers are registered, logging exception.
Traceback (most recent call last):
  File "C:\Users\user\PycharmProjects\pythonProject1\lib\site-packages\telegram\ext\updater.py", line 465, in _network_loop_retry
    if not action_cb():
  File "C:\Users\user\PycharmProjects\pythonProject1\lib\site-packages\telegram\ext\updater.py", line 416, in polling_action_cb
    updates = self.bot.get_updates(
  File "C:\Users\user\PycharmProjects\pythonProject1\lib\site-packages\telegram\bot.py", line 126, in decorator
    result = func(*args, **kwargs)
  File "C:\Users\user\PycharmProjects\pythonProject1\lib\site-packages\telegram\bot.py", line 2748, in get_updates
    result = self._post(
  File "C:\Users\user\PycharmProjects\pythonProject1\lib\site-packages\telegram\bot.py", line 258, in _post
    return self.request.post(
  File "C:\Users\user\PycharmProjects\pythonProject1\lib\site-packages\telegram\utils\request.py", line 349, in post
    result = self._request_wrapper(
  File "C:\Users\user\PycharmProjects\pythonProject1\lib\site-packages\telegram\utils\request.py", line 276, in _request_wrapper
    raise Conflict(message)
telegram.error.Conflict: Conflict: terminated by other getUpdates request; make sure that only one bot instance is running
2021-03-01 00:48:51,180 - ERROR - Error while getting Updates: Conflict: terminated by other getUpdates request; make sure that only one bot instance is running
2021-03-01 00:48:51,180 - ERROR - No error handlers are registered, logging exception.
Traceback (most recent call last):
  File "C:\Users\user\PycharmProjects\pythonProject\venv\lib\site-packages\telegram\ext\updater.py", line 465, in _network_loop_retry
    if not action_cb():
  File "C:\Users\user\PycharmProjects\pythonProject\venv\lib\site-packages\telegram\ext\updater.py", line 416, in polling_action_cb
    updates = self.bot.get_updates(
  File "<decorator-gen-31>", line 2, in get_updates
  File "C:\Users\user\PycharmProjects\pythonProject\venv\lib\site-packages\telegram\bot.py", line 135, in decorator
    result = func(*args, **kwargs)
  File "C:\Users\user\PycharmProjects\pythonProject\venv\lib\site-packages\telegram\bot.py", line 2638, in get_updates
    result = self._post(
  File "C:\Users\user\PycharmProjects\pythonProject\venv\lib\site-packages\telegram\bot.py", line 245, in _post
    return self.request.post(f'{self.base_url}/{endpoint}', data=data, timeout=timeout)
  File "C:\Users\user\PycharmProjects\pythonProject\venv\lib\site-packages\telegram\utils\request.py", line 349, in post
    result = self._request_wrapper(
  File "C:\Users\user\PycharmProjects\pythonProject\venv\lib\site-packages\telegram\utils\request.py", line 276, in _request_wrapper
    raise Conflict(message)
telegram.error.Conflict: Conflict: terminated by other getUpdates request; make sure that only one bot instance is running
2021-03-01 00:48:59,091 - ERROR - Error while getting Updates: Conflict: terminated by other getUpdates request; make sure that only one bot instance is running
2021-03-01 00:48:59,092 - ERROR - No error handlers are registered, logging exception.
Traceback (most recent call last):
  File "C:\Users\user\PycharmProjects\pythonProject1\lib\site-packages\telegram\ext\updater.py", line 465, in _network_loop_retry
    if not action_cb():
  File "C:\Users\user\PycharmProjects\pythonProject1\lib\site-packages\telegram\ext\updater.py", line 416, in polling_action_cb
    updates = self.bot.get_updates(
  File "C:\Users\user\PycharmProjects\pythonProject1\lib\site-packages\telegram\bot.py", line 126, in decorator
    result = func(*args, **kwargs)
  File "C:\Users\user\PycharmProjects\pythonProject1\lib\site-packages\telegram\bot.py", line 2748, in get_updates
    result = self._post(
  File "C:\Users\user\PycharmProjects\pythonProject1\lib\site-packages\telegram\bot.py", line 258, in _post
    return self.request.post(
  File "C:\Users\user\PycharmProjects\pythonProject1\lib\site-packages\telegram\utils\request.py", line 349, in post
    result = self._request_wrapper(
  File "C:\Users\user\PycharmProjects\pythonProject1\lib\site-packages\telegram\utils\request.py", line 276, in _request_wrapper
    raise Conflict(message)
telegram.error.Conflict: Conflict: terminated by other getUpdates request; make sure that only one bot instance is running
2021-03-01 00:49:03,400 - ERROR - Error while getting Updates: Conflict: terminated by other getUpdates request; make sure that only one bot instance is running
2021-03-01 00:49:03,401 - ERROR - No error handlers are registered, logging exception.
Traceback (most recent call last):
  File "C:\Users\user\PycharmProjects\pythonProject\venv\lib\site-packages\telegram\ext\updater.py", line 465, in _network_loop_retry
    if not action_cb():
  File "C:\Users\user\PycharmProjects\pythonProject\venv\lib\site-packages\telegram\ext\updater.py", line 416, in polling_action_cb
    updates = self.bot.get_updates(
  File "<decorator-gen-31>", line 2, in get_updates
  File "C:\Users\user\PycharmProjects\pythonProject\venv\lib\site-packages\telegram\bot.py", line 135, in decorator
    result = func(*args, **kwargs)
  File "C:\Users\user\PycharmProjects\pythonProject\venv\lib\site-packages\telegram\bot.py", line 2638, in get_updates
    result = self._post(
  File "C:\Users\user\PycharmProjects\pythonProject\venv\lib\site-packages\telegram\bot.py", line 245, in _post
    return self.request.post(f'{self.base_url}/{endpoint}', data=data, timeout=timeout)
  File "C:\Users\user\PycharmProjects\pythonProject\venv\lib\site-packages\telegram\utils\request.py", line 349, in post
    result = self._request_wrapper(
  File "C:\Users\user\PycharmProjects\pythonProject\venv\lib\site-packages\telegram\utils\request.py", line 276, in _request_wrapper
    raise Conflict(message)
telegram.error.Conflict: Conflict: terminated by other getUpdates request; make sure that only one bot instance is running
2021-03-01 00:49:14,673 - INFO - Scheduler started
2021-03-01 00:49:15,782 - ERROR - Error while getting Updates: Conflict: terminated by other getUpdates request; make sure that only one bot instance is running
2021-03-01 00:49:15,783 - ERROR - No error handlers are registered, logging exception.
Traceback (most recent call last):
  File "C:\Users\user\PycharmProjects\pythonProject1\lib\site-packages\telegram\ext\updater.py", line 465, in _network_loop_retry
    if not action_cb():
  File "C:\Users\user\PycharmProjects\pythonProject1\lib\site-packages\telegram\ext\updater.py", line 416, in polling_action_cb
    updates = self.bot.get_updates(
  File "C:\Users\user\PycharmProjects\pythonProject1\lib\site-packages\telegram\bot.py", line 126, in decorator
    result = func(*args, **kwargs)
  File "C:\Users\user\PycharmProjects\pythonProject1\lib\site-packages\telegram\bot.py", line 2748, in get_updates
    result = self._post(
  File "C:\Users\user\PycharmProjects\pythonProject1\lib\site-packages\telegram\bot.py", line 258, in _post
    return self.request.post(
  File "C:\Users\user\PycharmProjects\pythonProject1\lib\site-packages\telegram\utils\request.py", line 349, in post
    result = self._request_wrapper(
  File "C:\Users\user\PycharmProjects\pythonProject1\lib\site-packages\telegram\utils\request.py", line 276, in _request_wrapper
    raise Conflict(message)
telegram.error.Conflict: Conflict: terminated by other getUpdates request; make sure that only one bot instance is running
2021-03-01 00:49:19,084 - ERROR - ERROR:  duplicate key value violates unique constraint "chat_id"
DETAIL:  Key (chat_id)=(350402934) already exists.
Traceback (most recent call last):
  File "C:\Users\user\PycharmProjects\InvestBot\DB\Queries\dbConnection.py", line 31, in query
    records = update_db(conn,sql)
  File "C:\Users\user\PycharmProjects\InvestBot\DB\Queries\dbConnection.py", line 21, in update_db
    cursor.execute(sql)
psycopg2.errors.UniqueViolation: duplicate key value violates unique constraint "chat_id"
DETAIL:  Key (chat_id)=(350402934) already exists.

2021-03-01 00:49:19,085 - ERROR - No error handlers are registered, logging exception.
Traceback (most recent call last):
  File "C:\Users\user\PycharmProjects\pythonProject1\lib\site-packages\telegram\ext\dispatcher.py", line 442, in process_update
    handler.handle_update(update, self, check, context)
  File "C:\Users\user\PycharmProjects\pythonProject1\lib\site-packages\telegram\ext\handler.py", line 160, in handle_update
    return self.callback(update, context)
  File "C:\Users\user\PycharmProjects\InvestBot\Handlers\CommandHandlers\BaseCommandHandler.py", line 37, in startCommand
    print(bot)
OSError: [Errno 22] Invalid argument
2021-03-01 00:49:20,081 - ERROR - Error while getting Updates: Conflict: terminated by other getUpdates request; make sure that only one bot instance is running
2021-03-01 00:49:20,081 - ERROR - No error handlers are registered, logging exception.
Traceback (most recent call last):
  File "C:\Users\user\PycharmProjects\pythonProject\venv\lib\site-packages\telegram\ext\updater.py", line 465, in _network_loop_retry
    if not action_cb():
  File "C:\Users\user\PycharmProjects\pythonProject\venv\lib\site-packages\telegram\ext\updater.py", line 416, in polling_action_cb
    updates = self.bot.get_updates(
  File "<decorator-gen-31>", line 2, in get_updates
  File "C:\Users\user\PycharmProjects\pythonProject\venv\lib\site-packages\telegram\bot.py", line 135, in decorator
    result = func(*args, **kwargs)
  File "C:\Users\user\PycharmProjects\pythonProject\venv\lib\site-packages\telegram\bot.py", line 2638, in get_updates
    result = self._post(
  File "C:\Users\user\PycharmProjects\pythonProject\venv\lib\site-packages\telegram\bot.py", line 245, in _post
    return self.request.post(f'{self.base_url}/{endpoint}', data=data, timeout=timeout)
  File "C:\Users\user\PycharmProjects\pythonProject\venv\lib\site-packages\telegram\utils\request.py", line 349, in post
    result = self._request_wrapper(
  File "C:\Users\user\PycharmProjects\pythonProject\venv\lib\site-packages\telegram\utils\request.py", line 276, in _request_wrapper
    raise Conflict(message)
telegram.error.Conflict: Conflict: terminated by other getUpdates request; make sure that only one bot instance is running
2021-03-01 00:49:21,100 - ERROR - ERROR:  duplicate key value violates unique constraint "chat_id"
DETAIL:  Key (chat_id)=(350402934) already exists.
Traceback (most recent call last):
  File "C:\Users\user\PycharmProjects\InvestBot\DB\Queries\dbConnection.py", line 31, in query
    records = update_db(conn,sql)
  File "C:\Users\user\PycharmProjects\InvestBot\DB\Queries\dbConnection.py", line 21, in update_db
    cursor.execute(sql)
psycopg2.errors.UniqueViolation: duplicate key value violates unique constraint "chat_id"
DETAIL:  Key (chat_id)=(350402934) already exists.

2021-03-01 00:49:21,102 - ERROR - No error handlers are registered, logging exception.
Traceback (most recent call last):
  File "C:\Users\user\PycharmProjects\pythonProject1\lib\site-packages\telegram\ext\dispatcher.py", line 442, in process_update
    handler.handle_update(update, self, check, context)
  File "C:\Users\user\PycharmProjects\pythonProject1\lib\site-packages\telegram\ext\handler.py", line 160, in handle_update
    return self.callback(update, context)
  File "C:\Users\user\PycharmProjects\InvestBot\Handlers\CommandHandlers\BaseCommandHandler.py", line 37, in startCommand
    print(bot)
OSError: [Errno 22] Invalid argument
2021-03-01 00:49:21,306 - ERROR - Error while getting Updates: Conflict: terminated by other getUpdates request; make sure that only one bot instance is running
2021-03-01 00:49:21,306 - ERROR - No error handlers are registered, logging exception.
Traceback (most recent call last):
  File "C:\Users\user\PycharmProjects\pythonProject1\lib\site-packages\telegram\ext\updater.py", line 465, in _network_loop_retry
    if not action_cb():
  File "C:\Users\user\PycharmProjects\pythonProject1\lib\site-packages\telegram\ext\updater.py", line 416, in polling_action_cb
    updates = self.bot.get_updates(
  File "C:\Users\user\PycharmProjects\pythonProject1\lib\site-packages\telegram\bot.py", line 126, in decorator
    result = func(*args, **kwargs)
  File "C:\Users\user\PycharmProjects\pythonProject1\lib\site-packages\telegram\bot.py", line 2748, in get_updates
    result = self._post(
  File "C:\Users\user\PycharmProjects\pythonProject1\lib\site-packages\telegram\bot.py", line 258, in _post
    return self.request.post(
  File "C:\Users\user\PycharmProjects\pythonProject1\lib\site-packages\telegram\utils\request.py", line 349, in post
    result = self._request_wrapper(
  File "C:\Users\user\PycharmProjects\pythonProject1\lib\site-packages\telegram\utils\request.py", line 276, in _request_wrapper
    raise Conflict(message)
telegram.error.Conflict: Conflict: terminated by other getUpdates request; make sure that only one bot instance is running
2021-03-01 00:49:27,310 - INFO - Scheduler started
2021-03-01 00:49:27,716 - ERROR - ERROR:  duplicate key value violates unique constraint "chat_id"
DETAIL:  Key (chat_id)=(350402934) already exists.
Traceback (most recent call last):
  File "C:\Users\user\PycharmProjects\InvestBot\DB\Queries\dbConnection.py", line 31, in query
    records = update_db(conn,sql)
  File "C:\Users\user\PycharmProjects\InvestBot\DB\Queries\dbConnection.py", line 21, in update_db
    cursor.execute(sql)
psycopg2.errors.UniqueViolation: duplicate key value violates unique constraint "chat_id"
DETAIL:  Key (chat_id)=(350402934) already exists.

2021-03-01 00:49:27,718 - ERROR - No error handlers are registered, logging exception.
Traceback (most recent call last):
  File "C:\Users\user\PycharmProjects\pythonProject1\lib\site-packages\telegram\ext\dispatcher.py", line 442, in process_update
    handler.handle_update(update, self, check, context)
  File "C:\Users\user\PycharmProjects\pythonProject1\lib\site-packages\telegram\ext\handler.py", line 160, in handle_update
    return self.callback(update, context)
  File "C:\Users\user\PycharmProjects\InvestBot\Handlers\CommandHandlers\BaseCommandHandler.py", line 37, in startCommand
    print(bot)
OSError: [Errno 22] Invalid argument
2021-03-01 00:49:28,478 - ERROR - Error while getting Updates: Conflict: terminated by other getUpdates request; make sure that only one bot instance is running
2021-03-01 00:49:28,479 - ERROR - No error handlers are registered, logging exception.
Traceback (most recent call last):
  File "C:\Users\user\PycharmProjects\pythonProject1\lib\site-packages\telegram\ext\updater.py", line 465, in _network_loop_retry
    if not action_cb():
  File "C:\Users\user\PycharmProjects\pythonProject1\lib\site-packages\telegram\ext\updater.py", line 416, in polling_action_cb
    updates = self.bot.get_updates(
  File "C:\Users\user\PycharmProjects\pythonProject1\lib\site-packages\telegram\bot.py", line 126, in decorator
    result = func(*args, **kwargs)
  File "C:\Users\user\PycharmProjects\pythonProject1\lib\site-packages\telegram\bot.py", line 2748, in get_updates
    result = self._post(
  File "C:\Users\user\PycharmProjects\pythonProject1\lib\site-packages\telegram\bot.py", line 258, in _post
    return self.request.post(
  File "C:\Users\user\PycharmProjects\pythonProject1\lib\site-packages\telegram\utils\request.py", line 349, in post
    result = self._request_wrapper(
  File "C:\Users\user\PycharmProjects\pythonProject1\lib\site-packages\telegram\utils\request.py", line 276, in _request_wrapper
    raise Conflict(message)
telegram.error.Conflict: Conflict: terminated by other getUpdates request; make sure that only one bot instance is running
2021-03-01 00:49:32,784 - ERROR - Error while getting Updates: Conflict: terminated by other getUpdates request; make sure that only one bot instance is running
2021-03-01 00:49:32,785 - ERROR - No error handlers are registered, logging exception.
Traceback (most recent call last):
  File "C:\Users\user\PycharmProjects\pythonProject\venv\lib\site-packages\telegram\ext\updater.py", line 465, in _network_loop_retry
    if not action_cb():
  File "C:\Users\user\PycharmProjects\pythonProject\venv\lib\site-packages\telegram\ext\updater.py", line 416, in polling_action_cb
    updates = self.bot.get_updates(
  File "<decorator-gen-31>", line 2, in get_updates
  File "C:\Users\user\PycharmProjects\pythonProject\venv\lib\site-packages\telegram\bot.py", line 135, in decorator
    result = func(*args, **kwargs)
  File "C:\Users\user\PycharmProjects\pythonProject\venv\lib\site-packages\telegram\bot.py", line 2638, in get_updates
    result = self._post(
  File "C:\Users\user\PycharmProjects\pythonProject\venv\lib\site-packages\telegram\bot.py", line 245, in _post
    return self.request.post(f'{self.base_url}/{endpoint}', data=data, timeout=timeout)
  File "C:\Users\user\PycharmProjects\pythonProject\venv\lib\site-packages\telegram\utils\request.py", line 349, in post
    result = self._request_wrapper(
  File "C:\Users\user\PycharmProjects\pythonProject\venv\lib\site-packages\telegram\utils\request.py", line 276, in _request_wrapper
    raise Conflict(message)
telegram.error.Conflict: Conflict: terminated by other getUpdates request; make sure that only one bot instance is running
2021-03-01 00:49:34,106 - ERROR - Error while getting Updates: Conflict: terminated by other getUpdates request; make sure that only one bot instance is running
2021-03-01 00:49:34,107 - ERROR - No error handlers are registered, logging exception.
Traceback (most recent call last):
  File "C:\Users\user\PycharmProjects\pythonProject1\lib\site-packages\telegram\ext\updater.py", line 465, in _network_loop_retry
    if not action_cb():
  File "C:\Users\user\PycharmProjects\pythonProject1\lib\site-packages\telegram\ext\updater.py", line 416, in polling_action_cb
    updates = self.bot.get_updates(
  File "C:\Users\user\PycharmProjects\pythonProject1\lib\site-packages\telegram\bot.py", line 126, in decorator
    result = func(*args, **kwargs)
  File "C:\Users\user\PycharmProjects\pythonProject1\lib\site-packages\telegram\bot.py", line 2748, in get_updates
    result = self._post(
  File "C:\Users\user\PycharmProjects\pythonProject1\lib\site-packages\telegram\bot.py", line 258, in _post
    return self.request.post(
  File "C:\Users\user\PycharmProjects\pythonProject1\lib\site-packages\telegram\utils\request.py", line 349, in post
    result = self._request_wrapper(
  File "C:\Users\user\PycharmProjects\pythonProject1\lib\site-packages\telegram\utils\request.py", line 276, in _request_wrapper
    raise Conflict(message)
telegram.error.Conflict: Conflict: terminated by other getUpdates request; make sure that only one bot instance is running
2021-03-01 00:49:38,926 - ERROR - Error while getting Updates: Conflict: terminated by other getUpdates request; make sure that only one bot instance is running
2021-03-01 00:49:38,926 - ERROR - No error handlers are registered, logging exception.
Traceback (most recent call last):
  File "C:\Users\user\PycharmProjects\pythonProject\venv\lib\site-packages\telegram\ext\updater.py", line 465, in _network_loop_retry
    if not action_cb():
  File "C:\Users\user\PycharmProjects\pythonProject\venv\lib\site-packages\telegram\ext\updater.py", line 416, in polling_action_cb
    updates = self.bot.get_updates(
  File "<decorator-gen-31>", line 2, in get_updates
  File "C:\Users\user\PycharmProjects\pythonProject\venv\lib\site-packages\telegram\bot.py", line 135, in decorator
    result = func(*args, **kwargs)
  File "C:\Users\user\PycharmProjects\pythonProject\venv\lib\site-packages\telegram\bot.py", line 2638, in get_updates
    result = self._post(
  File "C:\Users\user\PycharmProjects\pythonProject\venv\lib\site-packages\telegram\bot.py", line 245, in _post
    return self.request.post(f'{self.base_url}/{endpoint}', data=data, timeout=timeout)
  File "C:\Users\user\PycharmProjects\pythonProject\venv\lib\site-packages\telegram\utils\request.py", line 349, in post
    result = self._request_wrapper(
  File "C:\Users\user\PycharmProjects\pythonProject\venv\lib\site-packages\telegram\utils\request.py", line 276, in _request_wrapper
    raise Conflict(message)
telegram.error.Conflict: Conflict: terminated by other getUpdates request; make sure that only one bot instance is running
2021-03-01 00:49:40,663 - ERROR - Error while getting Updates: Conflict: terminated by other getUpdates request; make sure that only one bot instance is running
2021-03-01 00:49:40,663 - ERROR - No error handlers are registered, logging exception.
Traceback (most recent call last):
  File "C:\Users\user\PycharmProjects\pythonProject1\lib\site-packages\telegram\ext\updater.py", line 465, in _network_loop_retry
    if not action_cb():
  File "C:\Users\user\PycharmProjects\pythonProject1\lib\site-packages\telegram\ext\updater.py", line 416, in polling_action_cb
    updates = self.bot.get_updates(
  File "C:\Users\user\PycharmProjects\pythonProject1\lib\site-packages\telegram\bot.py", line 126, in decorator
    result = func(*args, **kwargs)
  File "C:\Users\user\PycharmProjects\pythonProject1\lib\site-packages\telegram\bot.py", line 2748, in get_updates
    result = self._post(
  File "C:\Users\user\PycharmProjects\pythonProject1\lib\site-packages\telegram\bot.py", line 258, in _post
    return self.request.post(
  File "C:\Users\user\PycharmProjects\pythonProject1\lib\site-packages\telegram\utils\request.py", line 349, in post
    result = self._request_wrapper(
  File "C:\Users\user\PycharmProjects\pythonProject1\lib\site-packages\telegram\utils\request.py", line 276, in _request_wrapper
    raise Conflict(message)
telegram.error.Conflict: Conflict: terminated by other getUpdates request; make sure that only one bot instance is running
2021-03-01 00:49:46,193 - ERROR - Error while getting Updates: Conflict: terminated by other getUpdates request; make sure that only one bot instance is running
2021-03-01 00:49:46,194 - ERROR - No error handlers are registered, logging exception.
Traceback (most recent call last):
  File "C:\Users\user\PycharmProjects\pythonProject\venv\lib\site-packages\telegram\ext\updater.py", line 465, in _network_loop_retry
    if not action_cb():
  File "C:\Users\user\PycharmProjects\pythonProject\venv\lib\site-packages\telegram\ext\updater.py", line 416, in polling_action_cb
    updates = self.bot.get_updates(
  File "<decorator-gen-31>", line 2, in get_updates
  File "C:\Users\user\PycharmProjects\pythonProject\venv\lib\site-packages\telegram\bot.py", line 135, in decorator
    result = func(*args, **kwargs)
  File "C:\Users\user\PycharmProjects\pythonProject\venv\lib\site-packages\telegram\bot.py", line 2638, in get_updates
    result = self._post(
  File "C:\Users\user\PycharmProjects\pythonProject\venv\lib\site-packages\telegram\bot.py", line 245, in _post
    return self.request.post(f'{self.base_url}/{endpoint}', data=data, timeout=timeout)
  File "C:\Users\user\PycharmProjects\pythonProject\venv\lib\site-packages\telegram\utils\request.py", line 349, in post
    result = self._request_wrapper(
  File "C:\Users\user\PycharmProjects\pythonProject\venv\lib\site-packages\telegram\utils\request.py", line 276, in _request_wrapper
    raise Conflict(message)
telegram.error.Conflict: Conflict: terminated by other getUpdates request; make sure that only one bot instance is running
2021-03-01 00:49:46,274 - ERROR - ERROR:  duplicate key value violates unique constraint "chat_id"
DETAIL:  Key (chat_id)=(350402934) already exists.
Traceback (most recent call last):
  File "C:\Users\user\PycharmProjects\InvestBot\DB\Queries\dbConnection.py", line 31, in query
    records = update_db(conn,sql)
  File "C:\Users\user\PycharmProjects\InvestBot\DB\Queries\dbConnection.py", line 21, in update_db
    cursor.execute(sql)
psycopg2.errors.UniqueViolation: duplicate key value violates unique constraint "chat_id"
DETAIL:  Key (chat_id)=(350402934) already exists.

2021-03-01 00:49:46,276 - ERROR - No error handlers are registered, logging exception.
Traceback (most recent call last):
  File "C:\Users\user\PycharmProjects\pythonProject1\lib\site-packages\telegram\ext\dispatcher.py", line 442, in process_update
    handler.handle_update(update, self, check, context)
  File "C:\Users\user\PycharmProjects\pythonProject1\lib\site-packages\telegram\ext\handler.py", line 160, in handle_update
    return self.callback(update, context)
  File "C:\Users\user\PycharmProjects\InvestBot\Handlers\CommandHandlers\BaseCommandHandler.py", line 37, in startCommand
    print(bot)
OSError: [Errno 22] Invalid argument
2021-03-01 00:49:48,790 - ERROR - Error while getting Updates: Conflict: terminated by other getUpdates request; make sure that only one bot instance is running
2021-03-01 00:49:48,790 - ERROR - No error handlers are registered, logging exception.
Traceback (most recent call last):
  File "C:\Users\user\PycharmProjects\pythonProject1\lib\site-packages\telegram\ext\updater.py", line 465, in _network_loop_retry
    if not action_cb():
  File "C:\Users\user\PycharmProjects\pythonProject1\lib\site-packages\telegram\ext\updater.py", line 416, in polling_action_cb
    updates = self.bot.get_updates(
  File "C:\Users\user\PycharmProjects\pythonProject1\lib\site-packages\telegram\bot.py", line 126, in decorator
    result = func(*args, **kwargs)
  File "C:\Users\user\PycharmProjects\pythonProject1\lib\site-packages\telegram\bot.py", line 2748, in get_updates
    result = self._post(
  File "C:\Users\user\PycharmProjects\pythonProject1\lib\site-packages\telegram\bot.py", line 258, in _post
    return self.request.post(
  File "C:\Users\user\PycharmProjects\pythonProject1\lib\site-packages\telegram\utils\request.py", line 349, in post
    result = self._request_wrapper(
  File "C:\Users\user\PycharmProjects\pythonProject1\lib\site-packages\telegram\utils\request.py", line 276, in _request_wrapper
    raise Conflict(message)
telegram.error.Conflict: Conflict: terminated by other getUpdates request; make sure that only one bot instance is running
2021-03-01 00:49:53,052 - ERROR - Error while getting Updates: Conflict: terminated by other getUpdates request; make sure that only one bot instance is running
2021-03-01 00:49:53,052 - ERROR - No error handlers are registered, logging exception.
Traceback (most recent call last):
  File "C:\Users\user\PycharmProjects\pythonProject\venv\lib\site-packages\telegram\ext\updater.py", line 465, in _network_loop_retry
    if not action_cb():
  File "C:\Users\user\PycharmProjects\pythonProject\venv\lib\site-packages\telegram\ext\updater.py", line 416, in polling_action_cb
    updates = self.bot.get_updates(
  File "<decorator-gen-31>", line 2, in get_updates
  File "C:\Users\user\PycharmProjects\pythonProject\venv\lib\site-packages\telegram\bot.py", line 135, in decorator
    result = func(*args, **kwargs)
  File "C:\Users\user\PycharmProjects\pythonProject\venv\lib\site-packages\telegram\bot.py", line 2638, in get_updates
    result = self._post(
  File "C:\Users\user\PycharmProjects\pythonProject\venv\lib\site-packages\telegram\bot.py", line 245, in _post
    return self.request.post(f'{self.base_url}/{endpoint}', data=data, timeout=timeout)
  File "C:\Users\user\PycharmProjects\pythonProject\venv\lib\site-packages\telegram\utils\request.py", line 349, in post
    result = self._request_wrapper(
  File "C:\Users\user\PycharmProjects\pythonProject\venv\lib\site-packages\telegram\utils\request.py", line 276, in _request_wrapper
    raise Conflict(message)
telegram.error.Conflict: Conflict: terminated by other getUpdates request; make sure that only one bot instance is running
2021-03-01 00:49:55,641 - ERROR - No error handlers are registered, logging exception.
Traceback (most recent call last):
  File "C:\Users\user\PycharmProjects\pythonProject1\lib\site-packages\telegram\ext\dispatcher.py", line 442, in process_update
    handler.handle_update(update, self, check, context)
  File "C:\Users\user\PycharmProjects\pythonProject1\lib\site-packages\telegram\ext\conversationhandler.py", line 549, in handle_update
    new_state = handler.handle_update(update, dispatcher, check_result, context)
  File "C:\Users\user\PycharmProjects\pythonProject1\lib\site-packages\telegram\ext\handler.py", line 160, in handle_update
    return self.callback(update, context)
  File "C:\Users\user\PycharmProjects\InvestBot\Handlers\CallBackQueryHandlers\helpCallbackQueryHandler.py", line 15, in aboutCommands
    print(chatId)
OSError: [Errno 22] Invalid argument
2021-03-01 00:49:56,738 - ERROR - Error while getting Updates: Conflict: terminated by other getUpdates request; make sure that only one bot instance is running
2021-03-01 00:49:56,739 - ERROR - No error handlers are registered, logging exception.
Traceback (most recent call last):
  File "C:\Users\user\PycharmProjects\pythonProject1\lib\site-packages\telegram\ext\updater.py", line 465, in _network_loop_retry
    if not action_cb():
  File "C:\Users\user\PycharmProjects\pythonProject1\lib\site-packages\telegram\ext\updater.py", line 416, in polling_action_cb
    updates = self.bot.get_updates(
  File "C:\Users\user\PycharmProjects\pythonProject1\lib\site-packages\telegram\bot.py", line 126, in decorator
    result = func(*args, **kwargs)
  File "C:\Users\user\PycharmProjects\pythonProject1\lib\site-packages\telegram\bot.py", line 2748, in get_updates
    result = self._post(
  File "C:\Users\user\PycharmProjects\pythonProject1\lib\site-packages\telegram\bot.py", line 258, in _post
    return self.request.post(
  File "C:\Users\user\PycharmProjects\pythonProject1\lib\site-packages\telegram\utils\request.py", line 349, in post
    result = self._request_wrapper(
  File "C:\Users\user\PycharmProjects\pythonProject1\lib\site-packages\telegram\utils\request.py", line 276, in _request_wrapper
    raise Conflict(message)
telegram.error.Conflict: Conflict: terminated by other getUpdates request; make sure that only one bot instance is running
2021-03-01 00:50:01,039 - ERROR - Error while getting Updates: Conflict: terminated by other getUpdates request; make sure that only one bot instance is running
2021-03-01 00:50:01,040 - ERROR - No error handlers are registered, logging exception.
Traceback (most recent call last):
  File "C:\Users\user\PycharmProjects\pythonProject\venv\lib\site-packages\telegram\ext\updater.py", line 465, in _network_loop_retry
    if not action_cb():
  File "C:\Users\user\PycharmProjects\pythonProject\venv\lib\site-packages\telegram\ext\updater.py", line 416, in polling_action_cb
    updates = self.bot.get_updates(
  File "<decorator-gen-31>", line 2, in get_updates
  File "C:\Users\user\PycharmProjects\pythonProject\venv\lib\site-packages\telegram\bot.py", line 135, in decorator
    result = func(*args, **kwargs)
  File "C:\Users\user\PycharmProjects\pythonProject\venv\lib\site-packages\telegram\bot.py", line 2638, in get_updates
    result = self._post(
  File "C:\Users\user\PycharmProjects\pythonProject\venv\lib\site-packages\telegram\bot.py", line 245, in _post
    return self.request.post(f'{self.base_url}/{endpoint}', data=data, timeout=timeout)
  File "C:\Users\user\PycharmProjects\pythonProject\venv\lib\site-packages\telegram\utils\request.py", line 349, in post
    result = self._request_wrapper(
  File "C:\Users\user\PycharmProjects\pythonProject\venv\lib\site-packages\telegram\utils\request.py", line 276, in _request_wrapper
    raise Conflict(message)
telegram.error.Conflict: Conflict: terminated by other getUpdates request; make sure that only one bot instance is running
2021-03-01 00:50:06,364 - ERROR - Error while getting Updates: Conflict: terminated by other getUpdates request; make sure that only one bot instance is running
2021-03-01 00:50:06,364 - ERROR - No error handlers are registered, logging exception.
Traceback (most recent call last):
  File "C:\Users\user\PycharmProjects\pythonProject1\lib\site-packages\telegram\ext\updater.py", line 465, in _network_loop_retry
    if not action_cb():
  File "C:\Users\user\PycharmProjects\pythonProject1\lib\site-packages\telegram\ext\updater.py", line 416, in polling_action_cb
    updates = self.bot.get_updates(
  File "C:\Users\user\PycharmProjects\pythonProject1\lib\site-packages\telegram\bot.py", line 126, in decorator
    result = func(*args, **kwargs)
  File "C:\Users\user\PycharmProjects\pythonProject1\lib\site-packages\telegram\bot.py", line 2748, in get_updates
    result = self._post(
  File "C:\Users\user\PycharmProjects\pythonProject1\lib\site-packages\telegram\bot.py", line 258, in _post
    return self.request.post(
  File "C:\Users\user\PycharmProjects\pythonProject1\lib\site-packages\telegram\utils\request.py", line 349, in post
    result = self._request_wrapper(
  File "C:\Users\user\PycharmProjects\pythonProject1\lib\site-packages\telegram\utils\request.py", line 276, in _request_wrapper
    raise Conflict(message)
telegram.error.Conflict: Conflict: terminated by other getUpdates request; make sure that only one bot instance is running
2021-03-01 00:50:08,314 - ERROR - No error handlers are registered, logging exception.
Traceback (most recent call last):
  File "C:\Users\user\PycharmProjects\pythonProject1\lib\site-packages\telegram\ext\dispatcher.py", line 442, in process_update
    handler.handle_update(update, self, check, context)
  File "C:\Users\user\PycharmProjects\pythonProject1\lib\site-packages\telegram\ext\conversationhandler.py", line 549, in handle_update
    new_state = handler.handle_update(update, dispatcher, check_result, context)
  File "C:\Users\user\PycharmProjects\pythonProject1\lib\site-packages\telegram\ext\handler.py", line 160, in handle_update
    return self.callback(update, context)
  File "C:\Users\user\PycharmProjects\InvestBot\Handlers\CallBackQueryHandlers\helpCallbackQueryHandler.py", line 15, in aboutCommands
    print(chatId)
OSError: [Errno 22] Invalid argument
2021-03-01 00:50:11,086 - ERROR - Error while getting Updates: Conflict: terminated by other getUpdates request; make sure that only one bot instance is running
2021-03-01 00:50:11,086 - ERROR - No error handlers are registered, logging exception.
Traceback (most recent call last):
  File "C:\Users\user\PycharmProjects\pythonProject\venv\lib\site-packages\telegram\ext\updater.py", line 465, in _network_loop_retry
    if not action_cb():
  File "C:\Users\user\PycharmProjects\pythonProject\venv\lib\site-packages\telegram\ext\updater.py", line 416, in polling_action_cb
    updates = self.bot.get_updates(
  File "<decorator-gen-31>", line 2, in get_updates
  File "C:\Users\user\PycharmProjects\pythonProject\venv\lib\site-packages\telegram\bot.py", line 135, in decorator
    result = func(*args, **kwargs)
  File "C:\Users\user\PycharmProjects\pythonProject\venv\lib\site-packages\telegram\bot.py", line 2638, in get_updates
    result = self._post(
  File "C:\Users\user\PycharmProjects\pythonProject\venv\lib\site-packages\telegram\bot.py", line 245, in _post
    return self.request.post(f'{self.base_url}/{endpoint}', data=data, timeout=timeout)
  File "C:\Users\user\PycharmProjects\pythonProject\venv\lib\site-packages\telegram\utils\request.py", line 349, in post
    result = self._request_wrapper(
  File "C:\Users\user\PycharmProjects\pythonProject\venv\lib\site-packages\telegram\utils\request.py", line 276, in _request_wrapper
    raise Conflict(message)
telegram.error.Conflict: Conflict: terminated by other getUpdates request; make sure that only one bot instance is running
2021-03-01 00:50:12,311 - ERROR - ERROR:  duplicate key value violates unique constraint "chat_id"
DETAIL:  Key (chat_id)=(350402934) already exists.
Traceback (most recent call last):
  File "C:\Users\user\PycharmProjects\InvestBot\DB\Queries\dbConnection.py", line 31, in query
    records = update_db(conn,sql)
  File "C:\Users\user\PycharmProjects\InvestBot\DB\Queries\dbConnection.py", line 21, in update_db
    cursor.execute(sql)
psycopg2.errors.UniqueViolation: duplicate key value violates unique constraint "chat_id"
DETAIL:  Key (chat_id)=(350402934) already exists.

2021-03-01 00:50:12,312 - ERROR - No error handlers are registered, logging exception.
Traceback (most recent call last):
  File "C:\Users\user\PycharmProjects\pythonProject1\lib\site-packages\telegram\ext\dispatcher.py", line 442, in process_update
    handler.handle_update(update, self, check, context)
  File "C:\Users\user\PycharmProjects\pythonProject1\lib\site-packages\telegram\ext\handler.py", line 160, in handle_update
    return self.callback(update, context)
  File "C:\Users\user\PycharmProjects\InvestBot\Handlers\CommandHandlers\BaseCommandHandler.py", line 37, in startCommand
    print(bot)
OSError: [Errno 22] Invalid argument
2021-03-01 00:50:12,414 - ERROR - ERROR:  duplicate key value violates unique constraint "chat_id"
DETAIL:  Key (chat_id)=(350402934) already exists.
Traceback (most recent call last):
  File "C:\Users\user\PycharmProjects\InvestBot\DB\Queries\dbConnection.py", line 31, in query
    records = update_db(conn,sql)
  File "C:\Users\user\PycharmProjects\InvestBot\DB\Queries\dbConnection.py", line 21, in update_db
    cursor.execute(sql)
psycopg2.errors.UniqueViolation: duplicate key value violates unique constraint "chat_id"
DETAIL:  Key (chat_id)=(350402934) already exists.

2021-03-01 00:50:12,507 - ERROR - Error while getting Updates: Conflict: terminated by other getUpdates request; make sure that only one bot instance is running
2021-03-01 00:50:12,507 - ERROR - No error handlers are registered, logging exception.
Traceback (most recent call last):
  File "C:\Users\user\PycharmProjects\pythonProject1\lib\site-packages\telegram\ext\updater.py", line 465, in _network_loop_retry
    if not action_cb():
  File "C:\Users\user\PycharmProjects\pythonProject1\lib\site-packages\telegram\ext\updater.py", line 416, in polling_action_cb
    updates = self.bot.get_updates(
  File "C:\Users\user\PycharmProjects\pythonProject1\lib\site-packages\telegram\bot.py", line 126, in decorator
    result = func(*args, **kwargs)
  File "C:\Users\user\PycharmProjects\pythonProject1\lib\site-packages\telegram\bot.py", line 2748, in get_updates
    result = self._post(
  File "C:\Users\user\PycharmProjects\pythonProject1\lib\site-packages\telegram\bot.py", line 258, in _post
    return self.request.post(
  File "C:\Users\user\PycharmProjects\pythonProject1\lib\site-packages\telegram\utils\request.py", line 349, in post
    result = self._request_wrapper(
  File "C:\Users\user\PycharmProjects\pythonProject1\lib\site-packages\telegram\utils\request.py", line 276, in _request_wrapper
    raise Conflict(message)
telegram.error.Conflict: Conflict: terminated by other getUpdates request; make sure that only one bot instance is running
2021-03-01 00:50:16,706 - ERROR - Error while getting Updates: Conflict: terminated by other getUpdates request; make sure that only one bot instance is running
2021-03-01 00:50:16,706 - ERROR - No error handlers are registered, logging exception.
Traceback (most recent call last):
  File "C:\Users\user\PycharmProjects\pythonProject\venv\lib\site-packages\telegram\ext\updater.py", line 465, in _network_loop_retry
    if not action_cb():
  File "C:\Users\user\PycharmProjects\pythonProject\venv\lib\site-packages\telegram\ext\updater.py", line 416, in polling_action_cb
    updates = self.bot.get_updates(
  File "<decorator-gen-31>", line 2, in get_updates
  File "C:\Users\user\PycharmProjects\pythonProject\venv\lib\site-packages\telegram\bot.py", line 135, in decorator
    result = func(*args, **kwargs)
  File "C:\Users\user\PycharmProjects\pythonProject\venv\lib\site-packages\telegram\bot.py", line 2638, in get_updates
    result = self._post(
  File "C:\Users\user\PycharmProjects\pythonProject\venv\lib\site-packages\telegram\bot.py", line 245, in _post
    return self.request.post(f'{self.base_url}/{endpoint}', data=data, timeout=timeout)
  File "C:\Users\user\PycharmProjects\pythonProject\venv\lib\site-packages\telegram\utils\request.py", line 349, in post
    result = self._request_wrapper(
  File "C:\Users\user\PycharmProjects\pythonProject\venv\lib\site-packages\telegram\utils\request.py", line 276, in _request_wrapper
    raise Conflict(message)
telegram.error.Conflict: Conflict: terminated by other getUpdates request; make sure that only one bot instance is running
2021-03-01 00:50:18,004 - ERROR - Error while getting Updates: Conflict: terminated by other getUpdates request; make sure that only one bot instance is running
2021-03-01 00:50:18,005 - ERROR - No error handlers are registered, logging exception.
Traceback (most recent call last):
  File "C:\Users\user\PycharmProjects\pythonProject1\lib\site-packages\telegram\ext\updater.py", line 465, in _network_loop_retry
    if not action_cb():
  File "C:\Users\user\PycharmProjects\pythonProject1\lib\site-packages\telegram\ext\updater.py", line 416, in polling_action_cb
    updates = self.bot.get_updates(
  File "C:\Users\user\PycharmProjects\pythonProject1\lib\site-packages\telegram\bot.py", line 126, in decorator
    result = func(*args, **kwargs)
  File "C:\Users\user\PycharmProjects\pythonProject1\lib\site-packages\telegram\bot.py", line 2748, in get_updates
    result = self._post(
  File "C:\Users\user\PycharmProjects\pythonProject1\lib\site-packages\telegram\bot.py", line 258, in _post
    return self.request.post(
  File "C:\Users\user\PycharmProjects\pythonProject1\lib\site-packages\telegram\utils\request.py", line 349, in post
    result = self._request_wrapper(
  File "C:\Users\user\PycharmProjects\pythonProject1\lib\site-packages\telegram\utils\request.py", line 276, in _request_wrapper
    raise Conflict(message)
telegram.error.Conflict: Conflict: terminated by other getUpdates request; make sure that only one bot instance is running
2021-03-01 00:50:22,245 - ERROR - Error while getting Updates: Conflict: terminated by other getUpdates request; make sure that only one bot instance is running
2021-03-01 00:50:22,246 - ERROR - No error handlers are registered, logging exception.
Traceback (most recent call last):
  File "C:\Users\user\PycharmProjects\pythonProject\venv\lib\site-packages\telegram\ext\updater.py", line 465, in _network_loop_retry
    if not action_cb():
  File "C:\Users\user\PycharmProjects\pythonProject\venv\lib\site-packages\telegram\ext\updater.py", line 416, in polling_action_cb
    updates = self.bot.get_updates(
  File "<decorator-gen-31>", line 2, in get_updates
  File "C:\Users\user\PycharmProjects\pythonProject\venv\lib\site-packages\telegram\bot.py", line 135, in decorator
    result = func(*args, **kwargs)
  File "C:\Users\user\PycharmProjects\pythonProject\venv\lib\site-packages\telegram\bot.py", line 2638, in get_updates
    result = self._post(
  File "C:\Users\user\PycharmProjects\pythonProject\venv\lib\site-packages\telegram\bot.py", line 245, in _post
    return self.request.post(f'{self.base_url}/{endpoint}', data=data, timeout=timeout)
  File "C:\Users\user\PycharmProjects\pythonProject\venv\lib\site-packages\telegram\utils\request.py", line 349, in post
    result = self._request_wrapper(
  File "C:\Users\user\PycharmProjects\pythonProject\venv\lib\site-packages\telegram\utils\request.py", line 276, in _request_wrapper
    raise Conflict(message)
telegram.error.Conflict: Conflict: terminated by other getUpdates request; make sure that only one bot instance is running
2021-03-01 00:50:24,181 - ERROR - Error while getting Updates: Conflict: terminated by other getUpdates request; make sure that only one bot instance is running
2021-03-01 00:50:24,182 - ERROR - No error handlers are registered, logging exception.
Traceback (most recent call last):
  File "C:\Users\user\PycharmProjects\pythonProject1\lib\site-packages\telegram\ext\updater.py", line 465, in _network_loop_retry
    if not action_cb():
  File "C:\Users\user\PycharmProjects\pythonProject1\lib\site-packages\telegram\ext\updater.py", line 416, in polling_action_cb
    updates = self.bot.get_updates(
  File "C:\Users\user\PycharmProjects\pythonProject1\lib\site-packages\telegram\bot.py", line 126, in decorator
    result = func(*args, **kwargs)
  File "C:\Users\user\PycharmProjects\pythonProject1\lib\site-packages\telegram\bot.py", line 2748, in get_updates
    result = self._post(
  File "C:\Users\user\PycharmProjects\pythonProject1\lib\site-packages\telegram\bot.py", line 258, in _post
    return self.request.post(
  File "C:\Users\user\PycharmProjects\pythonProject1\lib\site-packages\telegram\utils\request.py", line 349, in post
    result = self._request_wrapper(
  File "C:\Users\user\PycharmProjects\pythonProject1\lib\site-packages\telegram\utils\request.py", line 276, in _request_wrapper
    raise Conflict(message)
telegram.error.Conflict: Conflict: terminated by other getUpdates request; make sure that only one bot instance is running
2021-03-01 00:50:28,484 - ERROR - Error while getting Updates: Conflict: terminated by other getUpdates request; make sure that only one bot instance is running
2021-03-01 00:50:28,484 - ERROR - No error handlers are registered, logging exception.
Traceback (most recent call last):
  File "C:\Users\user\PycharmProjects\pythonProject\venv\lib\site-packages\telegram\ext\updater.py", line 465, in _network_loop_retry
    if not action_cb():
  File "C:\Users\user\PycharmProjects\pythonProject\venv\lib\site-packages\telegram\ext\updater.py", line 416, in polling_action_cb
    updates = self.bot.get_updates(
  File "<decorator-gen-31>", line 2, in get_updates
  File "C:\Users\user\PycharmProjects\pythonProject\venv\lib\site-packages\telegram\bot.py", line 135, in decorator
    result = func(*args, **kwargs)
  File "C:\Users\user\PycharmProjects\pythonProject\venv\lib\site-packages\telegram\bot.py", line 2638, in get_updates
    result = self._post(
  File "C:\Users\user\PycharmProjects\pythonProject\venv\lib\site-packages\telegram\bot.py", line 245, in _post
    return self.request.post(f'{self.base_url}/{endpoint}', data=data, timeout=timeout)
  File "C:\Users\user\PycharmProjects\pythonProject\venv\lib\site-packages\telegram\utils\request.py", line 349, in post
    result = self._request_wrapper(
  File "C:\Users\user\PycharmProjects\pythonProject\venv\lib\site-packages\telegram\utils\request.py", line 276, in _request_wrapper
    raise Conflict(message)
telegram.error.Conflict: Conflict: terminated by other getUpdates request; make sure that only one bot instance is running
2021-03-01 00:50:30,941 - ERROR - Error while getting Updates: Conflict: terminated by other getUpdates request; make sure that only one bot instance is running
2021-03-01 00:50:30,942 - ERROR - No error handlers are registered, logging exception.
Traceback (most recent call last):
  File "C:\Users\user\PycharmProjects\pythonProject1\lib\site-packages\telegram\ext\updater.py", line 465, in _network_loop_retry
    if not action_cb():
  File "C:\Users\user\PycharmProjects\pythonProject1\lib\site-packages\telegram\ext\updater.py", line 416, in polling_action_cb
    updates = self.bot.get_updates(
  File "C:\Users\user\PycharmProjects\pythonProject1\lib\site-packages\telegram\bot.py", line 126, in decorator
    result = func(*args, **kwargs)
  File "C:\Users\user\PycharmProjects\pythonProject1\lib\site-packages\telegram\bot.py", line 2748, in get_updates
    result = self._post(
  File "C:\Users\user\PycharmProjects\pythonProject1\lib\site-packages\telegram\bot.py", line 258, in _post
    return self.request.post(
  File "C:\Users\user\PycharmProjects\pythonProject1\lib\site-packages\telegram\utils\request.py", line 349, in post
    result = self._request_wrapper(
  File "C:\Users\user\PycharmProjects\pythonProject1\lib\site-packages\telegram\utils\request.py", line 276, in _request_wrapper
    raise Conflict(message)
telegram.error.Conflict: Conflict: terminated by other getUpdates request; make sure that only one bot instance is running
2021-03-01 00:50:35,761 - ERROR - Error while getting Updates: Conflict: terminated by other getUpdates request; make sure that only one bot instance is running
2021-03-01 00:50:35,762 - ERROR - No error handlers are registered, logging exception.
Traceback (most recent call last):
  File "C:\Users\user\PycharmProjects\pythonProject\venv\lib\site-packages\telegram\ext\updater.py", line 465, in _network_loop_retry
    if not action_cb():
  File "C:\Users\user\PycharmProjects\pythonProject\venv\lib\site-packages\telegram\ext\updater.py", line 416, in polling_action_cb
    updates = self.bot.get_updates(
  File "<decorator-gen-31>", line 2, in get_updates
  File "C:\Users\user\PycharmProjects\pythonProject\venv\lib\site-packages\telegram\bot.py", line 135, in decorator
    result = func(*args, **kwargs)
  File "C:\Users\user\PycharmProjects\pythonProject\venv\lib\site-packages\telegram\bot.py", line 2638, in get_updates
    result = self._post(
  File "C:\Users\user\PycharmProjects\pythonProject\venv\lib\site-packages\telegram\bot.py", line 245, in _post
    return self.request.post(f'{self.base_url}/{endpoint}', data=data, timeout=timeout)
  File "C:\Users\user\PycharmProjects\pythonProject\venv\lib\site-packages\telegram\utils\request.py", line 349, in post
    result = self._request_wrapper(
  File "C:\Users\user\PycharmProjects\pythonProject\venv\lib\site-packages\telegram\utils\request.py", line 276, in _request_wrapper
    raise Conflict(message)
telegram.error.Conflict: Conflict: terminated by other getUpdates request; make sure that only one bot instance is running
2021-03-01 00:50:39,445 - ERROR - Error while getting Updates: Conflict: terminated by other getUpdates request; make sure that only one bot instance is running
2021-03-01 00:50:39,445 - ERROR - No error handlers are registered, logging exception.
Traceback (most recent call last):
  File "C:\Users\user\PycharmProjects\pythonProject1\lib\site-packages\telegram\ext\updater.py", line 465, in _network_loop_retry
    if not action_cb():
  File "C:\Users\user\PycharmProjects\pythonProject1\lib\site-packages\telegram\ext\updater.py", line 416, in polling_action_cb
    updates = self.bot.get_updates(
  File "C:\Users\user\PycharmProjects\pythonProject1\lib\site-packages\telegram\bot.py", line 126, in decorator
    result = func(*args, **kwargs)
  File "C:\Users\user\PycharmProjects\pythonProject1\lib\site-packages\telegram\bot.py", line 2748, in get_updates
    result = self._post(
  File "C:\Users\user\PycharmProjects\pythonProject1\lib\site-packages\telegram\bot.py", line 258, in _post
    return self.request.post(
  File "C:\Users\user\PycharmProjects\pythonProject1\lib\site-packages\telegram\utils\request.py", line 349, in post
    result = self._request_wrapper(
  File "C:\Users\user\PycharmProjects\pythonProject1\lib\site-packages\telegram\utils\request.py", line 276, in _request_wrapper
    raise Conflict(message)
telegram.error.Conflict: Conflict: terminated by other getUpdates request; make sure that only one bot instance is running
2021-03-01 00:50:45,076 - ERROR - Error while getting Updates: Conflict: terminated by other getUpdates request; make sure that only one bot instance is running
2021-03-01 00:50:45,077 - ERROR - No error handlers are registered, logging exception.
Traceback (most recent call last):
  File "C:\Users\user\PycharmProjects\pythonProject\venv\lib\site-packages\telegram\ext\updater.py", line 465, in _network_loop_retry
    if not action_cb():
  File "C:\Users\user\PycharmProjects\pythonProject\venv\lib\site-packages\telegram\ext\updater.py", line 416, in polling_action_cb
    updates = self.bot.get_updates(
  File "<decorator-gen-31>", line 2, in get_updates
  File "C:\Users\user\PycharmProjects\pythonProject\venv\lib\site-packages\telegram\bot.py", line 135, in decorator
    result = func(*args, **kwargs)
  File "C:\Users\user\PycharmProjects\pythonProject\venv\lib\site-packages\telegram\bot.py", line 2638, in get_updates
    result = self._post(
  File "C:\Users\user\PycharmProjects\pythonProject\venv\lib\site-packages\telegram\bot.py", line 245, in _post
    return self.request.post(f'{self.base_url}/{endpoint}', data=data, timeout=timeout)
  File "C:\Users\user\PycharmProjects\pythonProject\venv\lib\site-packages\telegram\utils\request.py", line 349, in post
    result = self._request_wrapper(
  File "C:\Users\user\PycharmProjects\pythonProject\venv\lib\site-packages\telegram\utils\request.py", line 276, in _request_wrapper
    raise Conflict(message)
telegram.error.Conflict: Conflict: terminated by other getUpdates request; make sure that only one bot instance is running
2021-03-01 00:50:50,406 - ERROR - Error while getting Updates: Conflict: terminated by other getUpdates request; make sure that only one bot instance is running
2021-03-01 00:50:50,407 - ERROR - No error handlers are registered, logging exception.
Traceback (most recent call last):
  File "C:\Users\user\PycharmProjects\pythonProject1\lib\site-packages\telegram\ext\updater.py", line 465, in _network_loop_retry
    if not action_cb():
  File "C:\Users\user\PycharmProjects\pythonProject1\lib\site-packages\telegram\ext\updater.py", line 416, in polling_action_cb
    updates = self.bot.get_updates(
  File "C:\Users\user\PycharmProjects\pythonProject1\lib\site-packages\telegram\bot.py", line 126, in decorator
    result = func(*args, **kwargs)
  File "C:\Users\user\PycharmProjects\pythonProject1\lib\site-packages\telegram\bot.py", line 2748, in get_updates
    result = self._post(
  File "C:\Users\user\PycharmProjects\pythonProject1\lib\site-packages\telegram\bot.py", line 258, in _post
    return self.request.post(
  File "C:\Users\user\PycharmProjects\pythonProject1\lib\site-packages\telegram\utils\request.py", line 349, in post
    result = self._request_wrapper(
  File "C:\Users\user\PycharmProjects\pythonProject1\lib\site-packages\telegram\utils\request.py", line 276, in _request_wrapper
    raise Conflict(message)
telegram.error.Conflict: Conflict: terminated by other getUpdates request; make sure that only one bot instance is running
2021-03-01 00:50:54,027 - ERROR - Error while getting Updates: Conflict: terminated by other getUpdates request; make sure that only one bot instance is running
2021-03-01 00:50:54,027 - ERROR - No error handlers are registered, logging exception.
Traceback (most recent call last):
  File "C:\Users\user\PycharmProjects\pythonProject\venv\lib\site-packages\telegram\ext\updater.py", line 465, in _network_loop_retry
    if not action_cb():
  File "C:\Users\user\PycharmProjects\pythonProject\venv\lib\site-packages\telegram\ext\updater.py", line 416, in polling_action_cb
    updates = self.bot.get_updates(
  File "<decorator-gen-31>", line 2, in get_updates
  File "C:\Users\user\PycharmProjects\pythonProject\venv\lib\site-packages\telegram\bot.py", line 135, in decorator
    result = func(*args, **kwargs)
  File "C:\Users\user\PycharmProjects\pythonProject\venv\lib\site-packages\telegram\bot.py", line 2638, in get_updates
    result = self._post(
  File "C:\Users\user\PycharmProjects\pythonProject\venv\lib\site-packages\telegram\bot.py", line 245, in _post
    return self.request.post(f'{self.base_url}/{endpoint}', data=data, timeout=timeout)
  File "C:\Users\user\PycharmProjects\pythonProject\venv\lib\site-packages\telegram\utils\request.py", line 349, in post
    result = self._request_wrapper(
  File "C:\Users\user\PycharmProjects\pythonProject\venv\lib\site-packages\telegram\utils\request.py", line 276, in _request_wrapper
    raise Conflict(message)
telegram.error.Conflict: Conflict: terminated by other getUpdates request; make sure that only one bot instance is running
2021-03-01 00:51:01,871 - ERROR - Error while getting Updates: Conflict: terminated by other getUpdates request; make sure that only one bot instance is running
2021-03-01 00:51:01,871 - ERROR - No error handlers are registered, logging exception.
Traceback (most recent call last):
  File "C:\Users\user\PycharmProjects\pythonProject1\lib\site-packages\telegram\ext\updater.py", line 465, in _network_loop_retry
    if not action_cb():
  File "C:\Users\user\PycharmProjects\pythonProject1\lib\site-packages\telegram\ext\updater.py", line 416, in polling_action_cb
    updates = self.bot.get_updates(
  File "C:\Users\user\PycharmProjects\pythonProject1\lib\site-packages\telegram\bot.py", line 126, in decorator
    result = func(*args, **kwargs)
  File "C:\Users\user\PycharmProjects\pythonProject1\lib\site-packages\telegram\bot.py", line 2748, in get_updates
    result = self._post(
  File "C:\Users\user\PycharmProjects\pythonProject1\lib\site-packages\telegram\bot.py", line 258, in _post
    return self.request.post(
  File "C:\Users\user\PycharmProjects\pythonProject1\lib\site-packages\telegram\utils\request.py", line 349, in post
    result = self._request_wrapper(
  File "C:\Users\user\PycharmProjects\pythonProject1\lib\site-packages\telegram\utils\request.py", line 276, in _request_wrapper
    raise Conflict(message)
telegram.error.Conflict: Conflict: terminated by other getUpdates request; make sure that only one bot instance is running
2021-03-01 00:51:07,198 - ERROR - Error while getting Updates: Conflict: terminated by other getUpdates request; make sure that only one bot instance is running
2021-03-01 00:51:07,199 - ERROR - No error handlers are registered, logging exception.
Traceback (most recent call last):
  File "C:\Users\user\PycharmProjects\pythonProject\venv\lib\site-packages\telegram\ext\updater.py", line 465, in _network_loop_retry
    if not action_cb():
  File "C:\Users\user\PycharmProjects\pythonProject\venv\lib\site-packages\telegram\ext\updater.py", line 416, in polling_action_cb
    updates = self.bot.get_updates(
  File "<decorator-gen-31>", line 2, in get_updates
  File "C:\Users\user\PycharmProjects\pythonProject\venv\lib\site-packages\telegram\bot.py", line 135, in decorator
    result = func(*args, **kwargs)
  File "C:\Users\user\PycharmProjects\pythonProject\venv\lib\site-packages\telegram\bot.py", line 2638, in get_updates
    result = self._post(
  File "C:\Users\user\PycharmProjects\pythonProject\venv\lib\site-packages\telegram\bot.py", line 245, in _post
    return self.request.post(f'{self.base_url}/{endpoint}', data=data, timeout=timeout)
  File "C:\Users\user\PycharmProjects\pythonProject\venv\lib\site-packages\telegram\utils\request.py", line 349, in post
    result = self._request_wrapper(
  File "C:\Users\user\PycharmProjects\pythonProject\venv\lib\site-packages\telegram\utils\request.py", line 276, in _request_wrapper
    raise Conflict(message)
telegram.error.Conflict: Conflict: terminated by other getUpdates request; make sure that only one bot instance is running
2021-03-01 00:51:18,866 - ERROR - Error while getting Updates: Conflict: terminated by other getUpdates request; make sure that only one bot instance is running
2021-03-01 00:51:18,866 - ERROR - No error handlers are registered, logging exception.
Traceback (most recent call last):
  File "C:\Users\user\PycharmProjects\pythonProject1\lib\site-packages\telegram\ext\updater.py", line 465, in _network_loop_retry
    if not action_cb():
  File "C:\Users\user\PycharmProjects\pythonProject1\lib\site-packages\telegram\ext\updater.py", line 416, in polling_action_cb
    updates = self.bot.get_updates(
  File "C:\Users\user\PycharmProjects\pythonProject1\lib\site-packages\telegram\bot.py", line 126, in decorator
    result = func(*args, **kwargs)
  File "C:\Users\user\PycharmProjects\pythonProject1\lib\site-packages\telegram\bot.py", line 2748, in get_updates
    result = self._post(
  File "C:\Users\user\PycharmProjects\pythonProject1\lib\site-packages\telegram\bot.py", line 258, in _post
    return self.request.post(
  File "C:\Users\user\PycharmProjects\pythonProject1\lib\site-packages\telegram\utils\request.py", line 349, in post
    result = self._request_wrapper(
  File "C:\Users\user\PycharmProjects\pythonProject1\lib\site-packages\telegram\utils\request.py", line 276, in _request_wrapper
    raise Conflict(message)
telegram.error.Conflict: Conflict: terminated by other getUpdates request; make sure that only one bot instance is running
2021-03-01 00:51:23,170 - ERROR - Error while getting Updates: Conflict: terminated by other getUpdates request; make sure that only one bot instance is running
2021-03-01 00:51:23,171 - ERROR - No error handlers are registered, logging exception.
Traceback (most recent call last):
  File "C:\Users\user\PycharmProjects\pythonProject\venv\lib\site-packages\telegram\ext\updater.py", line 465, in _network_loop_retry
    if not action_cb():
  File "C:\Users\user\PycharmProjects\pythonProject\venv\lib\site-packages\telegram\ext\updater.py", line 416, in polling_action_cb
    updates = self.bot.get_updates(
  File "<decorator-gen-31>", line 2, in get_updates
  File "C:\Users\user\PycharmProjects\pythonProject\venv\lib\site-packages\telegram\bot.py", line 135, in decorator
    result = func(*args, **kwargs)
  File "C:\Users\user\PycharmProjects\pythonProject\venv\lib\site-packages\telegram\bot.py", line 2638, in get_updates
    result = self._post(
  File "C:\Users\user\PycharmProjects\pythonProject\venv\lib\site-packages\telegram\bot.py", line 245, in _post
    return self.request.post(f'{self.base_url}/{endpoint}', data=data, timeout=timeout)
  File "C:\Users\user\PycharmProjects\pythonProject\venv\lib\site-packages\telegram\utils\request.py", line 349, in post
    result = self._request_wrapper(
  File "C:\Users\user\PycharmProjects\pythonProject\venv\lib\site-packages\telegram\utils\request.py", line 276, in _request_wrapper
    raise Conflict(message)
telegram.error.Conflict: Conflict: terminated by other getUpdates request; make sure that only one bot instance is running
2021-03-01 00:51:40,588 - ERROR - Error while getting Updates: Conflict: terminated by other getUpdates request; make sure that only one bot instance is running
2021-03-01 00:51:40,588 - ERROR - No error handlers are registered, logging exception.
Traceback (most recent call last):
  File "C:\Users\user\PycharmProjects\pythonProject\venv\lib\site-packages\telegram\ext\updater.py", line 465, in _network_loop_retry
    if not action_cb():
  File "C:\Users\user\PycharmProjects\pythonProject\venv\lib\site-packages\telegram\ext\updater.py", line 416, in polling_action_cb
    updates = self.bot.get_updates(
  File "<decorator-gen-31>", line 2, in get_updates
  File "C:\Users\user\PycharmProjects\pythonProject\venv\lib\site-packages\telegram\bot.py", line 135, in decorator
    result = func(*args, **kwargs)
  File "C:\Users\user\PycharmProjects\pythonProject\venv\lib\site-packages\telegram\bot.py", line 2638, in get_updates
    result = self._post(
  File "C:\Users\user\PycharmProjects\pythonProject\venv\lib\site-packages\telegram\bot.py", line 245, in _post
    return self.request.post(f'{self.base_url}/{endpoint}', data=data, timeout=timeout)
  File "C:\Users\user\PycharmProjects\pythonProject\venv\lib\site-packages\telegram\utils\request.py", line 349, in post
    result = self._request_wrapper(
  File "C:\Users\user\PycharmProjects\pythonProject\venv\lib\site-packages\telegram\utils\request.py", line 276, in _request_wrapper
    raise Conflict(message)
telegram.error.Conflict: Conflict: terminated by other getUpdates request; make sure that only one bot instance is running
2021-03-01 00:52:06,496 - ERROR - Error while getting Updates: Conflict: terminated by other getUpdates request; make sure that only one bot instance is running
2021-03-01 00:52:06,497 - ERROR - No error handlers are registered, logging exception.
Traceback (most recent call last):
  File "C:\Users\user\PycharmProjects\pythonProject1\lib\site-packages\telegram\ext\updater.py", line 465, in _network_loop_retry
    if not action_cb():
  File "C:\Users\user\PycharmProjects\pythonProject1\lib\site-packages\telegram\ext\updater.py", line 416, in polling_action_cb
    updates = self.bot.get_updates(
  File "C:\Users\user\PycharmProjects\pythonProject1\lib\site-packages\telegram\bot.py", line 126, in decorator
    result = func(*args, **kwargs)
  File "C:\Users\user\PycharmProjects\pythonProject1\lib\site-packages\telegram\bot.py", line 2748, in get_updates
    result = self._post(
  File "C:\Users\user\PycharmProjects\pythonProject1\lib\site-packages\telegram\bot.py", line 258, in _post
    return self.request.post(
  File "C:\Users\user\PycharmProjects\pythonProject1\lib\site-packages\telegram\utils\request.py", line 349, in post
    result = self._request_wrapper(
  File "C:\Users\user\PycharmProjects\pythonProject1\lib\site-packages\telegram\utils\request.py", line 276, in _request_wrapper
    raise Conflict(message)
telegram.error.Conflict: Conflict: terminated by other getUpdates request; make sure that only one bot instance is running
2021-03-01 00:52:10,787 - ERROR - Error while getting Updates: Conflict: terminated by other getUpdates request; make sure that only one bot instance is running
2021-03-01 00:52:10,787 - ERROR - No error handlers are registered, logging exception.
Traceback (most recent call last):
  File "C:\Users\user\PycharmProjects\pythonProject\venv\lib\site-packages\telegram\ext\updater.py", line 465, in _network_loop_retry
    if not action_cb():
  File "C:\Users\user\PycharmProjects\pythonProject\venv\lib\site-packages\telegram\ext\updater.py", line 416, in polling_action_cb
    updates = self.bot.get_updates(
  File "<decorator-gen-31>", line 2, in get_updates
  File "C:\Users\user\PycharmProjects\pythonProject\venv\lib\site-packages\telegram\bot.py", line 135, in decorator
    result = func(*args, **kwargs)
  File "C:\Users\user\PycharmProjects\pythonProject\venv\lib\site-packages\telegram\bot.py", line 2638, in get_updates
    result = self._post(
  File "C:\Users\user\PycharmProjects\pythonProject\venv\lib\site-packages\telegram\bot.py", line 245, in _post
    return self.request.post(f'{self.base_url}/{endpoint}', data=data, timeout=timeout)
  File "C:\Users\user\PycharmProjects\pythonProject\venv\lib\site-packages\telegram\utils\request.py", line 349, in post
    result = self._request_wrapper(
  File "C:\Users\user\PycharmProjects\pythonProject\venv\lib\site-packages\telegram\utils\request.py", line 276, in _request_wrapper
    raise Conflict(message)
telegram.error.Conflict: Conflict: terminated by other getUpdates request; make sure that only one bot instance is running
2021-03-01 00:52:36,329 - INFO - Scheduler started
2021-03-01 00:52:37,540 - ERROR - Error while getting Updates: Conflict: terminated by other getUpdates request; make sure that only one bot instance is running
2021-03-01 00:52:37,540 - ERROR - No error handlers are registered, logging exception.
Traceback (most recent call last):
  File "C:\Users\user\PycharmProjects\pythonProject1\lib\site-packages\telegram\ext\updater.py", line 465, in _network_loop_retry
    if not action_cb():
  File "C:\Users\user\PycharmProjects\pythonProject1\lib\site-packages\telegram\ext\updater.py", line 416, in polling_action_cb
    updates = self.bot.get_updates(
  File "C:\Users\user\PycharmProjects\pythonProject1\lib\site-packages\telegram\bot.py", line 126, in decorator
    result = func(*args, **kwargs)
  File "C:\Users\user\PycharmProjects\pythonProject1\lib\site-packages\telegram\bot.py", line 2748, in get_updates
    result = self._post(
  File "C:\Users\user\PycharmProjects\pythonProject1\lib\site-packages\telegram\bot.py", line 258, in _post
    return self.request.post(
  File "C:\Users\user\PycharmProjects\pythonProject1\lib\site-packages\telegram\utils\request.py", line 349, in post
    result = self._request_wrapper(
  File "C:\Users\user\PycharmProjects\pythonProject1\lib\site-packages\telegram\utils\request.py", line 276, in _request_wrapper
    raise Conflict(message)
telegram.error.Conflict: Conflict: terminated by other getUpdates request; make sure that only one bot instance is running
2021-03-01 00:52:41,204 - ERROR - ERROR:  duplicate key value violates unique constraint "chat_id"
DETAIL:  Key (chat_id)=(350402934) already exists.
Traceback (most recent call last):
  File "C:\Users\user\PycharmProjects\InvestBot\DB\Queries\dbConnection.py", line 31, in query
    records = update_db(conn,sql)
  File "C:\Users\user\PycharmProjects\InvestBot\DB\Queries\dbConnection.py", line 21, in update_db
    cursor.execute(sql)
psycopg2.errors.UniqueViolation: duplicate key value violates unique constraint "chat_id"
DETAIL:  Key (chat_id)=(350402934) already exists.

2021-03-01 00:52:41,206 - ERROR - No error handlers are registered, logging exception.
Traceback (most recent call last):
  File "C:\Users\user\PycharmProjects\pythonProject1\lib\site-packages\telegram\ext\dispatcher.py", line 442, in process_update
    handler.handle_update(update, self, check, context)
  File "C:\Users\user\PycharmProjects\pythonProject1\lib\site-packages\telegram\ext\handler.py", line 160, in handle_update
    return self.callback(update, context)
  File "C:\Users\user\PycharmProjects\InvestBot\Handlers\CommandHandlers\BaseCommandHandler.py", line 37, in startCommand
    print(bot)
OSError: [Errno 22] Invalid argument
2021-03-01 00:52:41,823 - ERROR - Error while getting Updates: Conflict: terminated by other getUpdates request; make sure that only one bot instance is running
2021-03-01 00:52:41,823 - ERROR - No error handlers are registered, logging exception.
Traceback (most recent call last):
  File "C:\Users\user\PycharmProjects\pythonProject\venv\lib\site-packages\telegram\ext\updater.py", line 465, in _network_loop_retry
    if not action_cb():
  File "C:\Users\user\PycharmProjects\pythonProject\venv\lib\site-packages\telegram\ext\updater.py", line 416, in polling_action_cb
    updates = self.bot.get_updates(
  File "<decorator-gen-31>", line 2, in get_updates
  File "C:\Users\user\PycharmProjects\pythonProject\venv\lib\site-packages\telegram\bot.py", line 135, in decorator
    result = func(*args, **kwargs)
  File "C:\Users\user\PycharmProjects\pythonProject\venv\lib\site-packages\telegram\bot.py", line 2638, in get_updates
    result = self._post(
  File "C:\Users\user\PycharmProjects\pythonProject\venv\lib\site-packages\telegram\bot.py", line 245, in _post
    return self.request.post(f'{self.base_url}/{endpoint}', data=data, timeout=timeout)
  File "C:\Users\user\PycharmProjects\pythonProject\venv\lib\site-packages\telegram\utils\request.py", line 349, in post
    result = self._request_wrapper(
  File "C:\Users\user\PycharmProjects\pythonProject\venv\lib\site-packages\telegram\utils\request.py", line 276, in _request_wrapper
    raise Conflict(message)
telegram.error.Conflict: Conflict: terminated by other getUpdates request; make sure that only one bot instance is running
2021-03-01 00:52:43,146 - ERROR - Error while getting Updates: Conflict: terminated by other getUpdates request; make sure that only one bot instance is running
2021-03-01 00:52:43,146 - ERROR - No error handlers are registered, logging exception.
Traceback (most recent call last):
  File "C:\Users\user\PycharmProjects\pythonProject1\lib\site-packages\telegram\ext\updater.py", line 465, in _network_loop_retry
    if not action_cb():
  File "C:\Users\user\PycharmProjects\pythonProject1\lib\site-packages\telegram\ext\updater.py", line 416, in polling_action_cb
    updates = self.bot.get_updates(
  File "C:\Users\user\PycharmProjects\pythonProject1\lib\site-packages\telegram\bot.py", line 126, in decorator
    result = func(*args, **kwargs)
  File "C:\Users\user\PycharmProjects\pythonProject1\lib\site-packages\telegram\bot.py", line 2748, in get_updates
    result = self._post(
  File "C:\Users\user\PycharmProjects\pythonProject1\lib\site-packages\telegram\bot.py", line 258, in _post
    return self.request.post(
  File "C:\Users\user\PycharmProjects\pythonProject1\lib\site-packages\telegram\utils\request.py", line 349, in post
    result = self._request_wrapper(
  File "C:\Users\user\PycharmProjects\pythonProject1\lib\site-packages\telegram\utils\request.py", line 276, in _request_wrapper
    raise Conflict(message)
telegram.error.Conflict: Conflict: terminated by other getUpdates request; make sure that only one bot instance is running
2021-03-01 00:52:47,448 - ERROR - Error while getting Updates: Conflict: terminated by other getUpdates request; make sure that only one bot instance is running
2021-03-01 00:52:47,449 - ERROR - No error handlers are registered, logging exception.
Traceback (most recent call last):
  File "C:\Users\user\PycharmProjects\pythonProject\venv\lib\site-packages\telegram\ext\updater.py", line 465, in _network_loop_retry
    if not action_cb():
  File "C:\Users\user\PycharmProjects\pythonProject\venv\lib\site-packages\telegram\ext\updater.py", line 416, in polling_action_cb
    updates = self.bot.get_updates(
  File "<decorator-gen-31>", line 2, in get_updates
  File "C:\Users\user\PycharmProjects\pythonProject\venv\lib\site-packages\telegram\bot.py", line 135, in decorator
    result = func(*args, **kwargs)
  File "C:\Users\user\PycharmProjects\pythonProject\venv\lib\site-packages\telegram\bot.py", line 2638, in get_updates
    result = self._post(
  File "C:\Users\user\PycharmProjects\pythonProject\venv\lib\site-packages\telegram\bot.py", line 245, in _post
    return self.request.post(f'{self.base_url}/{endpoint}', data=data, timeout=timeout)
  File "C:\Users\user\PycharmProjects\pythonProject\venv\lib\site-packages\telegram\utils\request.py", line 349, in post
    result = self._request_wrapper(
  File "C:\Users\user\PycharmProjects\pythonProject\venv\lib\site-packages\telegram\utils\request.py", line 276, in _request_wrapper
    raise Conflict(message)
telegram.error.Conflict: Conflict: terminated by other getUpdates request; make sure that only one bot instance is running
2021-03-01 00:52:49,189 - ERROR - Error while getting Updates: Conflict: terminated by other getUpdates request; make sure that only one bot instance is running
2021-03-01 00:52:49,189 - ERROR - No error handlers are registered, logging exception.
Traceback (most recent call last):
  File "C:\Users\user\PycharmProjects\pythonProject1\lib\site-packages\telegram\ext\updater.py", line 465, in _network_loop_retry
    if not action_cb():
  File "C:\Users\user\PycharmProjects\pythonProject1\lib\site-packages\telegram\ext\updater.py", line 416, in polling_action_cb
    updates = self.bot.get_updates(
  File "C:\Users\user\PycharmProjects\pythonProject1\lib\site-packages\telegram\bot.py", line 126, in decorator
    result = func(*args, **kwargs)
  File "C:\Users\user\PycharmProjects\pythonProject1\lib\site-packages\telegram\bot.py", line 2748, in get_updates
    result = self._post(
  File "C:\Users\user\PycharmProjects\pythonProject1\lib\site-packages\telegram\bot.py", line 258, in _post
    return self.request.post(
  File "C:\Users\user\PycharmProjects\pythonProject1\lib\site-packages\telegram\utils\request.py", line 349, in post
    result = self._request_wrapper(
  File "C:\Users\user\PycharmProjects\pythonProject1\lib\site-packages\telegram\utils\request.py", line 276, in _request_wrapper
    raise Conflict(message)
telegram.error.Conflict: Conflict: terminated by other getUpdates request; make sure that only one bot instance is running
2021-03-01 00:52:53,910 - ERROR - Error while getting Updates: Conflict: terminated by other getUpdates request; make sure that only one bot instance is running
2021-03-01 00:52:53,910 - ERROR - No error handlers are registered, logging exception.
Traceback (most recent call last):
  File "C:\Users\user\PycharmProjects\pythonProject\venv\lib\site-packages\telegram\ext\updater.py", line 465, in _network_loop_retry
    if not action_cb():
  File "C:\Users\user\PycharmProjects\pythonProject\venv\lib\site-packages\telegram\ext\updater.py", line 416, in polling_action_cb
    updates = self.bot.get_updates(
  File "<decorator-gen-31>", line 2, in get_updates
  File "C:\Users\user\PycharmProjects\pythonProject\venv\lib\site-packages\telegram\bot.py", line 135, in decorator
    result = func(*args, **kwargs)
  File "C:\Users\user\PycharmProjects\pythonProject\venv\lib\site-packages\telegram\bot.py", line 2638, in get_updates
    result = self._post(
  File "C:\Users\user\PycharmProjects\pythonProject\venv\lib\site-packages\telegram\bot.py", line 245, in _post
    return self.request.post(f'{self.base_url}/{endpoint}', data=data, timeout=timeout)
  File "C:\Users\user\PycharmProjects\pythonProject\venv\lib\site-packages\telegram\utils\request.py", line 349, in post
    result = self._request_wrapper(
  File "C:\Users\user\PycharmProjects\pythonProject\venv\lib\site-packages\telegram\utils\request.py", line 276, in _request_wrapper
    raise Conflict(message)
telegram.error.Conflict: Conflict: terminated by other getUpdates request; make sure that only one bot instance is running
2021-03-01 00:52:56,459 - ERROR - Error while getting Updates: Conflict: terminated by other getUpdates request; make sure that only one bot instance is running
2021-03-01 00:52:56,460 - ERROR - No error handlers are registered, logging exception.
Traceback (most recent call last):
  File "C:\Users\user\PycharmProjects\pythonProject1\lib\site-packages\telegram\ext\updater.py", line 465, in _network_loop_retry
    if not action_cb():
  File "C:\Users\user\PycharmProjects\pythonProject1\lib\site-packages\telegram\ext\updater.py", line 416, in polling_action_cb
    updates = self.bot.get_updates(
  File "C:\Users\user\PycharmProjects\pythonProject1\lib\site-packages\telegram\bot.py", line 126, in decorator
    result = func(*args, **kwargs)
  File "C:\Users\user\PycharmProjects\pythonProject1\lib\site-packages\telegram\bot.py", line 2748, in get_updates
    result = self._post(
  File "C:\Users\user\PycharmProjects\pythonProject1\lib\site-packages\telegram\bot.py", line 258, in _post
    return self.request.post(
  File "C:\Users\user\PycharmProjects\pythonProject1\lib\site-packages\telegram\utils\request.py", line 349, in post
    result = self._request_wrapper(
  File "C:\Users\user\PycharmProjects\pythonProject1\lib\site-packages\telegram\utils\request.py", line 276, in _request_wrapper
    raise Conflict(message)
telegram.error.Conflict: Conflict: terminated by other getUpdates request; make sure that only one bot instance is running
2021-03-01 00:53:00,764 - ERROR - Error while getting Updates: Conflict: terminated by other getUpdates request; make sure that only one bot instance is running
2021-03-01 00:53:00,764 - ERROR - No error handlers are registered, logging exception.
Traceback (most recent call last):
  File "C:\Users\user\PycharmProjects\pythonProject\venv\lib\site-packages\telegram\ext\updater.py", line 465, in _network_loop_retry
    if not action_cb():
  File "C:\Users\user\PycharmProjects\pythonProject\venv\lib\site-packages\telegram\ext\updater.py", line 416, in polling_action_cb
    updates = self.bot.get_updates(
  File "<decorator-gen-31>", line 2, in get_updates
  File "C:\Users\user\PycharmProjects\pythonProject\venv\lib\site-packages\telegram\bot.py", line 135, in decorator
    result = func(*args, **kwargs)
  File "C:\Users\user\PycharmProjects\pythonProject\venv\lib\site-packages\telegram\bot.py", line 2638, in get_updates
    result = self._post(
  File "C:\Users\user\PycharmProjects\pythonProject\venv\lib\site-packages\telegram\bot.py", line 245, in _post
    return self.request.post(f'{self.base_url}/{endpoint}', data=data, timeout=timeout)
  File "C:\Users\user\PycharmProjects\pythonProject\venv\lib\site-packages\telegram\utils\request.py", line 349, in post
    result = self._request_wrapper(
  File "C:\Users\user\PycharmProjects\pythonProject\venv\lib\site-packages\telegram\utils\request.py", line 276, in _request_wrapper
    raise Conflict(message)
telegram.error.Conflict: Conflict: terminated by other getUpdates request; make sure that only one bot instance is running
2021-03-01 22:49:33,818 - INFO - Scheduler started
2021-03-01 22:49:34,988 - ERROR - ERROR:  duplicate key value violates unique constraint "chat_id"
DETAIL:  Key (chat_id)=(360008942) already exists.
Traceback (most recent call last):
  File "/Users/a18850286/PycharmProjects/InvestBot/DB/Queries/dbConnection.py", line 31, in query
    records = update_db(conn,sql)
  File "/Users/a18850286/PycharmProjects/InvestBot/DB/Queries/dbConnection.py", line 21, in update_db
    cursor.execute(sql)
psycopg2.errors.UniqueViolation: duplicate key value violates unique constraint "chat_id"
DETAIL:  Key (chat_id)=(360008942) already exists.

2021-03-01 22:49:35,807 - ERROR - None
Traceback (most recent call last):
  File "/Users/a18850286/PycharmProjects/InvestBot/DB/Queries/dbConnection.py", line 31, in query
    records = update_db(conn,sql)
  File "/Users/a18850286/PycharmProjects/InvestBot/DB/Queries/dbConnection.py", line 23, in update_db
    records = cursor.fetchall()
psycopg2.ProgrammingError: no results to fetch
2021-03-01 22:50:09,202 - INFO - Received signal 2 (SIGINT), stopping...
2021-03-01 22:50:09,202 - INFO - Scheduler has been shut down
2021-03-01 23:17:49,550 - INFO - Scheduler started
2021-03-01 23:18:09,208 - INFO - Received signal 2 (SIGINT), stopping...
2021-03-01 23:18:09,208 - INFO - Scheduler has been shut down
2021-03-01 23:18:27,453 - INFO - Scheduler started
2021-03-01 23:18:59,139 - INFO - Received signal 2 (SIGINT), stopping...
2021-03-01 23:18:59,139 - INFO - Scheduler has been shut down
2021-03-01 23:19:31,305 - INFO - Scheduler started
2021-03-01 23:21:22,110 - INFO - Received signal 2 (SIGINT), stopping...
2021-03-01 23:21:22,111 - INFO - Scheduler has been shut down
2021-03-01 23:21:52,183 - INFO - Scheduler started
2021-03-01 23:22:28,678 - INFO - Received signal 2 (SIGINT), stopping...
2021-03-01 23:22:28,678 - INFO - Scheduler has been shut down
2021-03-01 23:22:46,155 - INFO - Scheduler started
2021-03-01 23:23:26,178 - INFO - Received signal 2 (SIGINT), stopping...
2021-03-01 23:23:26,178 - INFO - Scheduler has been shut down
2021-03-01 23:27:02,514 - INFO - Scheduler started
2021-03-01 23:27:42,190 - INFO - Received signal 2 (SIGINT), stopping...
2021-03-01 23:27:42,191 - INFO - Scheduler has been shut down
2021-03-01 23:31:45,051 - INFO - Scheduler started
2021-03-01 23:32:05,139 - INFO - Received signal 2 (SIGINT), stopping...
2021-03-01 23:32:05,139 - INFO - Scheduler has been shut down
2021-03-01 23:48:17,539 - INFO - Scheduler started
2021-03-01 23:48:27,321 - INFO - Received signal 2 (SIGINT), stopping...
2021-03-01 23:48:27,321 - INFO - Scheduler has been shut down
2021-03-01 23:51:45,867 - INFO - Scheduler started
2021-03-01 23:51:59,901 - ERROR - No error handlers are registered, logging exception.
Traceback (most recent call last):
  File "/Library/Frameworks/Python.framework/Versions/3.8/lib/python3.8/site-packages/telegram/ext/dispatcher.py", line 432, in process_update
    handler.handle_update(update, self, check, context)
  File "/Library/Frameworks/Python.framework/Versions/3.8/lib/python3.8/site-packages/telegram/ext/conversationhandler.py", line 517, in handle_update
    new_state = handler.handle_update(update, dispatcher, check_result, context)
  File "/Library/Frameworks/Python.framework/Versions/3.8/lib/python3.8/site-packages/telegram/ext/handler.py", line 156, in handle_update
    return self.callback(update, context)
  File "/Users/a18850286/PycharmProjects/InvestBot/Handlers/CallBackQueryHandlers/officeCallbackQueryHandler.py", line 13, in nextAsset
    update.bot.editMessageText(message,chatId, parse_mode="Markdown")
  File "<decorator-gen-27>", line 2, in edit_message_text
  File "/Library/Frameworks/Python.framework/Versions/3.8/lib/python3.8/site-packages/telegram/bot.py", line 135, in decorator
    result = func(*args, **kwargs)
  File "/Library/Frameworks/Python.framework/Versions/3.8/lib/python3.8/site-packages/telegram/bot.py", line 2362, in edit_message_text
    return self._message(
  File "/Library/Frameworks/Python.framework/Versions/3.8/lib/python3.8/site-packages/telegram/bot.py", line 281, in _message
    result = self._post(endpoint, data, timeout=timeout, api_kwargs=api_kwargs)
  File "/Library/Frameworks/Python.framework/Versions/3.8/lib/python3.8/site-packages/telegram/bot.py", line 245, in _post
    return self.request.post(f'{self.base_url}/{endpoint}', data=data, timeout=timeout)
  File "/Library/Frameworks/Python.framework/Versions/3.8/lib/python3.8/site-packages/telegram/utils/request.py", line 349, in post
    result = self._request_wrapper(
  File "/Library/Frameworks/Python.framework/Versions/3.8/lib/python3.8/site-packages/telegram/utils/request.py", line 272, in _request_wrapper
    raise BadRequest(message)
telegram.error.BadRequest: Message text is empty
2021-03-01 23:52:50,816 - INFO - Received signal 2 (SIGINT), stopping...
2021-03-01 23:52:50,817 - INFO - Scheduler has been shut down
2021-03-01 23:54:13,082 - INFO - Scheduler started
2021-03-01 23:54:20,172 - ERROR - No error handlers are registered, logging exception.
Traceback (most recent call last):
  File "/Library/Frameworks/Python.framework/Versions/3.8/lib/python3.8/site-packages/telegram/ext/dispatcher.py", line 432, in process_update
    handler.handle_update(update, self, check, context)
  File "/Library/Frameworks/Python.framework/Versions/3.8/lib/python3.8/site-packages/telegram/ext/conversationhandler.py", line 517, in handle_update
    new_state = handler.handle_update(update, dispatcher, check_result, context)
  File "/Library/Frameworks/Python.framework/Versions/3.8/lib/python3.8/site-packages/telegram/ext/handler.py", line 156, in handle_update
    return self.callback(update, context)
  File "/Users/a18850286/PycharmProjects/InvestBot/Handlers/CallBackQueryHandlers/officeCallbackQueryHandler.py", line 14, in nextAsset
    update.bot.editMessageText(message,chatId, parse_mode="Markdown")
  File "<decorator-gen-27>", line 2, in edit_message_text
  File "/Library/Frameworks/Python.framework/Versions/3.8/lib/python3.8/site-packages/telegram/bot.py", line 135, in decorator
    result = func(*args, **kwargs)
  File "/Library/Frameworks/Python.framework/Versions/3.8/lib/python3.8/site-packages/telegram/bot.py", line 2362, in edit_message_text
    return self._message(
  File "/Library/Frameworks/Python.framework/Versions/3.8/lib/python3.8/site-packages/telegram/bot.py", line 281, in _message
    result = self._post(endpoint, data, timeout=timeout, api_kwargs=api_kwargs)
  File "/Library/Frameworks/Python.framework/Versions/3.8/lib/python3.8/site-packages/telegram/bot.py", line 245, in _post
    return self.request.post(f'{self.base_url}/{endpoint}', data=data, timeout=timeout)
  File "/Library/Frameworks/Python.framework/Versions/3.8/lib/python3.8/site-packages/telegram/utils/request.py", line 349, in post
    result = self._request_wrapper(
  File "/Library/Frameworks/Python.framework/Versions/3.8/lib/python3.8/site-packages/telegram/utils/request.py", line 272, in _request_wrapper
    raise BadRequest(message)
telegram.error.BadRequest: Message text is empty
2021-03-01 23:54:26,932 - INFO - Received signal 2 (SIGINT), stopping...
2021-03-01 23:54:26,932 - INFO - Scheduler has been shut down
2021-03-01 23:55:24,096 - INFO - Scheduler started
2021-03-01 23:55:30,759 - ERROR - No error handlers are registered, logging exception.
Traceback (most recent call last):
  File "/Library/Frameworks/Python.framework/Versions/3.8/lib/python3.8/site-packages/telegram/ext/dispatcher.py", line 432, in process_update
    handler.handle_update(update, self, check, context)
  File "/Library/Frameworks/Python.framework/Versions/3.8/lib/python3.8/site-packages/telegram/ext/conversationhandler.py", line 517, in handle_update
    new_state = handler.handle_update(update, dispatcher, check_result, context)
  File "/Library/Frameworks/Python.framework/Versions/3.8/lib/python3.8/site-packages/telegram/ext/handler.py", line 156, in handle_update
    return self.callback(update, context)
  File "/Users/a18850286/PycharmProjects/InvestBot/Handlers/CallBackQueryHandlers/officeCallbackQueryHandler.py", line 15, in nextAsset
    update.bot.editMessageText(text=message,chat_id=chatId,message_id=messageId, parse_mode="Markdown")
  File "<decorator-gen-27>", line 2, in edit_message_text
  File "/Library/Frameworks/Python.framework/Versions/3.8/lib/python3.8/site-packages/telegram/bot.py", line 135, in decorator
    result = func(*args, **kwargs)
  File "/Library/Frameworks/Python.framework/Versions/3.8/lib/python3.8/site-packages/telegram/bot.py", line 2362, in edit_message_text
    return self._message(
  File "/Library/Frameworks/Python.framework/Versions/3.8/lib/python3.8/site-packages/telegram/bot.py", line 281, in _message
    result = self._post(endpoint, data, timeout=timeout, api_kwargs=api_kwargs)
  File "/Library/Frameworks/Python.framework/Versions/3.8/lib/python3.8/site-packages/telegram/bot.py", line 245, in _post
    return self.request.post(f'{self.base_url}/{endpoint}', data=data, timeout=timeout)
  File "/Library/Frameworks/Python.framework/Versions/3.8/lib/python3.8/site-packages/telegram/utils/request.py", line 349, in post
    result = self._request_wrapper(
  File "/Library/Frameworks/Python.framework/Versions/3.8/lib/python3.8/site-packages/telegram/utils/request.py", line 272, in _request_wrapper
    raise BadRequest(message)
telegram.error.BadRequest: Message text is empty
2021-03-01 23:56:00,814 - INFO - Received signal 2 (SIGINT), stopping...
2021-03-01 23:56:00,815 - INFO - Scheduler has been shut down
2021-03-01 23:57:02,705 - INFO - Scheduler started
2021-03-01 23:57:09,837 - ERROR - No error handlers are registered, logging exception.
Traceback (most recent call last):
  File "/Library/Frameworks/Python.framework/Versions/3.8/lib/python3.8/site-packages/telegram/ext/dispatcher.py", line 432, in process_update
    handler.handle_update(update, self, check, context)
  File "/Library/Frameworks/Python.framework/Versions/3.8/lib/python3.8/site-packages/telegram/ext/conversationhandler.py", line 517, in handle_update
    new_state = handler.handle_update(update, dispatcher, check_result, context)
  File "/Library/Frameworks/Python.framework/Versions/3.8/lib/python3.8/site-packages/telegram/ext/handler.py", line 156, in handle_update
    return self.callback(update, context)
  File "/Users/a18850286/PycharmProjects/InvestBot/Handlers/CallBackQueryHandlers/officeCallbackQueryHandler.py", line 15, in nextAsset
    update.bot.editMessageText(message,chatId,messageId,"Markdown")
  File "<decorator-gen-27>", line 2, in edit_message_text
  File "/Library/Frameworks/Python.framework/Versions/3.8/lib/python3.8/site-packages/telegram/bot.py", line 135, in decorator
    result = func(*args, **kwargs)
  File "/Library/Frameworks/Python.framework/Versions/3.8/lib/python3.8/site-packages/telegram/bot.py", line 2362, in edit_message_text
    return self._message(
  File "/Library/Frameworks/Python.framework/Versions/3.8/lib/python3.8/site-packages/telegram/bot.py", line 281, in _message
    result = self._post(endpoint, data, timeout=timeout, api_kwargs=api_kwargs)
  File "/Library/Frameworks/Python.framework/Versions/3.8/lib/python3.8/site-packages/telegram/bot.py", line 245, in _post
    return self.request.post(f'{self.base_url}/{endpoint}', data=data, timeout=timeout)
  File "/Library/Frameworks/Python.framework/Versions/3.8/lib/python3.8/site-packages/telegram/utils/request.py", line 349, in post
    result = self._request_wrapper(
  File "/Library/Frameworks/Python.framework/Versions/3.8/lib/python3.8/site-packages/telegram/utils/request.py", line 272, in _request_wrapper
    raise BadRequest(message)
telegram.error.BadRequest: Message text is empty
2021-03-01 23:57:19,548 - INFO - Received signal 2 (SIGINT), stopping...
2021-03-01 23:57:19,548 - INFO - Scheduler has been shut down
2021-03-01 23:57:41,188 - INFO - Scheduler started
2021-03-01 23:57:55,945 - INFO - Received signal 2 (SIGINT), stopping...
2021-03-01 23:57:55,946 - INFO - Scheduler has been shut down
2021-03-17 20:23:12,286 - INFO - Scheduler started
2021-03-17 20:23:13,918 - INFO - Received signal 2 (SIGINT), stopping...
2021-03-17 20:23:13,918 - INFO - Scheduler has been shut down
2021-03-17 20:32:41,776 - INFO - Scheduler started
2021-03-17 20:33:39,248 - ERROR - ERROR:  duplicate key value violates unique constraint "chat_id"
DETAIL:  Key (chat_id)=(360008942) already exists.
Traceback (most recent call last):
  File "/Users/a18850286/PycharmProjects/InvestBot/DB/Queries/dbConnection.py", line 31, in query
    records = update_db(conn,sql)
  File "/Users/a18850286/PycharmProjects/InvestBot/DB/Queries/dbConnection.py", line 21, in update_db
    cursor.execute(sql)
psycopg2.errors.UniqueViolation: duplicate key value violates unique constraint "chat_id"
DETAIL:  Key (chat_id)=(360008942) already exists.

2021-03-17 21:35:16,080 - ERROR - ERROR:  duplicate key value violates unique constraint "chat_id"
DETAIL:  Key (chat_id)=(550666260) already exists.
Traceback (most recent call last):
  File "/Users/a18850286/PycharmProjects/InvestBot/DB/Queries/dbConnection.py", line 31, in query
    records = update_db(conn,sql)
  File "/Users/a18850286/PycharmProjects/InvestBot/DB/Queries/dbConnection.py", line 21, in update_db
    cursor.execute(sql)
psycopg2.errors.UniqueViolation: duplicate key value violates unique constraint "chat_id"
DETAIL:  Key (chat_id)=(550666260) already exists.

2021-03-17 21:36:08,175 - ERROR - No error handlers are registered, logging exception.
Traceback (most recent call last):
  File "/Library/Frameworks/Python.framework/Versions/3.8/lib/python3.8/site-packages/telegram/ext/dispatcher.py", line 432, in process_update
    handler.handle_update(update, self, check, context)
  File "/Library/Frameworks/Python.framework/Versions/3.8/lib/python3.8/site-packages/telegram/ext/conversationhandler.py", line 517, in handle_update
    new_state = handler.handle_update(update, dispatcher, check_result, context)
  File "/Library/Frameworks/Python.framework/Versions/3.8/lib/python3.8/site-packages/telegram/ext/handler.py", line 156, in handle_update
    return self.callback(update, context)
  File "/Users/a18850286/PycharmProjects/InvestBot/Handlers/CallBackQueryHandlers/officeCallbackQueryHandler.py", line 15, in nextAsset
    update.bot.editMessageText(message,chatId,messageId,"Markdown",)
  File "<decorator-gen-27>", line 2, in edit_message_text
  File "/Library/Frameworks/Python.framework/Versions/3.8/lib/python3.8/site-packages/telegram/bot.py", line 135, in decorator
    result = func(*args, **kwargs)
  File "/Library/Frameworks/Python.framework/Versions/3.8/lib/python3.8/site-packages/telegram/bot.py", line 2362, in edit_message_text
    return self._message(
  File "/Library/Frameworks/Python.framework/Versions/3.8/lib/python3.8/site-packages/telegram/bot.py", line 281, in _message
    result = self._post(endpoint, data, timeout=timeout, api_kwargs=api_kwargs)
  File "/Library/Frameworks/Python.framework/Versions/3.8/lib/python3.8/site-packages/telegram/bot.py", line 245, in _post
    return self.request.post(f'{self.base_url}/{endpoint}', data=data, timeout=timeout)
  File "/Library/Frameworks/Python.framework/Versions/3.8/lib/python3.8/site-packages/telegram/utils/request.py", line 349, in post
    result = self._request_wrapper(
  File "/Library/Frameworks/Python.framework/Versions/3.8/lib/python3.8/site-packages/telegram/utils/request.py", line 272, in _request_wrapper
    raise BadRequest(message)
telegram.error.BadRequest: Message text is empty
2021-03-17 21:37:37,159 - ERROR - No error handlers are registered, logging exception.
Traceback (most recent call last):
  File "/Library/Frameworks/Python.framework/Versions/3.8/lib/python3.8/site-packages/telegram/ext/dispatcher.py", line 432, in process_update
    handler.handle_update(update, self, check, context)
  File "/Library/Frameworks/Python.framework/Versions/3.8/lib/python3.8/site-packages/telegram/ext/conversationhandler.py", line 517, in handle_update
    new_state = handler.handle_update(update, dispatcher, check_result, context)
  File "/Library/Frameworks/Python.framework/Versions/3.8/lib/python3.8/site-packages/telegram/ext/handler.py", line 156, in handle_update
    return self.callback(update, context)
  File "/Users/a18850286/PycharmProjects/InvestBot/Handlers/CallBackQueryHandlers/officeCallbackQueryHandler.py", line 15, in nextAsset
    update.bot.editMessageText(message,chatId,messageId,"Markdown",)
  File "<decorator-gen-27>", line 2, in edit_message_text
  File "/Library/Frameworks/Python.framework/Versions/3.8/lib/python3.8/site-packages/telegram/bot.py", line 135, in decorator
    result = func(*args, **kwargs)
  File "/Library/Frameworks/Python.framework/Versions/3.8/lib/python3.8/site-packages/telegram/bot.py", line 2362, in edit_message_text
    return self._message(
  File "/Library/Frameworks/Python.framework/Versions/3.8/lib/python3.8/site-packages/telegram/bot.py", line 281, in _message
    result = self._post(endpoint, data, timeout=timeout, api_kwargs=api_kwargs)
  File "/Library/Frameworks/Python.framework/Versions/3.8/lib/python3.8/site-packages/telegram/bot.py", line 245, in _post
    return self.request.post(f'{self.base_url}/{endpoint}', data=data, timeout=timeout)
  File "/Library/Frameworks/Python.framework/Versions/3.8/lib/python3.8/site-packages/telegram/utils/request.py", line 349, in post
    result = self._request_wrapper(
  File "/Library/Frameworks/Python.framework/Versions/3.8/lib/python3.8/site-packages/telegram/utils/request.py", line 272, in _request_wrapper
    raise BadRequest(message)
telegram.error.BadRequest: Message text is empty
2021-03-17 21:40:59,785 - ERROR - No error handlers are registered, logging exception.
Traceback (most recent call last):
  File "/Library/Frameworks/Python.framework/Versions/3.8/lib/python3.8/site-packages/telegram/ext/dispatcher.py", line 432, in process_update
    handler.handle_update(update, self, check, context)
  File "/Library/Frameworks/Python.framework/Versions/3.8/lib/python3.8/site-packages/telegram/ext/conversationhandler.py", line 517, in handle_update
    new_state = handler.handle_update(update, dispatcher, check_result, context)
  File "/Library/Frameworks/Python.framework/Versions/3.8/lib/python3.8/site-packages/telegram/ext/handler.py", line 156, in handle_update
    return self.callback(update, context)
  File "/Users/a18850286/PycharmProjects/InvestBot/Handlers/CallBackQueryHandlers/officeCallbackQueryHandler.py", line 15, in nextAsset
    update.bot.editMessageText(message,chatId,messageId,"Markdown",)
  File "<decorator-gen-27>", line 2, in edit_message_text
  File "/Library/Frameworks/Python.framework/Versions/3.8/lib/python3.8/site-packages/telegram/bot.py", line 135, in decorator
    result = func(*args, **kwargs)
  File "/Library/Frameworks/Python.framework/Versions/3.8/lib/python3.8/site-packages/telegram/bot.py", line 2362, in edit_message_text
    return self._message(
  File "/Library/Frameworks/Python.framework/Versions/3.8/lib/python3.8/site-packages/telegram/bot.py", line 281, in _message
    result = self._post(endpoint, data, timeout=timeout, api_kwargs=api_kwargs)
  File "/Library/Frameworks/Python.framework/Versions/3.8/lib/python3.8/site-packages/telegram/bot.py", line 245, in _post
    return self.request.post(f'{self.base_url}/{endpoint}', data=data, timeout=timeout)
  File "/Library/Frameworks/Python.framework/Versions/3.8/lib/python3.8/site-packages/telegram/utils/request.py", line 349, in post
    result = self._request_wrapper(
  File "/Library/Frameworks/Python.framework/Versions/3.8/lib/python3.8/site-packages/telegram/utils/request.py", line 272, in _request_wrapper
    raise BadRequest(message)
telegram.error.BadRequest: Message text is empty
2021-03-17 21:57:25,974 - INFO - Received signal 2 (SIGINT), stopping...
2021-03-17 21:57:25,975 - INFO - Scheduler has been shut down
2021-03-19 13:14:25,184 - INFO - Scheduler started
2021-03-19 13:15:00,390 - INFO - Scheduler started
2021-03-19 13:15:00,580 - ERROR - Certificate did not match expected hostname: telegg.ru. Certificate: {'subject': ((('commonName', '*.reg.ru'),),), 'issuer': ((('countryName', 'BE'),), (('organizationName', 'GlobalSign nv-sa'),), (('commonName', 'AlphaSSL CA - SHA256 - G2'),)), 'version': 3, 'serialNumber': '39BB3D4CBE2A90AFE1FE101E', 'notBefore': 'Jan 27 08:38:16 2021 GMT', 'notAfter': 'Feb 28 08:38:16 2022 GMT', 'subjectAltName': (('DNS', '*.reg.ru'), ('DNS', 'reg.ru')), 'OCSP': ('http://ocsp2.globalsign.com/gsalphasha2g2',), 'caIssuers': ('http://secure2.alphassl.com/cacert/gsalphasha2g2r1.crt',), 'crlDistributionPoints': ('http://crl2.alphassl.com/gs/gsalphasha2g2.crl',)}
2021-03-19 13:18:10,730 - INFO - Scheduler started
2021-03-19 13:18:50,477 - INFO - Scheduler started
2021-03-19 13:18:50,541 - ERROR - Certificate did not match expected hostname: telegg.ru. Certificate: {'subject': ((('commonName', '*.reg.ru'),),), 'issuer': ((('countryName', 'BE'),), (('organizationName', 'GlobalSign nv-sa'),), (('commonName', 'AlphaSSL CA - SHA256 - G2'),)), 'version': 3, 'serialNumber': '39BB3D4CBE2A90AFE1FE101E', 'notBefore': 'Jan 27 08:38:16 2021 GMT', 'notAfter': 'Feb 28 08:38:16 2022 GMT', 'subjectAltName': (('DNS', '*.reg.ru'), ('DNS', 'reg.ru')), 'OCSP': ('http://ocsp2.globalsign.com/gsalphasha2g2',), 'caIssuers': ('http://secure2.alphassl.com/cacert/gsalphasha2g2r1.crt',), 'crlDistributionPoints': ('http://crl2.alphassl.com/gs/gsalphasha2g2.crl',)}
2021-03-19 13:22:54,941 - INFO - Scheduler started
2021-03-19 13:22:57,863 - INFO - Received signal 2 (SIGINT), stopping...
2021-03-19 13:22:57,863 - INFO - Scheduler has been shut down
2021-03-19 13:24:03,592 - INFO - Scheduler started
2021-03-19 13:24:05,311 - INFO - Received signal 2 (SIGINT), stopping...
2021-03-19 13:24:05,311 - INFO - Scheduler has been shut down
2021-03-19 13:24:08,369 - ERROR - Error while getting Updates: Conflict: terminated by other getUpdates request; make sure that only one bot instance is running
2021-03-22 21:03:07,272 - INFO - Scheduler started
2021-03-22 21:03:32,125 - INFO - Received signal 2 (SIGINT), stopping...
2021-03-22 21:03:32,125 - INFO - Scheduler has been shut down
2021-03-22 21:04:06,383 - INFO - Scheduler started
2021-03-22 21:04:33,726 - INFO - Received signal 2 (SIGINT), stopping...
2021-03-22 21:04:33,726 - INFO - Scheduler has been shut down
2021-03-22 21:05:08,390 - INFO - Scheduler started
2021-03-22 21:05:31,755 - INFO - Received signal 2 (SIGINT), stopping...
2021-03-22 21:05:31,755 - INFO - Scheduler has been shut down
2021-03-22 21:05:42,061 - INFO - Scheduler started
2021-03-22 21:06:03,622 - INFO - Received signal 2 (SIGINT), stopping...
2021-03-22 21:06:03,623 - INFO - Scheduler has been shut down
2021-03-22 21:16:39,763 - INFO - Scheduler started
2021-03-22 21:16:55,917 - INFO - Received signal 2 (SIGINT), stopping...
2021-03-22 21:16:55,917 - INFO - Scheduler has been shut down
2021-03-22 21:17:52,506 - INFO - Scheduler started
2021-03-22 21:18:02,903 - INFO - Received signal 2 (SIGINT), stopping...
2021-03-22 21:18:02,903 - INFO - Scheduler has been shut down
2021-03-22 21:21:00,131 - INFO - Scheduler started
2021-03-22 21:21:45,567 - INFO - Received signal 2 (SIGINT), stopping...
2021-03-22 21:21:45,567 - INFO - Scheduler has been shut down
2021-03-22 21:22:09,076 - INFO - Scheduler started
2021-03-22 21:22:53,154 - INFO - Received signal 2 (SIGINT), stopping...
2021-03-22 21:22:53,154 - INFO - Scheduler has been shut down
2021-03-22 21:30:23,102 - INFO - Scheduler started
2021-03-22 21:30:50,892 - INFO - Received signal 2 (SIGINT), stopping...
2021-03-22 21:30:50,892 - INFO - Scheduler has been shut down
2021-03-22 21:31:36,866 - INFO - Scheduler started
2021-03-22 21:31:54,493 - INFO - Received signal 2 (SIGINT), stopping...
2021-03-22 21:31:54,493 - INFO - Scheduler has been shut down
2021-03-22 21:33:49,627 - INFO - Scheduler started
2021-03-22 21:34:08,933 - INFO - Received signal 2 (SIGINT), stopping...
2021-03-22 21:34:08,934 - INFO - Scheduler has been shut down
2021-03-22 21:34:23,405 - INFO - Scheduler started
2021-03-22 21:34:30,710 - ERROR - No error handlers are registered, logging exception.
Traceback (most recent call last):
  File "/Library/Frameworks/Python.framework/Versions/3.8/lib/python3.8/site-packages/telegram/ext/dispatcher.py", line 432, in process_update
    handler.handle_update(update, self, check, context)
  File "/Library/Frameworks/Python.framework/Versions/3.8/lib/python3.8/site-packages/telegram/ext/conversationhandler.py", line 517, in handle_update
    new_state = handler.handle_update(update, dispatcher, check_result, context)
  File "/Library/Frameworks/Python.framework/Versions/3.8/lib/python3.8/site-packages/telegram/ext/handler.py", line 156, in handle_update
    return self.callback(update, context)
  File "/Users/a18850286/PycharmProjects/InvestBot/Handlers/CallBackQueryHandlers/paginationCallbackQueryHandler.py", line 15, in nextPage
    update.bot.editMessageText(message,chatId,messageId,"Markdown",)
  File "<decorator-gen-27>", line 2, in edit_message_text
  File "/Library/Frameworks/Python.framework/Versions/3.8/lib/python3.8/site-packages/telegram/bot.py", line 135, in decorator
    result = func(*args, **kwargs)
  File "/Library/Frameworks/Python.framework/Versions/3.8/lib/python3.8/site-packages/telegram/bot.py", line 2362, in edit_message_text
    return self._message(
  File "/Library/Frameworks/Python.framework/Versions/3.8/lib/python3.8/site-packages/telegram/bot.py", line 281, in _message
    result = self._post(endpoint, data, timeout=timeout, api_kwargs=api_kwargs)
  File "/Library/Frameworks/Python.framework/Versions/3.8/lib/python3.8/site-packages/telegram/bot.py", line 245, in _post
    return self.request.post(f'{self.base_url}/{endpoint}', data=data, timeout=timeout)
  File "/Library/Frameworks/Python.framework/Versions/3.8/lib/python3.8/site-packages/telegram/utils/request.py", line 349, in post
    result = self._request_wrapper(
  File "/Library/Frameworks/Python.framework/Versions/3.8/lib/python3.8/site-packages/telegram/utils/request.py", line 272, in _request_wrapper
    raise BadRequest(message)
telegram.error.BadRequest: Message text is empty
2021-03-22 21:34:59,852 - INFO - Received signal 2 (SIGINT), stopping...
2021-03-22 21:34:59,853 - INFO - Scheduler has been shut down
2021-03-22 21:37:01,067 - INFO - Scheduler started
2021-03-22 21:37:25,724 - INFO - Received signal 2 (SIGINT), stopping...
2021-03-22 21:37:25,724 - INFO - Scheduler has been shut down
2021-03-22 21:38:05,883 - INFO - Scheduler started
2021-03-22 21:38:50,046 - INFO - Received signal 2 (SIGINT), stopping...
2021-03-22 21:38:50,047 - INFO - Scheduler has been shut down
2021-03-22 21:39:36,190 - INFO - Scheduler started
2021-03-22 21:40:55,494 - INFO - Received signal 2 (SIGINT), stopping...
2021-03-22 21:40:55,495 - INFO - Scheduler has been shut down
2021-03-22 21:46:15,479 - INFO - Scheduler started
2021-03-22 21:47:12,174 - INFO - Received signal 2 (SIGINT), stopping...
2021-03-22 21:47:12,174 - INFO - Scheduler has been shut down
2021-03-22 21:48:19,838 - INFO - Scheduler started
2021-03-22 21:49:26,482 - INFO - Received signal 2 (SIGINT), stopping...
2021-03-22 21:49:26,482 - INFO - Scheduler has been shut down
2021-03-22 21:49:35,079 - INFO - Scheduler started
2021-03-22 21:49:43,239 - ERROR - No error handlers are registered, logging exception.
Traceback (most recent call last):
  File "/Library/Frameworks/Python.framework/Versions/3.8/lib/python3.8/site-packages/telegram/ext/dispatcher.py", line 432, in process_update
    handler.handle_update(update, self, check, context)
  File "/Library/Frameworks/Python.framework/Versions/3.8/lib/python3.8/site-packages/telegram/ext/conversationhandler.py", line 517, in handle_update
    new_state = handler.handle_update(update, dispatcher, check_result, context)
  File "/Library/Frameworks/Python.framework/Versions/3.8/lib/python3.8/site-packages/telegram/ext/handler.py", line 156, in handle_update
    return self.callback(update, context)
  File "/Users/a18850286/PycharmProjects/InvestBot/Handlers/CallBackQueryHandlers/paginationCallbackQueryHandler.py", line 15, in nextPage
    update.bot.editMessageText(message,chatId,messageId)
  File "<decorator-gen-27>", line 2, in edit_message_text
  File "/Library/Frameworks/Python.framework/Versions/3.8/lib/python3.8/site-packages/telegram/bot.py", line 135, in decorator
    result = func(*args, **kwargs)
  File "/Library/Frameworks/Python.framework/Versions/3.8/lib/python3.8/site-packages/telegram/bot.py", line 2362, in edit_message_text
    return self._message(
  File "/Library/Frameworks/Python.framework/Versions/3.8/lib/python3.8/site-packages/telegram/bot.py", line 281, in _message
    result = self._post(endpoint, data, timeout=timeout, api_kwargs=api_kwargs)
  File "/Library/Frameworks/Python.framework/Versions/3.8/lib/python3.8/site-packages/telegram/bot.py", line 245, in _post
    return self.request.post(f'{self.base_url}/{endpoint}', data=data, timeout=timeout)
  File "/Library/Frameworks/Python.framework/Versions/3.8/lib/python3.8/site-packages/telegram/utils/request.py", line 349, in post
    result = self._request_wrapper(
  File "/Library/Frameworks/Python.framework/Versions/3.8/lib/python3.8/site-packages/telegram/utils/request.py", line 272, in _request_wrapper
    raise BadRequest(message)
telegram.error.BadRequest: Message text is empty
2021-03-22 21:51:44,251 - INFO - Received signal 2 (SIGINT), stopping...
2021-03-22 21:51:44,251 - INFO - Scheduler has been shut down
2021-03-22 21:51:47,215 - INFO - Scheduler started
2021-03-22 21:52:04,321 - INFO - Received signal 2 (SIGINT), stopping...
2021-03-22 21:52:04,321 - INFO - Scheduler has been shut down
2021-03-22 22:18:46,322 - INFO - Scheduler started
2021-03-22 22:19:25,281 - INFO - Received signal 2 (SIGINT), stopping...
2021-03-22 22:19:25,281 - INFO - Scheduler has been shut down
2021-03-22 22:19:35,882 - INFO - Scheduler started
2021-03-22 22:20:48,843 - INFO - Received signal 2 (SIGINT), stopping...
2021-03-22 22:20:48,843 - INFO - Scheduler has been shut down
2021-03-22 22:21:13,201 - INFO - Scheduler started
2021-03-22 22:21:33,213 - INFO - Received signal 2 (SIGINT), stopping...
2021-03-22 22:21:33,213 - INFO - Scheduler has been shut down
2021-03-22 22:23:16,917 - INFO - Scheduler started
2021-03-22 22:23:28,387 - ERROR - No error handlers are registered, logging exception.
Traceback (most recent call last):
  File "/Library/Frameworks/Python.framework/Versions/3.8/lib/python3.8/site-packages/telegram/ext/dispatcher.py", line 432, in process_update
    handler.handle_update(update, self, check, context)
  File "/Library/Frameworks/Python.framework/Versions/3.8/lib/python3.8/site-packages/telegram/ext/handler.py", line 156, in handle_update
    return self.callback(update, context)
TypeError: 'NoneType' object is not callable
2021-03-22 22:23:29,710 - ERROR - No error handlers are registered, logging exception.
Traceback (most recent call last):
  File "/Library/Frameworks/Python.framework/Versions/3.8/lib/python3.8/site-packages/telegram/ext/dispatcher.py", line 432, in process_update
    handler.handle_update(update, self, check, context)
  File "/Library/Frameworks/Python.framework/Versions/3.8/lib/python3.8/site-packages/telegram/ext/handler.py", line 156, in handle_update
    return self.callback(update, context)
TypeError: 'NoneType' object is not callable
2021-03-22 22:23:34,146 - ERROR - No error handlers are registered, logging exception.
Traceback (most recent call last):
  File "/Library/Frameworks/Python.framework/Versions/3.8/lib/python3.8/site-packages/telegram/ext/dispatcher.py", line 432, in process_update
    handler.handle_update(update, self, check, context)
  File "/Library/Frameworks/Python.framework/Versions/3.8/lib/python3.8/site-packages/telegram/ext/handler.py", line 156, in handle_update
    return self.callback(update, context)
TypeError: 'NoneType' object is not callable
2021-03-22 22:23:53,728 - ERROR - No error handlers are registered, logging exception.
Traceback (most recent call last):
  File "/Library/Frameworks/Python.framework/Versions/3.8/lib/python3.8/site-packages/telegram/ext/dispatcher.py", line 432, in process_update
    handler.handle_update(update, self, check, context)
  File "/Library/Frameworks/Python.framework/Versions/3.8/lib/python3.8/site-packages/telegram/ext/handler.py", line 156, in handle_update
    return self.callback(update, context)
TypeError: 'NoneType' object is not callable
2021-03-22 22:24:07,816 - INFO - Received signal 2 (SIGINT), stopping...
2021-03-22 22:24:07,817 - INFO - Scheduler has been shut down
2021-03-22 22:27:12,980 - INFO - Scheduler started
2021-03-22 22:27:53,867 - INFO - Received signal 2 (SIGINT), stopping...
2021-03-22 22:27:53,867 - INFO - Scheduler has been shut down
2021-03-22 22:31:26,541 - INFO - Scheduler started
2021-03-22 22:31:50,096 - INFO - Received signal 2 (SIGINT), stopping...
2021-03-22 22:31:50,096 - INFO - Scheduler has been shut down
2021-03-22 22:32:07,090 - INFO - Scheduler started
2021-03-22 22:32:17,367 - INFO - Received signal 2 (SIGINT), stopping...
2021-03-22 22:32:17,367 - INFO - Scheduler has been shut down
2021-03-22 22:32:34,483 - INFO - Scheduler started
2021-03-22 22:32:54,325 - INFO - Received signal 2 (SIGINT), stopping...
2021-03-22 22:32:54,325 - INFO - Scheduler has been shut down
2021-03-22 22:35:42,203 - INFO - Scheduler started
2021-03-22 22:35:55,392 - INFO - Received signal 2 (SIGINT), stopping...
2021-03-22 22:35:55,392 - INFO - Scheduler has been shut down
2021-03-22 22:37:11,136 - INFO - Scheduler started
2021-03-22 22:37:19,531 - ERROR - No error handlers are registered, logging exception.
Traceback (most recent call last):
  File "/Library/Frameworks/Python.framework/Versions/3.8/lib/python3.8/site-packages/telegram/ext/dispatcher.py", line 432, in process_update
    handler.handle_update(update, self, check, context)
  File "/Library/Frameworks/Python.framework/Versions/3.8/lib/python3.8/site-packages/telegram/ext/conversationhandler.py", line 517, in handle_update
    new_state = handler.handle_update(update, dispatcher, check_result, context)
  File "/Library/Frameworks/Python.framework/Versions/3.8/lib/python3.8/site-packages/telegram/ext/handler.py", line 156, in handle_update
    return self.callback(update, context)
  File "/Users/a18850286/PycharmProjects/InvestBot/Handlers/CallBackQueryHandlers/paginationCallbackQueryHandler.py", line 29, in backPage
    update.bot.editMessageText(message,chatId,messageId)
  File "<decorator-gen-27>", line 2, in edit_message_text
  File "/Library/Frameworks/Python.framework/Versions/3.8/lib/python3.8/site-packages/telegram/bot.py", line 135, in decorator
    result = func(*args, **kwargs)
  File "/Library/Frameworks/Python.framework/Versions/3.8/lib/python3.8/site-packages/telegram/bot.py", line 2362, in edit_message_text
    return self._message(
  File "/Library/Frameworks/Python.framework/Versions/3.8/lib/python3.8/site-packages/telegram/bot.py", line 281, in _message
    result = self._post(endpoint, data, timeout=timeout, api_kwargs=api_kwargs)
  File "/Library/Frameworks/Python.framework/Versions/3.8/lib/python3.8/site-packages/telegram/bot.py", line 245, in _post
    return self.request.post(f'{self.base_url}/{endpoint}', data=data, timeout=timeout)
  File "/Library/Frameworks/Python.framework/Versions/3.8/lib/python3.8/site-packages/telegram/utils/request.py", line 349, in post
    result = self._request_wrapper(
  File "/Library/Frameworks/Python.framework/Versions/3.8/lib/python3.8/site-packages/telegram/utils/request.py", line 272, in _request_wrapper
    raise BadRequest(message)
telegram.error.BadRequest: Message text is empty
2021-03-22 22:38:04,690 - INFO - Received signal 2 (SIGINT), stopping...
2021-03-22 22:38:04,690 - INFO - Scheduler has been shut down
2021-03-22 22:38:12,296 - INFO - Scheduler started
2021-03-22 22:38:25,917 - INFO - Received signal 2 (SIGINT), stopping...
2021-03-22 22:38:25,918 - INFO - Scheduler has been shut down
2021-03-22 22:39:36,653 - INFO - Scheduler started
2021-03-22 22:39:54,103 - INFO - Received signal 2 (SIGINT), stopping...
2021-03-22 22:39:54,103 - INFO - Scheduler has been shut down
2021-03-22 22:52:50,812 - INFO - Scheduler started
2021-03-22 22:53:13,385 - INFO - Received signal 2 (SIGINT), stopping...
2021-03-22 22:53:13,385 - INFO - Scheduler has been shut down
2021-03-22 22:54:02,132 - INFO - Scheduler started
2021-03-22 22:54:51,524 - INFO - Received signal 2 (SIGINT), stopping...
2021-03-22 22:54:51,525 - INFO - Scheduler has been shut down
2021-03-22 22:55:44,426 - INFO - Scheduler started
2021-03-22 22:56:14,416 - INFO - Received signal 2 (SIGINT), stopping...
2021-03-22 22:56:14,416 - INFO - Scheduler has been shut down
2021-03-22 22:57:22,156 - INFO - Scheduler started
2021-03-22 22:58:12,792 - INFO - Received signal 2 (SIGINT), stopping...
2021-03-22 22:58:12,792 - INFO - Scheduler has been shut down
2021-03-22 22:59:24,490 - INFO - Scheduler started
2021-03-22 23:00:50,252 - INFO - Received signal 2 (SIGINT), stopping...
2021-03-22 23:00:50,252 - INFO - Scheduler has been shut down
2021-03-22 23:09:45,994 - INFO - Scheduler started
2021-03-22 23:10:00,700 - INFO - Received signal 2 (SIGINT), stopping...
2021-03-22 23:10:00,700 - INFO - Scheduler has been shut down
2021-03-22 23:11:07,022 - INFO - Scheduler started
2021-03-22 23:12:44,877 - INFO - Received signal 2 (SIGINT), stopping...
2021-03-22 23:12:44,877 - INFO - Scheduler has been shut down
2021-03-22 23:12:53,115 - INFO - Scheduler started
2021-03-22 23:13:04,714 - INFO - Received signal 2 (SIGINT), stopping...
2021-03-22 23:13:04,714 - INFO - Scheduler has been shut down
2021-03-22 23:19:24,241 - INFO - Scheduler started
2021-03-22 23:19:32,266 - ERROR - No error handlers are registered, logging exception.
Traceback (most recent call last):
  File "/Library/Frameworks/Python.framework/Versions/3.8/lib/python3.8/site-packages/telegram/ext/dispatcher.py", line 432, in process_update
    handler.handle_update(update, self, check, context)
  File "/Library/Frameworks/Python.framework/Versions/3.8/lib/python3.8/site-packages/telegram/ext/conversationhandler.py", line 517, in handle_update
    new_state = handler.handle_update(update, dispatcher, check_result, context)
  File "/Library/Frameworks/Python.framework/Versions/3.8/lib/python3.8/site-packages/telegram/ext/handler.py", line 156, in handle_update
    return self.callback(update, context)
  File "/Users/a18850286/PycharmProjects/InvestBot/Handlers/CallBackQueryHandlers/paginationCallbackQueryHandler.py", line 15, in nextPage
    listOfNextAssets = getUserAssets()
TypeError: getUserAssets() missing 2 required positional arguments: 'userChatId' and 'page'
2021-03-22 23:20:17,713 - INFO - Received signal 2 (SIGINT), stopping...
2021-03-22 23:20:17,713 - INFO - Scheduler has been shut down
2021-03-22 23:20:24,189 - INFO - Scheduler started
2021-03-22 23:20:32,920 - INFO - Received signal 2 (SIGINT), stopping...
2021-03-22 23:20:32,920 - INFO - Scheduler has been shut down
2021-03-22 23:21:31,505 - INFO - Scheduler started
2021-03-22 23:21:40,102 - INFO - Received signal 2 (SIGINT), stopping...
2021-03-22 23:21:40,102 - INFO - Scheduler has been shut down
2021-03-22 23:23:52,544 - INFO - Scheduler started
2021-03-22 23:23:59,382 - ERROR - No error handlers are registered, logging exception.
Traceback (most recent call last):
  File "/Library/Frameworks/Python.framework/Versions/3.8/lib/python3.8/site-packages/telegram/ext/dispatcher.py", line 432, in process_update
    handler.handle_update(update, self, check, context)
  File "/Library/Frameworks/Python.framework/Versions/3.8/lib/python3.8/site-packages/telegram/ext/conversationhandler.py", line 517, in handle_update
    new_state = handler.handle_update(update, dispatcher, check_result, context)
  File "/Library/Frameworks/Python.framework/Versions/3.8/lib/python3.8/site-packages/telegram/ext/handler.py", line 156, in handle_update
    return self.callback(update, context)
  File "/Users/a18850286/PycharmProjects/InvestBot/Handlers/CallBackQueryHandlers/paginationCallbackQueryHandler.py", line 17, in nextPage
    userAssets = getUserAssets(chatId, page)
  File "/Users/a18850286/PycharmProjects/InvestBot/DB/Queries/userQuery.py", line 39, in getUserAssets
    list = result[(page-1)*pageSize:page*pageSize]
TypeError: unsupported operand type(s) for -: 'str' and 'int'
2021-03-22 23:24:15,080 - INFO - Received signal 2 (SIGINT), stopping...
2021-03-22 23:24:15,080 - INFO - Scheduler has been shut down
2021-03-22 23:27:19,988 - INFO - Scheduler started
2021-03-22 23:27:30,871 - INFO - Received signal 2 (SIGINT), stopping...
2021-03-22 23:27:30,871 - INFO - Scheduler has been shut down
2021-03-22 23:28:51,438 - INFO - Scheduler started
2021-03-22 23:30:17,611 - INFO - Received signal 2 (SIGINT), stopping...
2021-03-22 23:30:17,611 - INFO - Scheduler has been shut down
2021-03-22 23:30:24,068 - INFO - Scheduler started
2021-03-22 23:30:48,926 - INFO - Received signal 2 (SIGINT), stopping...
2021-03-22 23:30:48,926 - INFO - Scheduler has been shut down
2021-03-22 23:32:44,918 - INFO - Scheduler started
2021-03-22 23:34:14,781 - INFO - Received signal 2 (SIGINT), stopping...
2021-03-22 23:34:14,782 - INFO - Scheduler has been shut down
2021-03-22 23:35:04,989 - INFO - Scheduler started
2021-03-22 23:45:11,314 - INFO - Received signal 2 (SIGINT), stopping...
2021-03-22 23:45:11,314 - INFO - Scheduler has been shut down
2021-03-22 23:45:22,684 - INFO - Scheduler started
2021-03-22 23:46:01,902 - INFO - Received signal 2 (SIGINT), stopping...
2021-03-22 23:46:01,902 - INFO - Scheduler has been shut down
2021-03-22 23:46:13,871 - INFO - Scheduler started
2021-03-22 23:49:24,410 - ERROR - ERROR:  duplicate key value violates unique constraint "chat_id"
DETAIL:  Key (chat_id)=(550666260) already exists.
Traceback (most recent call last):
  File "/Users/a18850286/PycharmProjects/InvestBot/DB/Queries/dbConnection.py", line 31, in query
    records = update_db(conn,sql)
  File "/Users/a18850286/PycharmProjects/InvestBot/DB/Queries/dbConnection.py", line 21, in update_db
    cursor.execute(sql)
psycopg2.errors.UniqueViolation: duplicate key value violates unique constraint "chat_id"
DETAIL:  Key (chat_id)=(550666260) already exists.

2021-03-22 23:49:50,583 - INFO - Received signal 2 (SIGINT), stopping...
2021-03-22 23:49:50,583 - INFO - Scheduler has been shut down
2021-03-22 23:54:19,929 - INFO - Scheduler started
2021-03-22 23:54:48,773 - ERROR - ERROR:  duplicate key value violates unique constraint "chat_id"
DETAIL:  Key (chat_id)=(550666260) already exists.
Traceback (most recent call last):
  File "/Users/a18850286/PycharmProjects/InvestBot/DB/Queries/dbConnection.py", line 31, in query
    records = update_db(conn,sql)
  File "/Users/a18850286/PycharmProjects/InvestBot/DB/Queries/dbConnection.py", line 21, in update_db
    cursor.execute(sql)
psycopg2.errors.UniqueViolation: duplicate key value violates unique constraint "chat_id"
DETAIL:  Key (chat_id)=(550666260) already exists.

2021-03-22 23:55:30,840 - INFO - Received signal 2 (SIGINT), stopping...
2021-03-22 23:55:30,840 - INFO - Scheduler has been shut down
